Workbook
Name DB_BeratKeluar: "Database!$M$3:$M$4846"
Name DB_BeratKeluar: "Database!$M$3:$M$4846"
Name DB_BeratKeluar: #REF!
Name DB_BeratMasuk: "Database!$L$3:$L$4846"
Name DB_BeratMasuk: "Database!$L$3:$L$4846"
Name DB_BeratMasuk: #REF!
Name DB_Netto: "Database!$N$3:$N$4846"
Name DB_Netto: "Database!$N$3:$N$4846"
Name DB_Netto: #REF!
Name DB_Netto2k: "Database!$N$3:$N$2000"
Name DB_Netto2k: "Database!$N$3:$N$2000"
Name DB_Netto2k: #REF!
Name DB_NoPol: "Database!$E$3:$E$4846"
Name DB_NoPol: "Database!$E$3:$E$4846"
Name DB_NoPol: #REF!
Name DB_NoPol2k: "Database!$E$3:$E$2000"
Name DB_NoPol2k: "Database!$E$3:$E$2000"
Name DB_NoPol2k: #REF!
Name DB_Produk: "Database!$I$3:$I$4846"
Name DB_Produk: "Database!$I$3:$I$4846"
Name DB_Produk: #REF!
Name DB_Produk2k: "Database!$I$3:$I$2000"
Name DB_Produk2k: "Database!$I$3:$I$2000"
Name DB_Produk2k: #REF!
Name DB_Relasi: "Database!$H$3:$H$4846"
Name DB_Relasi: "Database!$H$3:$H$4846"
Name DB_Relasi: #REF!
Name DB_Relasi2k: "Database!$H$3:$H$2000"
Name DB_Relasi2k: "Database!$H$3:$H$2000"
Name DB_Relasi2k: #REF!
Name DB_Tanggal: "Database!$K$3:$K$4846"
Name DB_Tanggal: "Database!$K$3:$K$4846"
Name DB_Tanggal: #REF!
Name DB_Tanggal2k: "Database!$K$3:$K$2000"
Name DB_Tanggal2k: "Database!$K$3:$K$2000"
Name DB_Tanggal2k: #REF!

Sheet Pivot
A3: Row Labels | B3: Sum of Jumlah | C3: Sum of Berat Netto PT WINS
A4: B-40 | B4: 44 | C4: 503310
A5: PT. WIJAYA NUSANTARA ENERGI | B5: 18 | C5: 295170
A6: PT. WISAN PETRO ENERGI | B6: 26 | C6: 208140
A7: BE | B7: 5 | C7: 101500
A8: PT. MADU LINGGA RAHARJA | B8: 5 | C8: 101500
A9: CPO | B9: 955 | C9: 14931050
A10: PT. JAS MULIA | B10: 402 | C10: 6495280
A11: PT. KASMAR MATANO PERSADA | B11: 174 | C11: 3939560
A12: PT. MADINRA INTI SAWIT | B12: 282 | C12: 2697400
A13: PT. PERKEBUNAN NUSANTARA | B13: 97 | C13: 1798810
A14: RBDPL | B14: 537 | C14: 5851470 | H14: =SUM(H15:H22) -> 5388583 | I14: =GETPIVOTDATA("Berat Netto PT WINS",$A$3,"Produk","RBDPL")-H14 -> 462887
A15: CV. DUTA ABADI | B15: 135 | C15: 1500660 | E15: 135 | F15: =GETPIVOTDATA("Sum of Jumlah",$A$3,"Relasi","CV. DUTA ABADI","Produk","RBDPL")-E15 -> 0 | H15: 1361110 | I15: =GETPIVOTDATA("Berat Netto PT WINS",$A$3,"Relasi","CV. DUTA ABADI","Produk","RBDPL")-H15 -> 139550
A16: CV. HALILINTAR SAKTI ABADI | B16: 76 | C16: 797790 | E16: 76 | F16: =GETPIVOTDATA("Sum of Jumlah",$A$3,"Relasi","CV. HALILINTAR SAKTI ABADI","Produk","RBDPL")-E16 -> 0 | H16: 797790 | I16: =GETPIVOTDATA("Berat Netto PT WINS",$A$3,"Relasi","CV. HALILINTAR SAKTI ABADI","Produk","RBDPL")-H16 -> 0
A17: CV. Nusantara Daya Jaya | B17: 1 | C17: 15090 | E17: 1 | F17: =GETPIVOTDATA("Sum of Jumlah",$A$3,"Relasi","CV. Nusantara Daya Jaya","Produk","RBDPL")-E17 -> 0 | H17: 15090 | I17: =GETPIVOTDATA("Berat Netto PT WINS",$A$3,"Relasi","CV. Nusantara Daya Jaya","Produk","RBDPL")-H17 -> 0
A18: CV. SURYA CAHAYA MAS | B18: 152 | C18: 1498140 | E18: 152 | F18: =GETPIVOTDATA("Sum of Jumlah",$A$3,"Relasi","CV. SURYA CAHAYA MAS","Produk","RBDPL")-E18 -> 0 | H18: 1327330 | I18: =GETPIVOTDATA("Berat Netto PT WINS",$A$3,"Relasi","CV. SURYA CAHAYA MAS","Produk","RBDPL")-H18 -> 170810
A19: PT. BUKIT JEJER LESTARI | B19: 137 | C19: 1290080 | E19: 137 | F19: =GETPIVOTDATA("Sum of Jumlah",$A$3,"Relasi","PT. BUKIT JEJER LESTARI","Produk","RBDPL")-E19 -> 0 | H19: 1224516 | I19: =GETPIVOTDATA("Berat Netto PT WINS",$A$3,"Relasi","PT. BUKIT JEJER LESTARI","Produk","RBDPL")-H19 -> 65564
A20: PT. PANDU URANE PERKASA | B20: 6 | C20: 127010 | E20: 6 | F20: =GETPIVOTDATA("Sum of Jumlah",$A$3,"Relasi","PT. PANDU URANE PERKASA","Produk","RBDPL")-E20 -> 0 | H20: 98039 | I20: =GETPIVOTDATA("Berat Netto PT WINS",$A$3,"Relasi","PT. PANDU URANE PERKASA","Produk","RBDPL")-H20 -> 28971
A21: PT. TRI DAYA JAYA | B21: 16 | C21: 305980 | E21: 16 | F21: =GETPIVOTDATA("Sum of Jumlah",$A$3,"Relasi","PT. TRI DAYA JAYA","Produk","RBDPL")-E21 -> 0 | H21: 276749 | I21: =GETPIVOTDATA("Berat Netto PT WINS",$A$3,"Relasi","PT. TRI DAYA JAYA","Produk","RBDPL")-H21 -> 29231
A22: PT. WIJAYA INTI NUSANTARA | B22: 14 | C22: 316720 | E22: 14 | F22: =GETPIVOTDATA("Sum of Jumlah",$A$3,"Relasi","PT. WIJAYA INTI NUSANTARA","Produk","RBDPL")-E22 -> 0 | H22: 287959 | I22: =GETPIVOTDATA("Berat Netto PT WINS",$A$3,"Relasi","PT. WIJAYA INTI NUSANTARA","Produk","RBDPL")-H22 -> 28761
A23: RBDPS | B23: 10 | C23: 200000
A24: PT. BORNEO MITRA SENTOSA | B24: 10 | C24: 200000
A25: (blank)
A26: (blank)
A27: Grand Total | B27: 1551 | C27: 21587330

Sheet Dashboard WB
D2: DASHBOARD TIMBANGAN
D4: Total Berat Netto | E4: =TEXT(_DB_Data!B7/1000,"#.##0")&" Ton" -> 21.764 Ton | F4: =IF(_DB_Data!B12>0,"↑ "&TEXT(ABS(_DB_Data!B12),"0.0%"),"↓ "&TEXT(ABS(_DB_Data!B12),"0.0%")) -> ↓ 15% | G4: ="Prev: "&TEXT(INT(_DB_Data!B10/1000),"#.##0")&" Ton" -> Prev: 3.853 Ton | K4: Year Filter | L4: 2025 | M4: 2026
D6: Filter Produk/Bulan: | E6: Semua | F6: 0
D7: TOTAL RITASI | F7: TOTAL NETTO (Kg) | H7: TOTAL NETTO (Ton) | J7: RATA-RATA/TRIP (Kg) | M7: MAKS NETTO/TRIP | O7: MIN NETTO/TRIP
D8: {=IF($E$6="Semua",IF($F$6=0,SUMPRODUCT((Database!$I$4:$I$4826<>"")*1),SUMPRODUCT((Database!$I$4:$I$4826<>"")*(MONTH(Database!$K$4:$K$4826)=$F$6))),IF($F$6=0,SUMPRODUCT((Database!$I$4:$I$4826=$E$6)*1),SUMPRODUCT((Database!$I$4:$I$4826=$E$6)*(MONTH(Database!$K$4:$K$4826)=$F$6))))} -> 1564 | F8: {=IF($E$6="Semua",IF($F$6=0,SUMPRODUCT((Database!$I$4:$I$4826<>"")*Database!$N$4:$N$4826),SUMPRODUCT((Database!$I$4:$I$4826<>"")*(MONTH(Database!$K$4:$K$4826)=$F$6)*Database!$N$4:$N$4826)),IF($F$6=0,SUMPRODUCT((Database!$I$4:$I$4826=$E$6)*Database!$N$4:$N$4826),SUMPRODUCT((Database!$I$4:$I$4826=$E$6)*(MONTH(Database!$K$4:$K$4826)=$F$6)*Database!$N$4:$N$4826)))} -> 21764280 | H8: {=IFERROR(ROUND(IF($E$6="Semua",IF($F$6=0,SUMPRODUCT((Database!$I$4:$I$4826<>"")*Database!$N$4:$N$4826),SUMPRODUCT((Database!$I$4:$I$4826<>"")*(MONTH(Database!$K$4:$K$4826)=$F$6)*Database!$N$4:$N$4826)),IF($F$6=0,SUMPRODUCT((Database!$I$4:$I$4826=$E$6)*Database!$N$4:$N$4826),SUMPRODUCT((Database!$I$4:$I$4826=$E$6)*(MONTH(Database!$K$4:$K$4826)=$F$6)*Database!$N$4:$N$4826)))/1000,0),0)} -> 21764 | J8: {=IFERROR(IF($E$6="Semua",IF($F$6=0,SUMPRODUCT((Database!$I$4:$I$4826<>"")*Database!$N$4:$N$4826),SUMPRODUCT((Database!$I$4:$I$4826<>"")*(MONTH(Database!$K$4:$K$4826)=$F$6)*Database!$N$4:$N$4826)),IF($F$6=0,SUMPRODUCT((Database!$I$4:$I$4826=$E$6)*Database!$N$4:$N$4826),SUMPRODUCT((Database!$I$4:$I$4826=$E$6)*(MONTH(Database!$K$4:$K$4826)=$F$6)*Database!$N$4:$N$4826)))/IF($E$6="Semua",IF($F$6=0,SUMPRODUCT((Database!$I$4:$I$4826<>"")*1),SUMPRODUCT((Database!$I$4:$I$4826<>"")*(MONTH(Database!$K$4:$K$4826)=$F$6))),IF($F$6=0,SUMPRODUCT((Database!$I$4:$I$4826=$E$6)*1),SUMPRODUCT((Database!$I$4:$I$4826=$E$6)*(MONTH(Database!$K$4:$K$4826)=$F$6)))),0)} -> 13915.78 | M8: =IFERROR(IF($E$6="Semua",IF($F$6=0,_xlfn.MAXIFS(Database!$N$4:$N$4826,Database!$N$4:$N$4826,">"&0),_xlfn.MAXIFS(Database!$N$4:$N$4826,Database!$N$4:$N$4826,">"&0,Database!$K$4:$K$4826,">="&DATE(YEAR(TODAY()),$F$6,1),Database!$K$4:$K$4826,"<"&EOMONTH(DATE(YEAR(TODAY()),$F$6,1),0)+1)),IF($F$6=0,_xlfn.MAXIFS(Database!$N$4:$N$4826,Database!$I$4:$I$4826,$E$6,Database!$N$4:$N$4826,">"&0),_xlfn.MAXIFS(Database!$N$4:$N$4826,Database!$I$4:$I$4826,$E$6,Database!$N$4:$N$4826,">"&0,Database!$K$4:$K$4826,">="&DATE(YEAR(TODAY()),$F$6,1),Database!$K$4:$K$4826,"<"&EOMONTH(DATE(YEAR(TODAY()),$F$6,1),0)+1))),0) -> 29000 | O8: =IFERROR(IF($E$6="Semua",IF($F$6=0,_xlfn.MINIFS(Database!$N$4:$N$4826,Database!$N$4:$N$4826,">"&100),_xlfn.MINIFS(Database!$N$4:$N$4826,Database!$N$4:$N$4826,">"&100,Database!$K$4:$K$4826,">="&DATE(YEAR(TODAY()),$F$6,1),Database!$K$4:$K$4826,"<"&EOMONTH(DATE(YEAR(TODAY()),$F$6,1),0)+1)),IF($F$6=0,_xlfn.MINIFS(Database!$N$4:$N$4826,Database!$I$4:$I$4826,$E$6,Database!$N$4:$N$4826,">"&100),_xlfn.MINIFS(Database!$N$4:$N$4826,Database!$I$4:$I$4826,$E$6,Database!$N$4:$N$4826,">"&100,Database!$K$4:$K$4826,">="&DATE(YEAR(TODAY()),$F$6,1),Database!$K$4:$K$4826,"<"&EOMONTH(DATE(YEAR(TODAY()),$F$6,1),0)+1))),0) -> 190
D9: Trip | F9: (Kg) | H9: (Ton) | J9: (Kg/Trip) | M9: (Kg) | O9: (Kg)
D14: ANALISIS RELASI & TREND
D17: DETAIL OPERASIONAL
D19: ="Data: Summary WB | "&TEXT(_DB_Data!B4,"#,##0")&" Trip | Filter: "&_DB_Data!B1&" | Auto-update s/d baris 2000" -> Data: Summary WB | 1564,0 Trip | Filter: Semua | Auto-update s/d baris 2000

Sheet Analisa CPO
A1: PERBANDINGAN DATA CPO
A4: RINGKASAN
A5: Metrik | B5: Jumlah | C5: % | E5: Per Field | F5: Berbeda
A6: Total Baris di Tes | B6: 941 | E6: No Polisi | F6: 9
A7: Total Baris CPO di Database | B7: 941 | E7: No Kontrak | F7: 480
A8: Total Pasangan Matched | B8: 941 | E8: Tanggal | F8: 526
A9: ✅ Semua Field Cocok | B9: 235 | C9: =B9/B8 -> 0.24973433 | E9: Berat Masuk | F9: 0
A10: ❌ Ada Perbedaan | B10: 706 | C10: =B10/B8 -> 0.75026567 | E10: Berat Keluar | F10: 0
A11: Data Orphan (tidak ditemukan) | B11: 0 | E11: Berat Netto WINS | F11: 0
E12: Berat Netto Relasi | F12: 0
A13: Metode Matching: | E13: Jam Masuk | F13: 94
A14: Fase 1: No Seri + No Kontrak = 439 | E14: Jam Keluar | F14: 104
A15: Fase 2: No Seri + Tanggal = 143 | E15: Penimbang | F15: 46
A16: Fase 3: No Seri saja = 359
A18: DETAIL PERBANDINGAN | F18: NO POLISI | I18: NO KONTRAK | L18: RELASI / DO | O18: TANGGAL | R18: BERAT MASUK | U18: BERAT KELUAR | X18: NETTO PT WINS | AB18: NETTO RELASI | AF18: JAM MASUK | AI18: JAM KELUAR | AL18: PENIMBANG | AO18: INFO TAMBAHAN DATABASE
A19: No | B19: No Seri | C19: Metode Match | D19: Status | F19: Tes | G19: Database | H19: Cek | I19: Tes | J19: Database | K19: Cek | L19: Tes (Relasi/DO) | M19: DB (DO) | N19: DB (Relasi) | O19: Tes | P19: Database | Q19: Cek | R19: Tes | S19: Database | T19: Cek | U19: Tes | V19: Database | W19: Cek | X19: Tes | Y19: Database | Z19: Cek | AA19: Selisih | AB19: Tes | AC19: Database | AD19: Cek | AE19: Selisih | AF19: Tes | AG19: Database | AH19: Cek | AI19: Tes | AJ19: Database | AK19: Cek | AL19: Tes | AM19: Database | AN19: Cek | AO19: No Seri Relasi | AP19: Driver | AQ19: Truck | AR19: Lokasi
A20: 1 | B20: 3 | C20: Seri+Kontrak | D20: ✅ Semua Cocok | F20: DP 8951 GB | G20: DP 8951 GB | H20: ✅ | I20: 215/PJB/MIS-WINS/X/2025 | J20: 215/PJB/MIS-WINS/X/2025 | K20: ✅ | L20: PT MIS - 1- 500 | M20: PT. MIS / 1 / 500 | N20: PT. MADINRA INTI SAWIT | O20: 45964 | P20: 45964 | Q20: ✅ | R20: 13680 | S20: 13680 | T20: ✅ | U20: 4080 | V20: 4080 | W20: ✅ | X20: 9600 | Y20: 9600 | Z20: ✅ | AA20: 0 | AB20: 9580 | AC20: 9580 | AD20: ✅ | AE20: 0 | AF20: 0.34305556 | AG20: 0.34305556 | AH20: ✅ | AI20: 0.4125 | AJ20: 0.4125 | AK20: ✅ | AL20: samsira | AM20: samsira | AN20: ✅ | AO20: CPO000003MIS | AQ20: 6 Roda | AR20: Pomala
A21: 2 | B21: 4 | C21: Seri+Kontrak | D21: ✅ Semua Cocok | F21: DP 8821 GL | G21: DP 8821 GL | H21: ✅ | I21: 215/PJB/MIS-WINS/X/2025 | J21: 215/PJB/MIS-WINS/X/2025 | K21: ✅ | L21: PT MIS - 1- 500 | M21: PT. MIS / 1 / 500 | N21: PT. MADINRA INTI SAWIT | O21: 45964 | P21: 45964 | Q21: ✅ | R21: 13260 | S21: 13260 | T21: ✅ | U21: 3750 | V21: 3750 | W21: ✅ | X21: 9510 | Y21: 9510 | Z21: ✅ | AA21: 0 | AB21: 9480 | AC21: 9480 | AD21: ✅ | AE21: 0 | AF21: 0.34375 | AG21: 0.34375 | AH21: ✅ | AI21: 0.39375 | AJ21: 0.39375 | AK21: ✅ | AL21: samsira | AM21: samsira | AN21: ✅ | AO21: CPO000004MIS | AQ21: 6 Roda | AR21: Pomala
A22: 3 | B22: 5 | C22: Seri+Kontrak | D22: ✅ Semua Cocok | F22: DP 8036 GK | G22: DP 8036 GK | H22: ✅ | I22: 215/PJB/MIS-WINS/X/2025 | J22: 215/PJB/MIS-WINS/X/2025 | K22: ✅ | L22: PT MIS - 1- 500 | M22: PT. MIS / 1 / 500 | N22: PT. MADINRA INTI SAWIT | O22: 45964 | P22: 45964 | Q22: ✅ | R22: 13390 | S22: 13390 | T22: ✅ | U22: 4000 | V22: 4000 | W22: ✅ | X22: 9390 | Y22: 9390 | Z22: ✅ | AA22: 0 | AB22: 9370 | AC22: 9370 | AD22: ✅ | AE22: 0 | AF22: 0.34513889 | AG22: 0.34513889 | AH22: ✅ | AI22: 0.38263889 | AJ22: 0.38263889 | AK22: ✅ | AL22: samsira | AM22: samsira | AN22: ✅ | AO22: CPO000005MIS | AQ22: 6 Roda | AR22: Pomala
A23: 4 | B23: 6 | C23: Seri+Tanggal | D23: ❌ Ada Perbedaan | F23: DD 9236 XX | G23: DD 9236 XX | H23: ✅ | I23: SPK JM-WINS NO.001/XI/2025 | J23: 001/CPO/JM-WINS/XI/2025 | K23: ❌ | L23: PT JAS MULIA -1-500 | M23: PT. JAS MULIA / 1 / 512 | N23: PT. JAS MULIA | O23: 45971 | P23: 45971 | Q23: ✅ | R23: 45780 | S23: 45780 | T23: ✅ | U23: 17430 | V23: 17430 | W23: ✅ | X23: 28350 | Y23: 28350 | Z23: ✅ | AA23: 0 | AB23: 28370 | AC23: 28370 | AD23: ✅ | AE23: 0 | AF23: 0.67777778 | AG23: 0.67777778 | AH23: ✅ | AI23: 0.74930556 | AJ23: 0.74930556 | AK23: ✅ | AL23: samsira | AM23: samsira | AN23: ✅ | AO23: CPO000006JAS | AP23: IBRAHIM | AQ23: 12 Roda | AR23: Bone Bone
A24: 5 | B24: 7 | C24: Seri+Tanggal | D24: ❌ Ada Perbedaan | F24: BM 8315 QQ | G24: BM 8315 QO | H24: ❌ | I24: SPK JM-WINS NO.001/XI/2025 | J24: 001/CPO/JM-WINS/XI/2025 | K24: ❌ | L24: PT JAS MULIA -1-500 | M24: PT. JAS MULIA / 1 / 512 | N24: PT. JAS MULIA | O24: 45971 | P24: 45971 | Q24: ✅ | R24: 45890 | S24: 45890 | T24: ✅ | U24: 17510 | V24: 17510 | W24: ✅ | X24: 28380 | Y24: 28380 | Z24: ✅ | AA24: 0 | AB24: 28350 | AC24: 28350 | AD24: ✅ | AE24: 0 | AF24: 0.67986111 | AG24: 0.67986111 | AH24: ✅ | AI24: 0.76458333 | AJ24: 0.76458333 | AK24: ✅ | AL24: samsira | AM24: samsira | AN24: ✅ | AO24: CPO000007JAS | AP24: IQBAL | AQ24: 12 Roda | AR24: Bone Bone
A25: 6 | B25: 8 | C25: Seri+Tanggal | D25: ❌ Ada Perbedaan | F25: DD 8711 XX | G25: DD 8711 XX | H25: ✅ | I25: SPK JM-WINS NO.001/XI/2025 | J25: 001/CPO/JM-WINS/XI/2025 | K25: ❌ | L25: PT JAS MULIA -1-500 | M25: PT. JAS MULIA / 1 / 512 | N25: PT. JAS MULIA | O25: 45971 | P25: 45971 | Q25: ✅ | R25: 25090 | S25: 25090 | T25: ✅ | U25: 10860 | V25: 10860 | W25: ✅ | X25: 14230 | Y25: 14230 | Z25: ✅ | AA25: 0 | AB25: 14180 | AC25: 14180 | AD25: ✅ | AE25: 0 | AF25: 0.68680556 | AG25: 0.68680556 | AH25: ✅ | AI25: 0.76736111 | AJ25: 0.76736111 | AK25: ✅ | AL25: samsira | AM25: samsira | AN25: ✅ | AO25: CPO000008JAS | AP25: RONI RAKAN | AQ25: 10 Roda | AR25: Bone Bone
A26: 7 | B26: 9 | C26: Seri+Tanggal | D26: ❌ Ada Perbedaan | F26: B 1918 SXX | G26: B 1918 SXX | H26: ✅ | I26: SPK JM-WINS NO.001/XI/2025 | J26: 001/CPO/JM-WINS/XI/2025 | K26: ❌ | L26: PT JAS MULIA -1-500 | M26: PT. JAS MULIA / 1 / 512 | N26: PT. JAS MULIA | O26: 45971 | P26: 45971 | Q26: ✅ | R26: 26510 | S26: 26510 | T26: ✅ | U26: 11650 | V26: 11650 | W26: ✅ | X26: 14860 | Y26: 14860 | Z26: ✅ | AA26: 0 | AB26: 14870 | AC26: 14870 | AD26: ✅ | AE26: 0 | AF26: 0.6875 | AG26: 0.6875 | AH26: ✅ | AI26: 0.78055556 | AJ26: 0.78055556 | AK26: ✅ | AL26: samsira | AM26: samsira | AN26: ✅ | AO26: CPO000009JAS | AP26: WALDI | AQ26: 10 Roda | AR26: Bone Bone
A27: 8 | B27: 10 | C27: Seri+Tanggal | D27: ❌ Ada Perbedaan | F27: BH 8459 MY | G27: BH 8459 MY | H27: ✅ | I27: SPK JM-WINS NO.001/XI/2025 | J27: 001/CPO/JM-WINS/XI/2025 | K27: ❌ | L27: PT JAS MULIA -1-500 | M27: PT. JAS MULIA / 1 / 512 | N27: PT. JAS MULIA | O27: 45972 | P27: 45972 | Q27: ✅ | R27: 26630 | S27: 26630 | T27: ✅ | U27: 12110 | V27: 12110 | W27: ✅ | X27: 14520 | Y27: 14520 | Z27: ✅ | AA27: 0 | AB27: 14540 | AC27: 14540 | AD27: ✅ | AE27: 0 | AF27: 0.33541667 | AG27: 0.33541667 | AH27: ✅ | AI27: 0.37708333 | AJ27: 0.37708333 | AK27: ✅ | AL27: samsira | AM27: samsira | AN27: ✅ | AO27: CPO000010JAS | AP27: ERWIN | AQ27: 10 Roda | AR27: Bone Bone
A28: 9 | B28: 11 | C28: Seri+Tanggal | D28: ❌ Ada Perbedaan | F28: B 1918 SXX | G28: B 1918 SXX | H28: ✅ | I28: SPK JM-WINS NO.001/XI/2025 | J28: 001/CPO/JM-WINS/XI/2025 | K28: ❌ | L28: PT JAS MULIA -1-500 | M28: PT. JAS MULIA / 1 / 512 | N28: PT. JAS MULIA | O28: 45972 | P28: 45972 | Q28: ✅ | R28: 26500 | S28: 26500 | T28: ✅ | U28: 11690 | V28: 11690 | W28: ✅ | X28: 14810 | Y28: 14810 | Z28: ✅ | AA28: 0 | AB28: 14870 | AC28: 14870 | AD28: ✅ | AE28: 0 | AF28: 0.56944444 | AG28: 0.56944444 | AH28: ✅ | AI28: 0.62291667 | AJ28: 0.62291667 | AK28: ✅ | AL28: samsira | AM28: samsira | AN28: ✅ | AO28: CPO000011JAS | AP28: WALDI | AQ28: 10 Roda | AR28: Bone Bone
A29: 10 | B29: 12 | C29: Seri+Tanggal | D29: ❌ Ada Perbedaan | F29: DD 8711 XX | G29: DD 8711 XX | H29: ✅ | I29: SPK JM-WINS NO.001/XI/2025 | J29: 001/CPO/JM-WINS/XI/2025 | K29: ❌ | L29: PT JAS MULIA -1-500 | M29: PT. JAS MULIA / 1 / 512 | N29: PT. JAS MULIA | O29: 45972 | P29: 45972 | Q29: ✅ | R29: 25140 | S29: 25140 | T29: ✅ | U29: 10820 | V29: 10820 | W29: ✅ | X29: 14320 | Y29: 14320 | Z29: ✅ | AA29: 0 | AB29: 14270 | AC29: 14270 | AD29: ✅ | AE29: 0 | AF29: 0.57083333 | AG29: 0.57083333 | AH29: ✅ | AI29: 0.65 | AJ29: 0.65 | AK29: ✅ | AL29: samsira | AM29: samsira | AN29: ✅ | AO29: CPO000012JAS | AP29: RONI RAKAN | AQ29: 10 Roda | AR29: Bone Bone
A30: 11 | B30: 13 | C30: Seri+Tanggal | D30: ❌ Ada Perbedaan | F30: DD 9236 XX | G30: DD 9236 XX | H30: ✅ | I30: SPK JM-WINS NO.001/XI/2025 | J30: 001/CPO/JM-WINS/XI/2025 | K30: ❌ | L30: PT JAS MULIA -1-500 | M30: PT. JAS MULIA / 1 / 512 | N30: PT. JAS MULIA | O30: 45972 | P30: 45972 | Q30: ✅ | R30: 45950 | S30: 45950 | T30: ✅ | U30: 17730 | V30: 17730 | W30: ✅ | X30: 28220 | Y30: 28220 | Z30: ✅ | AA30: 0 | AB30: 28300 | AC30: 28300 | AD30: ✅ | AE30: 0 | AF30: 0.57222222 | AG30: 0.57222222 | AH30: ✅ | AI30: 0.63541667 | AJ30: 0.63541667 | AK30: ✅ | AL30: samsira | AM30: samsira | AN30: ✅ | AO30: CPO000013JAS | AP30: IBRAHIM | AQ30: 12 Roda | AR30: Bone Bone
A31: 12 | B31: 14 | C31: Seri+Tanggal | D31: ❌ Ada Perbedaan | F31: BH 8459 MY | G31: BH 8459 MY | H31: ✅ | I31: SPK JM-WINS NO.001/XI/2025 | J31: 001/CPO/JM-WINS/XI/2025 | K31: ❌ | L31: PT JAS MULIA -1-500 | M31: PT. JAS MULIA / 1 / 512 | N31: PT. JAS MULIA | O31: 45972 | P31: 45972 | Q31: ✅ | R31: 26570 | S31: 26570 | T31: ✅ | U31: 12130 | V31: 12130 | W31: ✅ | X31: 14440 | Y31: 14440 | Z31: ✅ | AA31: 0 | AB31: 14470 | AC31: 14470 | AD31: ✅ | AE31: 0 | AF31: 0.61180556 | AG31: 0.61180556 | AH31: ✅ | AI31: 0.68125 | AJ31: 0.68125 | AK31: ✅ | AL31: samsira | AM31: samsira | AN31: ✅ | AO31: CPO000014JAS | AP31: ERWIN | AQ31: 10 Roda | AR31: Bone Bone
A32: 13 | B32: 15 | C32: Seri+Tanggal | D32: ❌ Ada Perbedaan | F32: BM 8316 QO | G32: BM 8315 QO | H32: ❌ | I32: SPK JM-WINS NO.001/XI/2025 | J32: 001/CPO/JM-WINS/XI/2025 | K32: ❌ | L32: PT JAS MULIA -1-500 | M32: PT. JAS MULIA / 1 / 512 | N32: PT. JAS MULIA | O32: 45972 | P32: 45972 | Q32: ✅ | R32: 45750 | S32: 45750 | T32: ✅ | U32: 17460 | V32: 17460 | W32: ✅ | X32: 28290 | Y32: 28290 | Z32: ✅ | AA32: 0 | AB32: 28300 | AC32: 28300 | AD32: ✅ | AE32: 0 | AF32: 0.61458333 | AG32: 0.61458333 | AH32: ✅ | AI32: 0.68333333 | AJ32: 0.68333333 | AK32: ✅ | AL32: samsira | AM32: samsira | AN32: ✅ | AO32: CPO000015JAS | AP32: IQBAL | AQ32: 12 Roda | AR32: Bone Bone
A33: 14 | B33: 16 | C33: Seri+Tanggal | D33: ❌ Ada Perbedaan | F33: DD 9236 XX | G33: DD 9236 XX | H33: ✅ | I33: SPK JM-WINS NO.001/XI/2025 | J33: 001/CPO/JM-WINS/XI/2025 | K33: ❌ | L33: PT JAS MULIA -1-500 | M33: PT. JAS MULIA / 1 / 512 | N33: PT. JAS MULIA | O33: 45972 | P33: 45972 | Q33: ✅ | R33: 45840 | S33: 45840 | T33: ✅ | U33: 17690 | V33: 17690 | W33: ✅ | X33: 28150 | Y33: 28150 | Z33: ✅ | AA33: 0 | AB33: 28070 | AC33: 28070 | AD33: ✅ | AE33: 0 | AF33: 0.86597222 | AG33: 0.86597222 | AH33: ✅ | AI33: 0.97638889 | AJ33: 0.97638889 | AK33: ✅ | AL33: samsira | AM33: samsira | AN33: ✅ | AO33: CPO000016JAS | AP33: IBRAHIM | AQ33: 12 Roda | AR33: Bone Bone
A34: 15 | B34: 17 | C34: Seri+Tanggal | D34: ❌ Ada Perbedaan | F34: DD 8711 XX | G34: DD 8711 XX | H34: ✅ | I34: SPK JM-WINS NO.001/XI/2025 | J34: 001/CPO/JM-WINS/XI/2025 | K34: ❌ | L34: PT JAS MULIA -1-500 | M34: PT. JAS MULIA / 1 / 512 | N34: PT. JAS MULIA | O34: 45972 | P34: 45972 | Q34: ✅ | R34: 25030 | S34: 25030 | T34: ✅ | U34: 10790 | V34: 10790 | W34: ✅ | X34: 14240 | Y34: 14240 | Z34: ✅ | AA34: 0 | AB34: 14190 | AC34: 14190 | AD34: ✅ | AE34: 0 | AF34: 0.87638889 | AG34: 0.87638889 | AH34: ✅ | AI34: 0.99583333 | AJ34: 0.99583333 | AK34: ✅ | AL34: samsira | AM34: samsira | AN34: ✅ | AO34: CPO000017JAS | AP34: RONI RAKAN | AQ34: 10 Roda | AR34: Bone Bone
... A76: 57 | B76: 39 | C76: Seri+Kontrak | D76: ✅ Semua Cocok | F76: WNE 02 | G76: WNE 02 | H76: ✅ | I76: KMP01092025 | J76: KMP01092025 | K76: ✅ | L76: PT KMP-1 500 | M76: PT. KMP / 1 / 500 | N76: PT. KASMAR MATANO PERSADA | O76: 45932 | P76: 45932 | Q76: ✅ | R76: 26550 | S76: 26550 | T76: ✅ | U76: 11770 | V76: 11770 | W76: ✅ | X76: 14780 | Y76: 14780 | Z76: ✅ | AA76: 0 | AB76: 14800 | AC76: 14800 | AD76: ✅ | AE76: 0 | AF76: 0.85277778 | AG76: 0.85277778 | AH76: ✅ | AI76: 0.94027778 | AJ76: 0.94027778 | AK76: ✅ | AL76: samsira | AM76: samsira | AN76: ✅ | AO76: CPO000039KMP | AP76: WALDI | AQ76: 10 Roda | AR76: Masamba
A77: 58 | B77: 39 | C77: Seri+Kontrak | D77: ✅ Semua Cocok | F77: DP 8935 UA | G77: DP 8935 UA | H77: ✅ | I77: 245/PJB/MIS-WINS/XI/2025 | J77: 245/PJB/MIS-WINS/XI/2025 | K77: ✅ | L77: PT MIS - 2 - 600 | M77: PT. MIS / 2 / 600 | N77: PT. MADINRA INTI SAWIT | O77: 46001 | P77: 46001 | Q77: ✅ | R77: 13900 | S77: 13900 | T77: ✅ | U77: 4020 | V77: 4020 | W77: ✅ | X77: 9690 | Y77: 9690 | Z77: ✅ | AA77: 0 | AB77: 9660 | AC77: 9660 | AD77: ✅ | AE77: 0 | AF77: 0.34166667 | AG77: 0.34166667 | AH77: ✅ | AI77: 0.40208333 | AJ77: 0.40208333 | AK77: ✅ | AL77: Samsira | AM77: samsira | AN77: ✅ | AO77: CPO000039MIS | AQ77: 6 Roda | AR77: Pomala
A78: 59 | B78: 39 | C78: Seri+Kontrak | D78: ❌ Ada Perbedaan | F78: DP 8935 UA | G78: DP 8935 UA | H78: ✅ | I78: 245/PJB/MIS-WINS/XI/2025 | J78: 245/PJB/MIS-WINS/XI/2025 | K78: ✅ | L78: PT MIS - 2 - 600 | M78: PT. MIS / 2 / 600 | N78: PT. MADINRA INTI SAWIT | O78: 46001 | P78: 46001 | Q78: ✅ | R78: 14020 | S78: 14020 | T78: ✅ | U78: 3980 | V78: 3980 | W78: ✅ | X78: 10040 | Y78: 10040 | Z78: ✅ | AA78: 0 | AB78: 9970 | AC78: 9970 | AD78: ✅ | AE78: 0 | AF78: 0.33819444 | AG78: 0.33819444 | AH78: ❌ | AI78: 0.37777778 | AJ78: 0.37777778 | AK78: ✅ | AL78: Samsira | AM78: samsira | AN78: ✅ | AO78: CPO000039MIS | AQ78: 6 Roda | AR78: Pomala
A79: 60 | B79: 40 | C79: Seri+Kontrak | D79: ✅ Semua Cocok | F79: WNE 03 | G79: WNE 03 | H79: ✅ | I79: KMP01092025 | J79: KMP01092025 | K79: ✅ | L79: PT KMP-1 500 | M79: PT. KMP / 1 / 500 | N79: PT. KASMAR MATANO PERSADA | O79: 45932 | P79: 45932 | Q79: ✅ | R79: 26640 | S79: 26640 | T79: ✅ | U79: 12080 | V79: 12080 | W79: ✅ | X79: 14560 | Y79: 14560 | Z79: ✅ | AA79: 0 | AB79: 14580 | AC79: 14580 | AD79: ✅ | AE79: 0 | AF79: 0.89861111 | AG79: 0.89861111 | AH79: ✅ | AI79: 0.99236111 | AJ79: 0.99236111 | AK79: ✅ | AL79: samsira | AM79: samsira | AN79: ✅ | AO79: CPO000040KMP | AP79: ERWIN | AQ79: 10 Roda | AR79: Masamba
A80: 61 | B80: 40 | C80: Seri+Kontrak | D80: ✅ Semua Cocok | F80: DP 9826 GA | G80: DP 9826 GA | H80: ✅ | I80: 245/PJB/MIS-WINS/XI/2025 | J80: 245/PJB/MIS-WINS/XI/2025 | K80: ✅ | L80: PT MIS - 2 - 600 | M80: PT. MIS / 2 / 600 | N80: PT. MADINRA INTI SAWIT | O80: 46001 | P80: 46001 | Q80: ✅ | R80: 13520 | S80: 13520 | T80: ✅ | U80: 4060 | V80: 4060 | W80: ✅ | X80: 9460 | Y80: 9460 | Z80: ✅ | AA80: 0 | AB80: 9430 | AC80: 9430 | AD80: ✅ | AE80: 0 | AF80: 0.34375 | AG80: 0.34375 | AH80: ✅ | AI80: 0.41805556 | AJ80: 0.41805556 | AK80: ✅ | AL80: Samsira | AM80: samsira | AN80: ✅ | AO80: CPO000040MIS | AQ80: 6 Roda | AR80: Pomala
A81: 62 | B81: 40 | C81: Seri+Kontrak | D81: ✅ Semua Cocok | F81: DP 9826 GA | G81: DP 9826 GA | H81: ✅ | I81: 265/PJB/MIS-WINS/XII/2025 | J81: 265/PJB/MIS-WINS/XII/2025 | K81: ✅ | L81: PT MIS - 3 - 500 | M81: PT. MIS / 3 / 600 | N81: PT. MADINRA INTI SAWIT | O81: 46001 | P81: 46001 | Q81: ✅ | R81: 13900 | S81: 13900 | T81: ✅ | U81: 13710 | V81: 13710 | W81: ✅ | X81: 190 | Y81: 190 | Z81: ✅ | AA81: 0 | AB81: 190 | AC81: 190 | AD81: ✅ | AE81: 0 | AF81: 0.34166667 | AG81: 0.34166667 | AH81: ✅ | AI81: 0.40208333 | AJ81: 0.40208333 | AK81: ✅ | AL81: samsira | AM81: samsira | AN81: ✅ | AO81: CPO000040MIS | AQ81: 6 Roda | AR81: Pomala
A82: 63 | B82: 41 | C82: Seri+Kontrak | D82: ❌ Ada Perbedaan | F82: DP 8821 GL | G82: DP 8821 GL | H82: ✅ | I82: 215/PJB/MIS-WINS/X/2025 | J82: 215/PJB/MIS-WINS/X/2025 | K82: ✅ | L82: PT MIS - 1- 500 | M82: PT. MIS / 1 / 500 | N82: PT. MADINRA INTI SAWIT | O82: 45962 | P82: 45962 | Q82: ✅ | R82: 13370 | S82: 13370 | T82: ✅ | U82: 3790 | V82: 3790 | W82: ✅ | X82: 9580 | Y82: 9580 | Z82: ✅ | AA82: 0 | AB82: 9540 | AC82: 9540 | AD82: ✅ | AE82: 0 | AF82: 0.97569444 | AG82: 0.97569444 | AH82: ❌ | AI82: 0.047222222 | AJ82: 0.047222222 | AK82: ✅ | AL82: samsira | AM82: samsira | AN82: ✅ | AO82: CPO000041MIS | AQ82: 6 Roda | AR82: Pomala
A83: 64 | B83: 41 | C83: Seri+Kontrak | D83: ✅ Semua Cocok | F83: DP 8004 GJ | G83: DP 8004 GJ | H83: ✅ | I83: 245/PJB/MIS-WINS/XI/2025 | J83: 245/PJB/MIS-WINS/XI/2025 | K83: ✅ | L83: PT MIS - 2 - 600 | M83: PT. MIS / 2 / 600 | N83: PT. MADINRA INTI SAWIT | O83: 46001 | P83: 46001 | Q83: ✅ | R83: 13580 | S83: 13580 | T83: ✅ | U83: 3980 | V83: 3980 | W83: ✅ | X83: 9600 | Y83: 9600 | Z83: ✅ | AA83: 0 | AB83: 9570 | AC83: 9570 | AD83: ✅ | AE83: 0 | AF83: 0.34513889 | AG83: 0.34513889 | AH83: ✅ | AI83: 0.43541667 | AJ83: 0.43541667 | AK83: ✅ | AL83: Samsira | AM83: samsira | AN83: ✅ | AO83: CPO000041MIS | AQ83: 6 Roda | AR83: Pomala
A84: 65 | B84: 42 | C84: Seri+Kontrak | D84: ✅ Semua Cocok | F84: DP 8951 GB | G84: DP 8951 GB | H84: ✅ | I84: 215/PJB/MIS-WINS/X/2025 | J84: 215/PJB/MIS-WINS/X/2025 | K84: ✅ | L84: PT MIS - 1- 500 | M84: PT. MIS / 1 / 500 | N84: PT. MADINRA INTI SAWIT | O84: 45962 | P84: 45962 | Q84: ✅ | R84: 13700 | S84: 13700 | T84: ✅ | U84: 4070 | V84: 4070 | W84: ✅ | X84: 9630 | Y84: 9630 | Z84: ✅ | AA84: 0 | AB84: 9590 | AC84: 9590 | AD84: ✅ | AE84: 0 | AF84: 0.97708333 | AG84: 0.97708333 | AH84: ✅ | AI84: 0.058333333 | AJ84: 0.058333333 | AK84: ✅ | AL84: samsira | AM84: samsira | AN84: ✅ | AO84: CPO000042MIS | AQ84: 6 Roda | AR84: Pomala
...

Sheet Database
N2: =MAX(N4:N1238) -> 28960
B3: Jumlah | C3: No. Seri | D3: No Seri Relasi | E3: No. Polisi | F3: No Kontrak | G3: DO | H3: Relasi | I3: Produk | J3: Truck | K3: Tanggal Masuk | L3: Berat Masuk | M3: Berat Keluar | N3: Berat Netto PT WINS | O3: Berat Relasi | P3: Jam Masuk | Q3: Jam Keluar | R3: Penimbang | S3: Driver | T3: Distance (Km) | U3: Transportir | V3: Lokasi pengiriman | W3: Column3 | Y3: Relasi | Z3: Lokasi | AA3: Transportir | AK3: Nama Relasi | AL3: Kode | AM3: Nama Relasi | AN3: Kode Suffix | AO3: Lokasi pengiriman/Pengantaran | AP3: Distance (Km) | AQ3: Produk | AR3: Jarak PP (Km) | AS3: 6 Roda | AT3: 10 Roda | AU3: 12 Roda | AX3: liter/PP
Y4: PT JAS MULIA | Z4: Makassar | AA4: CV WIL/CV Lingkar | AD4: B 1918 SXX | AE4: Waldi | AF4: Mercy | AG4: 10 | AM4: PT. MADINRA INTI SAWIT | AN4: MIS | AO4: Pomala | AP4: 494 | AQ4: CPO | AR4: =AP4*2 -> 988 | AS4: 800 | AT4: 800 | AU4: 800
Y5: PT KASMAR MATANO PERSADA | Z5: Palu | AA5: BJL | AB5: 223 | AD5: DD 8711 XX | AE5: Roni Rakan | AF5: Mercy | AG5: 10 | AM5: PT. WIJAYA NUSANTARA ENERGI | AN5: WNE | AQ5: B-40
Y6: PT MADINRA INTI SAWIT | Z6: Bone Bone | AA6: CV WIL | AB6: 70 | AD6: BM 8315 QO | AE6: Iqbal | AF6: Howo | AG6: 12 | AM6: PT. JAS MULIA | AN6: JAS | AO6: Bone Bone | AP6: 68 | AQ6: CPO | AR6: =AP6*2 -> 136 | AS6: 120 | AT6: 120 | AU6: 120 | AX6: 60 | AY6: 12 Roda | AZ6: 50 | BA6: 10 roda
Y7: PT PERKEBUNAN NUSANTARA | Z7: Masamba | AA7: CV WIL | AB7: 54 | AD7: DD 9236 XX | AE7: Ibrahim | AF7: Howo | AG7: 12 | AM7: PT. KASMAR MATANO PERSADA | AN7: KMP | AO7: Masamba | AP7: 53 | AQ7: CPO | AR7: =AP7*2 -> 106 | AS7: 110 | AT7: 110 | AU7: 110 | AX7: 50 | AY7: 12 Roda | AZ7: 45 | BA7: 10 roda
Y8: PT BUKIT JEJER LESTARI | Z8: Pomala | AA8: CV Lingkar | AB8: 218 | AD8: BH 8459 MY | AE8: Hamsal | AF8: Mercy | AG8: 10 | AM8: PT. PERKEBUNAN NUSANTARA | AN8: PN | AO8: Burau | AP8: 99 | AQ8: CPO | AR8: =AP8*2 -> 198 | AS8: 140 | AT8: 140 | AU8: 140 | AX8: 75 | AY8: 12 Roda | AZ8: 70 | BA8: 10 roda
B9: 1 | C9: 000018 | D9: =I9&C9&_xlfn.XLOOKUP(H9,$AM$4:$AM$26,$AN$4:$AN$26,"") -> CPO000018KMP | E9: WNE 01 | F9: KMP01092025 | G9: PT. KMP / 1 / 500 | H9: PT. KASMAR MATANO PERSADA | I9: CPO | J9: =IF(MIN(L9,M9)<=5000,"6 Roda",IF(MIN(L9,M9)<=13800,"10 Roda","12 Roda")) -> 10 Roda | K9: 45930 | L9: 25000 | M9: 10740 | N9: 14260 | O9: 14360 | P9: 0.11944444 | Q9: 0.6125 | R9: samsira | S9: RONI RAKAN | T9: =IFERROR(_xlfn.XLOOKUP(H9,$AM$4:$AM$18,$AP$4:$AP$18,""),0) -> 53 | U9: WIL | V9: =IFERROR(_xlfn.XLOOKUP(H9,$AM$4:$AM$18,$AO$4:$AO$18,""),"") -> Masamba | Y9: PT WIJAYA NUSANTARA ENERGI | Z9: Burau | AA9: CV WIL | AB9: 99 | AD9: WNE 01 | AE9: Roni Rakan | AF9: Mercy | AG9: 10 | AM9: PT. BUKIT JEJER LESTARI | AN9: BJL | AO9: Palu | AP9: 562 | AQ9: RBDPL | AR9: =AP9*2 -> 1124 | AS9: 1200 | AT9: 1200 | AU9: 1200
B10: 1 | C10: 000019 | D10: =I10&C10&_xlfn.XLOOKUP(H10,$AM$4:$AM$26,$AN$4:$AN$26,"") -> CPO000019KMP | E10: WNE 06 | F10: KMP01092025 | G10: PT. KMP / 1 / 500 | H10: PT. KASMAR MATANO PERSADA | I10: CPO | J10: =IF(MIN(L10,M10)<=5000,"6 Roda",IF(MIN(L10,M10)<=13800,"10 Roda","12 Roda")) -> 12 Roda | K10: 45930 | L10: 45770 | M10: 17820 | N10: 27950 | O10: 28420 | P10: 0.45138889 | Q10: 0.55138889 | R10: samsira | S10: IBRAHIM | T10: =IFERROR(_xlfn.XLOOKUP(H10,$AM$4:$AM$18,$AP$4:$AP$18,""),0) -> 53 | U10: WIL | V10: =IFERROR(_xlfn.XLOOKUP(H10,$AM$4:$AM$18,$AO$4:$AO$18,""),"") -> Masamba | Y10: PT WISAN PETRO ENERGI | Z10: Makassar | AD10: WNE 02 | AE10: Waldi | AF10: Mercy | AG10: 10 | AM10: PT. WISAN PETRO ENERGI | AN10: WPE | AQ10: B-40
B11: 1 | C11: 000020 | D11: =I11&C11&_xlfn.XLOOKUP(H11,$AM$4:$AM$26,$AN$4:$AN$26,"") -> CPO000020KMP | E11: WNE 05 | F11: KMP01092025 | G11: PT. KMP / 1 / 500 | H11: PT. KASMAR MATANO PERSADA | I11: CPO | J11: =IF(MIN(L11,M11)<=5000,"6 Roda",IF(MIN(L11,M11)<=13800,"10 Roda","12 Roda")) -> 12 Roda | K11: 45930 | L11: 45930 | M11: 18580 | N11: 27350 | O11: 28520 | P11: 0.45625 | Q11: 0.64027778 | R11: samsira | S11: IQBAL | T11: =IFERROR(_xlfn.XLOOKUP(H11,$AM$4:$AM$18,$AP$4:$AP$18,""),0) -> 53 | U11: WIL | V11: =IFERROR(_xlfn.XLOOKUP(H11,$AM$4:$AM$18,$AO$4:$AO$18,""),"") -> Masamba | Y11: PT MADU LINGGA RAHARJA | AD11: WNE 03 | AE11: Hamsal | AF11: Mercy | AG11: 10 | AM11: PT. MADU LINGGA RAHARJA | AN11: MLR | AQ11: CPO
B12: 1 | C12: 000021 | D12: =I12&C12&_xlfn.XLOOKUP(H12,$AM$4:$AM$26,$AN$4:$AN$26,"") -> CPO000021KMP | E12: WNE 03 | F12: KMP01092025 | G12: PT. KMP / 1 / 500 | H12: PT. KASMAR MATANO PERSADA | I12: CPO | J12: =IF(MIN(L12,M12)<=5000,"6 Roda",IF(MIN(L12,M12)<=13800,"10 Roda","12 Roda")) -> 10 Roda | K12: 45930 | L12: 26780 | M12: 12170 | N12: 14610 | O12: 14720 | P12: 0.45972222 | Q12: 0.55 | R12: samsira | S12: ERWIN | T12: =IFERROR(_xlfn.XLOOKUP(H12,$AM$4:$AM$18,$AP$4:$AP$18,""),0) -> 53 | U12: WIL | V12: =IFERROR(_xlfn.XLOOKUP(H12,$AM$4:$AM$18,$AO$4:$AO$18,""),"") -> Masamba | Y12: CV HALILINTAR SAKTI ABADI | AD12: WNE 05 | AE12: Iqbal | AF12: Howo | AG12: 12 | AM12: CV. HALILINTAR SAKTI ABADI | AN12: HSA | AO12: Makassar | AP12: 360 | AQ12: RBDPL | AR12: =AP12*2 -> 720 | AS12: 475 | AT12: 475 | AU12: 475 | AX12: 300 | AY12: 12 Roda | AZ12: 280 | BA12: 10 roda
B13: 1 | C13: 000022 | D13: =I13&C13&_xlfn.XLOOKUP(H13,$AM$4:$AM$26,$AN$4:$AN$26,"") -> CPO000022KMP | E13: WNE 01 | F13: KMP01092025 | G13: PT. KMP / 1 / 500 | H13: PT. KASMAR MATANO PERSADA | I13: CPO | J13: =IF(MIN(L13,M13)<=5000,"6 Roda",IF(MIN(L13,M13)<=13800,"10 Roda","12 Roda")) -> 10 Roda | K13: 45930 | L13: 24870 | M13: 10660 | N13: 14210 | O13: 14200 | P13: 0.86944444 | Q13: 0.94236111 | R13: samsira | S13: RONI RAKAN | T13: =IFERROR(_xlfn.XLOOKUP(H13,$AM$4:$AM$18,$AP$4:$AP$18,""),0) -> 53 | U13: WIL | V13: =IFERROR(_xlfn.XLOOKUP(H13,$AM$4:$AM$18,$AO$4:$AO$18,""),"") -> Masamba | Y13: CV SURYA CAHAYA MAS | AD13: WNE 06 | AE13: Ibrahim | AF13: Howo | AG13: 12 | AM13: CV. SURYA CAHAYA MAS | AN13: SCM | AO13: Gowa | AP13: 400 | AQ13: RBDPL | AR13: =AP13*2 -> 800 | AS13: 475 | AT13: 475 | AU13: 475 | AX13: 320 | AY13: 12 Roda | AZ13: 300 | BA13: 10 roda
B14: 1 | C14: 000024 | D14: =I14&C14&_xlfn.XLOOKUP(H14,$AM$4:$AM$26,$AN$4:$AN$26,"") -> CPO000024KMP | E14: WNE 06 | F14: KMP01092025 | G14: PT. KMP / 1 / 500 | H14: PT. KASMAR MATANO PERSADA | I14: CPO | J14: =IF(MIN(L14,M14)<=5000,"6 Roda",IF(MIN(L14,M14)<=13800,"10 Roda","12 Roda")) -> 12 Roda | K14: 45930 | L14: 45770 | M14: 17500 | N14: 28270 | O14: 28080 | P14: 0.87291667 | Q14: 0.95 | R14: samsira | S14: IBRAHIM | T14: =IFERROR(_xlfn.XLOOKUP(H14,$AM$4:$AM$18,$AP$4:$AP$18,""),0) -> 53 | U14: WIL | V14: =IFERROR(_xlfn.XLOOKUP(H14,$AM$4:$AM$18,$AO$4:$AO$18,""),"") -> Masamba | Y14: CV DUTA ABADI | AM14: CV. DUTA ABADI | AN14: DA | AO14: Makassar | AP14: 360 | AQ14: RBDPL | AR14: =AP14*2 -> 720 | AS14: 475 | AT14: 475 | AU14: 475 | AX14: 300 | AY14: 12 Roda | AZ14: 280 | BA14: 10 roda
B15: 1 | C15: 000023 | D15: =I15&C15&_xlfn.XLOOKUP(H15,$AM$4:$AM$26,$AN$4:$AN$26,"") -> CPO000023KMP | E15: WNE 03 | F15: KMP01092025 | G15: PT. KMP / 1 / 500 | H15: PT. KASMAR MATANO PERSADA | I15: CPO | J15: =IF(MIN(L15,M15)<=5000,"6 Roda",IF(MIN(L15,M15)<=13800,"10 Roda","12 Roda")) -> 10 Roda | K15: 45931 | L15: 26650 | M15: 12110 | N15: 14540 | O15: 14540 | P15: 0.87013889 | Q15: 0.0076388889 | R15: samsira | S15: ERWIN | T15: =IFERROR(_xlfn.XLOOKUP(H15,$AM$4:$AM$18,$AP$4:$AP$18,""),0) -> 53 | U15: WIL | V15: =IFERROR(_xlfn.XLOOKUP(H15,$AM$4:$AM$18,$AO$4:$AO$18,""),"") -> Masamba | Y15: PT GRAHA MINING UTAMA | AM15: PT. WIJAYA INTI NUSANTARA | AN15: WIN | AO15: Torobulu | AP15: 642 | AQ15: RBDPL | AR15: =AP15*2 -> 1284 | AS15: 1500 | AT15: 1500 | AU15: 1500 | AX15: 750 | AY15: 12 Roda | AZ15: 640 | BA15: 10 roda
B16: 1 | C16: 000025 | D16: =I16&C16&_xlfn.XLOOKUP(H16,$AM$4:$AM$26,$AN$4:$AN$26,"") -> CPO000025KMP | E16: WNE 05 | F16: KMP01092025 | G16: PT. KMP / 1 / 500 | H16: PT. KASMAR MATANO PERSADA | I16: CPO | J16: =IF(MIN(L16,M16)<=5000,"6 Roda",IF(MIN(L16,M16)<=13800,"10 Roda","12 Roda")) -> 12 Roda | K16: 45931 | L16: 45650 | M16: 17580 | N16: 28070 | O16: 27180 | P16: 0.89930556 | Q16: 0.015972222 | R16: samsira | S16: IQBAL | T16: =IFERROR(_xlfn.XLOOKUP(H16,$AM$4:$AM$18,$AP$4:$AP$18,""),0) -> 53 | U16: WIL | V16: =IFERROR(_xlfn.XLOOKUP(H16,$AM$4:$AM$18,$AO$4:$AO$18,""),"") -> Masamba | Y16: PT WIJAYA INTI NUSANTARA | AM16: PT. TRI DAYA JAYA | AN16: TDJ | AO16: Siumbatu | AP16: 473 | AQ16: RBDPL | AR16: =AP16*2 -> 946 | AS16: 1000 | AT16: 1000 | AU16: 1000 | AX16: 400 | AY16: 12 Roda | AZ16: 360 | BA16: 10 roda
B17: 1 | C17: 000026 | D17: =I17&C17&_xlfn.XLOOKUP(H17,$AM$4:$AM$26,$AN$4:$AN$26,"") -> CPO000026KMP | E17: WNE 03 | F17: KMP01092025 | G17: PT. KMP / 1 / 500 | H17: PT. KASMAR MATANO PERSADA | I17: CPO | J17: =IF(MIN(L17,M17)<=5000,"6 Roda",IF(MIN(L17,M17)<=13800,"10 Roda","12 Roda")) -> 10 Roda | K17: 45931 | L17: 26600 | M17: 12030 | N17: 14570 | O17: 14560 | P17: 0.54930556 | Q17: 0.60208333 | R17: samsira | S17: ERWIN | T17: =IFERROR(_xlfn.XLOOKUP(H17,$AM$4:$AM$18,$AP$4:$AP$18,""),0) -> 53 | U17: WIL | V17: =IFERROR(_xlfn.XLOOKUP(H17,$AM$4:$AM$18,$AO$4:$AO$18,""),"") -> Masamba | AM17: PT. PANDU URANE PERKASA | AN17: PUP | AO17: Torobulu | AP17: 642 | AQ17: RBDPL | AR17: =AP17*2 -> 1284 | AS17: 1500 | AT17: 1500 | AU17: 1500 | AX17: 750 | AY17: 12 Roda | AZ17: 640 | BA17: 10 roda
B18: 1 | C18: 000027 | D18: =I18&C18&_xlfn.XLOOKUP(H18,$AM$4:$AM$26,$AN$4:$AN$26,"") -> CPO000027KMP | E18: WNE 05 | F18: KMP01092025 | G18: PT. KMP / 1 / 500 | H18: PT. KASMAR MATANO PERSADA | I18: CPO | J18: =IF(MIN(L18,M18)<=5000,"6 Roda",IF(MIN(L18,M18)<=13800,"10 Roda","12 Roda")) -> 12 Roda | K18: 45931 | L18: 45720 | M18: 17500 | N18: 28220 | O18: 28240 | P18: 0.55138889 | Q18: 0.625 | R18: samsira | S18: IQBAL | T18: =IFERROR(_xlfn.XLOOKUP(H18,$AM$4:$AM$18,$AP$4:$AP$18,""),0) -> 53 | U18: WIL | V18: =IFERROR(_xlfn.XLOOKUP(H18,$AM$4:$AM$18,$AO$4:$AO$18,""),"") -> Masamba | AM18: CV. NUSANTARA DAYA JAYA | AN18: NDJ | AQ18: RBDPL
B19: 1 | C19: 000028 | D19: =I19&C19&_xlfn.XLOOKUP(H19,$AM$4:$AM$26,$AN$4:$AN$26,"") -> CPO000028KMP | E19: WNE 06 | F19: KMP01092025 | G19: PT. KMP / 1 / 500 | H19: PT. KASMAR MATANO PERSADA | I19: CPO | J19: =IF(MIN(L19,M19)<=5000,"6 Roda",IF(MIN(L19,M19)<=13800,"10 Roda","12 Roda")) -> 12 Roda | K19: 45931 | L19: 45660 | M19: 17430 | N19: 28230 | O19: 28260 | P19: 0.55972222 | Q19: 0.7125 | R19: samsira | S19: IBRAHIM | T19: =IFERROR(_xlfn.XLOOKUP(H19,$AM$4:$AM$18,$AP$4:$AP$18,""),0) -> 53 | U19: WIL | V19: =IFERROR(_xlfn.XLOOKUP(H19,$AM$4:$AM$18,$AO$4:$AO$18,""),"") -> Masamba | AM19: PT. BORNEO MITRA SENTOSA | AN19: BMS | AO19: Makassar | AP19: 360 | AQ19: RBDPS
B20: 1 | C20: 000029 | D20: =I20&C20&_xlfn.XLOOKUP(H20,$AM$4:$AM$26,$AN$4:$AN$26,"") -> CPO000029KMP | E20: WNE 01 | F20: KMP01092025 | G20: PT. KMP / 1 / 500 | H20: PT. KASMAR MATANO PERSADA | I20: CPO | J20: =IF(MIN(L20,M20)<=5000,"6 Roda",IF(MIN(L20,M20)<=13800,"10 Roda","12 Roda")) -> 10 Roda | K20: 45931 | L20: 24910 | M20: 10660 | N20: 14250 | O20: 14300 | P20: 0.63194444 | Q20: 0.69166667 | R20: samsira | S20: RONI RAKAN | T20: =IFERROR(_xlfn.XLOOKUP(H20,$AM$4:$AM$18,$AP$4:$AP$18,""),0) -> 53 | U20: WIL | V20: =IFERROR(_xlfn.XLOOKUP(H20,$AM$4:$AM$18,$AO$4:$AO$18,""),"") -> Masamba
B21: 1 | C21: 000030 | D21: =I21&C21&_xlfn.XLOOKUP(H21,$AM$4:$AM$26,$AN$4:$AN$26,"") -> CPO000030KMP | E21: WNE 03 | F21: KMP01092025 | G21: PT. KMP / 1 / 500 | H21: PT. KASMAR MATANO PERSADA | I21: CPO | J21: =IF(MIN(L21,M21)<=5000,"6 Roda",IF(MIN(L21,M21)<=13800,"10 Roda","12 Roda")) -> 10 Roda | K21: 45931 | L21: 26560 | M21: 12010 | N21: 14550 | O21: 14600 | P21: 0.81527778 | Q21: 0.88611111 | R21: samsira | S21: ERWIN | T21: =IFERROR(_xlfn.XLOOKUP(H21,$AM$4:$AM$18,$AP$4:$AP$18,""),0) -> 53 | U21: WIL | V21: =IFERROR(_xlfn.XLOOKUP(H21,$AM$4:$AM$18,$AO$4:$AO$18,""),"") -> Masamba
B22: 1 | C22: 000031 | D22: =I22&C22&_xlfn.XLOOKUP(H22,$AM$4:$AM$26,$AN$4:$AN$26,"") -> CPO000031KMP | E22: WNE 05 | F22: KMP01092025 | G22: PT. KMP / 1 / 500 | H22: PT. KASMAR MATANO PERSADA | I22: CPO | J22: =IF(MIN(L22,M22)<=5000,"6 Roda",IF(MIN(L22,M22)<=13800,"10 Roda","12 Roda")) -> 12 Roda | K22: 45931 | L22: 45560 | M22: 17480 | N22: 28080 | O22: 28140 | P22: 0.81666667 | Q22: 0.88958333 | R22: samsira | S22: IQBAL | T22: =IFERROR(_xlfn.XLOOKUP(H22,$AM$4:$AM$18,$AP$4:$AP$18,""),0) -> 53 | U22: WIL | V22: =IFERROR(_xlfn.XLOOKUP(H22,$AM$4:$AM$18,$AO$4:$AO$18,""),"") -> Masamba
B23: 1 | C23: 000032 | D23: =I23&C23&_xlfn.XLOOKUP(H23,$AM$4:$AM$26,$AN$4:$AN$26,"") -> CPO000032KMP | E23: WNE 06 | F23: KMP01092025 | G23: PT. KMP / 1 / 500 | H23: PT. KASMAR MATANO PERSADA | I23: CPO | J23: =IF(MIN(L23,M23)<=5000,"6 Roda",IF(MIN(L23,M23)<=13800,"10 Roda","12 Roda")) -> 12 Roda | K23: 45931 | L23: 45700 | M23: 17400 | N23: 28300 | O23: 28360 | P23: 0.87569444 | Q23: 0.97083333 | R23: samsira | S23: IBRAHIM | T23: =IFERROR(_xlfn.XLOOKUP(H23,$AM$4:$AM$18,$AP$4:$AP$18,""),0) -> 53 | U23: WIL | V23: =IFERROR(_xlfn.XLOOKUP(H23,$AM$4:$AM$18,$AO$4:$AO$18,""),"") -> Masamba
B24: 1 | C24: 000033 | D24: =I24&C24&_xlfn.XLOOKUP(H24,$AM$4:$AM$26,$AN$4:$AN$26,"") -> CPO000033KMP | E24: WNE 05 | F24: KMP01092025 | G24: PT. KMP / 1 / 500 | H24: PT. KASMAR MATANO PERSADA | I24: CPO | J24: =IF(MIN(L24,M24)<=5000,"6 Roda",IF(MIN(L24,M24)<=13800,"10 Roda","12 Roda")) -> 12 Roda | K24: 45932 | L24: 45520 | M24: 17410 | N24: 28110 | O24: 28160 | P24: 0.55625 | Q24: 0.63472222 | R24: samsira | S24: IQBAL | T24: =IFERROR(_xlfn.XLOOKUP(H24,$AM$4:$AM$18,$AP$4:$AP$18,""),0) -> 53 | U24: WIL | V24: =IFERROR(_xlfn.XLOOKUP(H24,$AM$4:$AM$18,$AO$4:$AO$18,""),"") -> Masamba
B25: 1 | C25: 000034 | D25: =I25&C25&_xlfn.XLOOKUP(H25,$AM$4:$AM$26,$AN$4:$AN$26,"") -> CPO000034KMP | E25: WNE 06 | F25: KMP01092025 | G25: PT. KMP / 1 / 500 | H25: PT. KASMAR MATANO PERSADA | I25: CPO | J25: =IF(MIN(L25,M25)<=5000,"6 Roda",IF(MIN(L25,M25)<=13800,"10 Roda","12 Roda")) -> 12 Roda | K25: 45932 | L25: 45170 | M25: 17510 | N25: 27660 | O25: 27680 | P25: 0.55902778 | Q25: 0.68125 | R25: samsira | S25: IBRAHIM | T25: =IFERROR(_xlfn.XLOOKUP(H25,$AM$4:$AM$18,$AP$4:$AP$18,""),0) -> 53 | U25: WIL | V25: =IFERROR(_xlfn.XLOOKUP(H25,$AM$4:$AM$18,$AO$4:$AO$18,""),"") -> Masamba
B26: 1 | C26: 000035 | D26: =I26&C26&_xlfn.XLOOKUP(H26,$AM$4:$AM$26,$AN$4:$AN$26,"") -> CPO000035KMP | E26: WNE 02 | F26: KMP01092025 | G26: PT. KMP / 1 / 500 | H26: PT. KASMAR MATANO PERSADA | I26: CPO | J26: =IF(MIN(L26,M26)<=5000,"6 Roda",IF(MIN(L26,M26)<=13800,"10 Roda","12 Roda")) -> 10 Roda | K26: 45932 | L26: 26620 | M26: 11800 | N26: 14820 | O26: 14860 | P26: 0.60347222 | Q26: 0.6875 | R26: samsira | S26: WALDI | T26: =IFERROR(_xlfn.XLOOKUP(H26,$AM$4:$AM$18,$AP$4:$AP$18,""),0) -> 53 | U26: WIL | V26: =IFERROR(_xlfn.XLOOKUP(H26,$AM$4:$AM$18,$AO$4:$AO$18,""),"") -> Masamba
B27: 1 | C27: 000036 | D27: =I27&C27&_xlfn.XLOOKUP(H27,$AM$4:$AM$26,$AN$4:$AN$26,"") -> CPO000036KMP | E27: WNE 03 | F27: KMP01092025 | G27: PT. KMP / 1 / 500 | H27: PT. KASMAR MATANO PERSADA | I27: CPO | J27: =IF(MIN(L27,M27)<=5000,"6 Roda",IF(MIN(L27,M27)<=13800,"10 Roda","12 Roda")) -> 10 Roda | K27: 45932 | L27: 26660 | M27: 12120 | N27: 14540 | O27: 14580 | P27: 0.61041667 | Q27: 0.73402778 | R27: samsira | S27: ERWIN | T27: =IFERROR(_xlfn.XLOOKUP(H27,$AM$4:$AM$18,$AP$4:$AP$18,""),0) -> 53 | U27: WIL | V27: =IFERROR(_xlfn.XLOOKUP(H27,$AM$4:$AM$18,$AO$4:$AO$18,""),"") -> Masamba
B28: 1 | C28: 000037 | D28: =I28&C28&_xlfn.XLOOKUP(H28,$AM$4:$AM$26,$AN$4:$AN$26,"") -> CPO000037KMP | E28: WNE 05 | F28: KMP01092025 | G28: PT. KMP / 1 / 500 | H28: PT. KASMAR MATANO PERSADA | I28: CPO | J28: =IF(MIN(L28,M28)<=5000,"6 Roda",IF(MIN(L28,M28)<=13800,"10 Roda","12 Roda")) -> 12 Roda | K28: 45932 | L28: 45730 | M28: 17580 | N28: 28150 | O28: 28200 | P28: 0.82222222 | Q28: 0.9 | R28: samsira | S28: IQBAL | T28: =IFERROR(_xlfn.XLOOKUP(H28,$AM$4:$AM$18,$AP$4:$AP$18,""),0) -> 53 | U28: WIL | V28: =IFERROR(_xlfn.XLOOKUP(H28,$AM$4:$AM$18,$AO$4:$AO$18,""),"") -> Masamba
B29: 1 | C29: 000038 | D29: =I29&C29&_xlfn.XLOOKUP(H29,$AM$4:$AM$26,$AN$4:$AN$26,"") -> CPO000038KMP | E29: WNE 06 | F29: KMP01092025 | G29: PT. KMP / 1 / 500 | H29: PT. KASMAR MATANO PERSADA | I29: CPO | J29: =IF(MIN(L29,M29)<=5000,"6 Roda",IF(MIN(L29,M29)<=13800,"10 Roda","12 Roda")) -> 12 Roda | K29: 45932 | L29: 45680 | M29: 17460 | N29: 28220 | O29: 28260 | P29: 0.83402778 | Q29: 0.95069444 | R29: samsira | S29: IBRAHIM | T29: =IFERROR(_xlfn.XLOOKUP(H29,$AM$4:$AM$18,$AP$4:$AP$18,""),0) -> 53 | U29: WIL | V29: =IFERROR(_xlfn.XLOOKUP(H29,$AM$4:$AM$18,$AO$4:$AO$18,""),"") -> Masamba
B30: 1 | C30: 000039 | D30: =I30&C30&_xlfn.XLOOKUP(H30,$AM$4:$AM$26,$AN$4:$AN$26,"") -> CPO000039KMP | E30: WNE 02 | F30: KMP01092025 | G30: PT. KMP / 1 / 500 | H30: PT. KASMAR MATANO PERSADA | I30: CPO | J30: =IF(MIN(L30,M30)<=5000,"6 Roda",IF(MIN(L30,M30)<=13800,"10 Roda","12 Roda")) -> 10 Roda | K30: 45932 | L30: 26550 | M30: 11770 | N30: 14780 | O30: 14800 | P30: 0.85277778 | Q30: 0.94027778 | R30: samsira | S30: WALDI | T30: =IFERROR(_xlfn.XLOOKUP(H30,$AM$4:$AM$18,$AP$4:$AP$18,""),0) -> 53 | U30: WIL | V30: =IFERROR(_xlfn.XLOOKUP(H30,$AM$4:$AM$18,$AO$4:$AO$18,""),"") -> Masamba
B31: 1 | C31: 000040 | D31: =I31&C31&_xlfn.XLOOKUP(H31,$AM$4:$AM$26,$AN$4:$AN$26,"") -> CPO000040KMP | E31: WNE 03 | F31: KMP01092025 | G31: PT. KMP / 1 / 500 | H31: PT. KASMAR MATANO PERSADA | I31: CPO | J31: =IF(MIN(L31,M31)<=5000,"6 Roda",IF(MIN(L31,M31)<=13800,"10 Roda","12 Roda")) -> 10 Roda | K31: 45932 | L31: 26640 | M31: 12080 | N31: 14560 | O31: 14580 | P31: 0.89861111 | Q31: 0.99236111 | R31: samsira | S31: ERWIN | T31: =IFERROR(_xlfn.XLOOKUP(H31,$AM$4:$AM$18,$AP$4:$AP$18,""),0) -> 53 | U31: WIL | V31: =IFERROR(_xlfn.XLOOKUP(H31,$AM$4:$AM$18,$AO$4:$AO$18,""),"") -> Masamba
B32: 1 | C32: 000041 | D32: =I32&C32&_xlfn.XLOOKUP(H32,$AM$4:$AM$26,$AN$4:$AN$26,"") -> CPO000041MIS | E32: DP 8821 GL | F32: 215/PJB/MIS-WINS/X/2025 | G32: PT. MIS / 1 / 500 | H32: PT. MADINRA INTI SAWIT | I32: CPO | J32: =IF(MIN(L32,M32)<=5000,"6 Roda",IF(MIN(L32,M32)<=13800,"10 Roda","12 Roda")) -> 6 Roda | K32: 45962 | L32: 13370 | M32: 3790 | N32: 9580 | O32: 9540 | P32: 0.97569444 | Q32: 0.047222222 | R32: samsira | T32: =IFERROR(_xlfn.XLOOKUP(H32,$AM$4:$AM$18,$AP$4:$AP$18,""),0) -> 494 | V32: =IFERROR(_xlfn.XLOOKUP(H32,$AM$4:$AM$18,$AO$4:$AO$18,""),"") -> Pomala
B33: 1 | C33: 000042 | D33: =I33&C33&_xlfn.XLOOKUP(H33,$AM$4:$AM$26,$AN$4:$AN$26,"") -> CPO000042MIS | E33: DP 8951 GB | F33: 215/PJB/MIS-WINS/X/2025 | G33: PT. MIS / 1 / 500 | H33: PT. MADINRA INTI SAWIT | I33: CPO | J33: =IF(MIN(L33,M33)<=5000,"6 Roda",IF(MIN(L33,M33)<=13800,"10 Roda","12 Roda")) -> 6 Roda | K33: 45962 | L33: 13700 | M33: 4070 | N33: 9630 | O33: 9590 | P33: 0.97708333 | Q33: 0.058333333 | R33: samsira | T33: =IFERROR(_xlfn.XLOOKUP(H33,$AM$4:$AM$18,$AP$4:$AP$18,""),0) -> 494 | V33: =IFERROR(_xlfn.XLOOKUP(H33,$AM$4:$AM$18,$AO$4:$AO$18,""),"") -> Pomala
B34: 1 | C34: 000043 | D34: =I34&C34&_xlfn.XLOOKUP(H34,$AM$4:$AM$26,$AN$4:$AN$26,"") -> CPO000043MIS | E34: DP 8994 GH | F34: 215/PJB/MIS-WINS/X/2025 | G34: PT. MIS / 1 / 500 | H34: PT. MADINRA INTI SAWIT | I34: CPO | J34: =IF(MIN(L34,M34)<=5000,"6 Roda",IF(MIN(L34,M34)<=13800,"10 Roda","12 Roda")) -> 6 Roda | K34: 45962 | L34: 13570 | M34: 3910 | N34: 9660 | O34: 9650 | P34: 0.97777778 | Q34: 0.095138889 | R34: samsira | T34: =IFERROR(_xlfn.XLOOKUP(H34,$AM$4:$AM$18,$AP$4:$AP$18,""),0) -> 494 | V34: =IFERROR(_xlfn.XLOOKUP(H34,$AM$4:$AM$18,$AO$4:$AO$18,""),"") -> Pomala
B35: 1 | C35: 000044 | D35: =I35&C35&_xlfn.XLOOKUP(H35,$AM$4:$AM$26,$AN$4:$AN$26,"") -> CPO000044MIS | E35: DP 8928 GM | F35: 215/PJB/MIS-WINS/X/2025 | G35: PT. MIS / 1 / 500 | H35: PT. MADINRA INTI SAWIT | I35: CPO | J35: =IF(MIN(L35,M35)<=5000,"6 Roda",IF(MIN(L35,M35)<=13800,"10 Roda","12 Roda")) -> 6 Roda | K35: 45962 | L35: 13900 | M35: 3810 | N35: 10090 | O35: 10090 | P35: 0.97847222 | Q35: 0.063194444 | R35: samsira | T35: =IFERROR(_xlfn.XLOOKUP(H35,$AM$4:$AM$18,$AP$4:$AP$18,""),0) -> 494 | V35: =IFERROR(_xlfn.XLOOKUP(H35,$AM$4:$AM$18,$AO$4:$AO$18,""),"") -> Pomala
B36: 1 | C36: 000045 | D36: =I36&C36&_xlfn.XLOOKUP(H36,$AM$4:$AM$26,$AN$4:$AN$26,"") -> CPO000045MIS | E36: DN 8492 CU | F36: 215/PJB/MIS-WINS/X/2025 | G36: PT. MIS / 1 / 500 | H36: PT. MADINRA INTI SAWIT | I36: CPO | J36: =IF(MIN(L36,M36)<=5000,"6 Roda",IF(MIN(L36,M36)<=13800,"10 Roda","12 Roda")) -> 6 Roda | K36: 45962 | L36: 13600 | M36: 3990 | N36: 9610 | O36: 9590 | P36: 0.97916667 | Q36: 0.11597222 | R36: samsira | T36: =IFERROR(_xlfn.XLOOKUP(H36,$AM$4:$AM$18,$AP$4:$AP$18,""),0) -> 494 | V36: =IFERROR(_xlfn.XLOOKUP(H36,$AM$4:$AM$18,$AO$4:$AO$18,""),"") -> Pomala
B37: 1 | C37: 000046 | D37: =I37&C37&_xlfn.XLOOKUP(H37,$AM$4:$AM$26,$AN$4:$AN$26,"") -> CPO000046MIS | E37: DP 8036 GK | F37: 215/PJB/MIS-WINS/X/2025 | G37: PT. MIS / 1 / 500 | H37: PT. MADINRA INTI SAWIT | I37: CPO | J37: =IF(MIN(L37,M37)<=5000,"6 Roda",IF(MIN(L37,M37)<=13800,"10 Roda","12 Roda")) -> 6 Roda | K37: 45962 | L37: 13440 | M37: 3980 | N37: 9460 | O37: 9420 | P37: 0.97986111 | Q37: 0.088888889 | R37: samsira | T37: =IFERROR(_xlfn.XLOOKUP(H37,$AM$4:$AM$18,$AP$4:$AP$18,""),0) -> 494 | V37: =IFERROR(_xlfn.XLOOKUP(H37,$AM$4:$AM$18,$AO$4:$AO$18,""),"") -> Pomala
B38: 1 | C38: 000047 | D38: =I38&C38&_xlfn.XLOOKUP(H38,$AM$4:$AM$26,$AN$4:$AN$26,"") -> CPO000047MIS | E38: DP 8662 GH | F38: 215/PJB/MIS-WINS/X/2025 | G38: PT. MIS / 1 / 500 | H38: PT. MADINRA INTI SAWIT | I38: CPO | J38: =IF(MIN(L38,M38)<=5000,"6 Roda",IF(MIN(L38,M38)<=13800,"10 Roda","12 Roda")) -> 6 Roda | K38: 45962 | L38: 14050 | M38: 3960 | N38: 10090 | O38: 10070 | P38: 0.090972222 | Q38: 0.15208333 | R38: samsira | T38: =IFERROR(_xlfn.XLOOKUP(H38,$AM$4:$AM$18,$AP$4:$AP$18,""),0) -> 494 | V38: =IFERROR(_xlfn.XLOOKUP(H38,$AM$4:$AM$18,$AO$4:$AO$18,""),"") -> Pomala
B39: 1 | C39: 000048 | D39: =I39&C39&_xlfn.XLOOKUP(H39,$AM$4:$AM$26,$AN$4:$AN$26,"") -> CPO000048MIS | E39: DP 8004 GJ | F39: 215/PJB/MIS-WINS/X/2025 | G39: PT. MIS / 1 / 500 | H39: PT. MADINRA INTI SAWIT | I39: CPO | J39: =IF(MIN(L39,M39)<=5000,"6 Roda",IF(MIN(L39,M39)<=13800,"10 Roda","12 Roda")) -> 6 Roda | K39: 45962 | L39: 13500 | M39: 4090 | N39: 9410 | O39: 9380 | P39: 0.091666667 | Q39: 0.16666667 | R39: samsira | T39: =IFERROR(_xlfn.XLOOKUP(H39,$AM$4:$AM$18,$AP$4:$AP$18,""),0) -> 494 | V39: =IFERROR(_xlfn.XLOOKUP(H39,$AM$4:$AM$18,$AO$4:$AO$18,""),"") -> Pomala
B40: 1 | C40: 000049 | D40: =I40&C40&_xlfn.XLOOKUP(H40,$AM$4:$AM$26,$AN$4:$AN$26,"") -> CPO000049MIS | E40: DP 8762 GH | F40: 215/PJB/MIS-WINS/X/2025 | G40: PT. MIS / 1 / 500 | H40: PT. MADINRA INTI SAWIT | I40: CPO | J40: =IF(MIN(L40,M40)<=5000,"6 Roda",IF(MIN(L40,M40)<=13800,"10 Roda","12 Roda")) -> 6 Roda | K40: 45962 | L40: 13150 | M40: 3810 | N40: 9340 | O40: 9320 | P40: 0.12083333 | Q40: 0.17777778 | R40: samsira | T40: =IFERROR(_xlfn.XLOOKUP(H40,$AM$4:$AM$18,$AP$4:$AP$18,""),0) -> 494 | V40: =IFERROR(_xlfn.XLOOKUP(H40,$AM$4:$AM$18,$AO$4:$AO$18,""),"") -> Pomala
B41: 1 | C41: 000050 | D41: =I41&C41&_xlfn.XLOOKUP(H41,$AM$4:$AM$26,$AN$4:$AN$26,"") -> CPO000050MIS | E41: DP 9826 GA | F41: 215/PJB/MIS-WINS/X/2025 | G41: PT. MIS / 1 / 500 | H41: PT. MADINRA INTI SAWIT | I41: CPO | J41: =IF(MIN(L41,M41)<=5000,"6 Roda",IF(MIN(L41,M41)<=13800,"10 Roda","12 Roda")) -> 6 Roda | K41: 45962 | L41: 13910 | M41: 4030 | N41: 9880 | O41: 9870 | P41: 0.12152778 | Q41: 0.18958333 | R41: samsira | T41: =IFERROR(_xlfn.XLOOKUP(H41,$AM$4:$AM$18,$AP$4:$AP$18,""),0) -> 494 | V41: =IFERROR(_xlfn.XLOOKUP(H41,$AM$4:$AM$18,$AO$4:$AO$18,""),"") -> Pomala
...

Sheet Efisiensi Armada
O1: [Helper - Daftar Lokasi]
O2: Bone Bone
B3: A. ESTIMASI TEKNIS KENDARAAN | O3: Burau
B4: Parameter | C4: 6 Roda | D4: 10 Roda | E4: 12 Roda | F4: Satuan | O4: Gowa
B5: Kapasitas Muat Maks Aktual (per lokasi pilihan) | C5: =IFERROR(IF($B$11="(Semua Lokasi)",_xlfn.MAXIFS(Database!$N$4:$N$1256,Database!$J$4:$J$1256,"6 Roda"),_xlfn.MAXIFS(Database!$N$4:$N$1256,Database!$J$4:$J$1256,"6 Roda",Database!$V$4:$V$1256,$B$11)),0) -> 28440 | D5: =IFERROR(IF($B$11="(Semua Lokasi)",_xlfn.MAXIFS(Database!$N$4:$N$1256,Database!$J$4:$J$1256,"10 Roda"),_xlfn.MAXIFS(Database!$N$4:$N$1256,Database!$J$4:$J$1256,"10 Roda",Database!$V$4:$V$1256,$B$11)),0) -> 20510 | E5: =IFERROR(IF($B$11="(Semua Lokasi)",_xlfn.MAXIFS(Database!$N$4:$N$1256,Database!$J$4:$J$1256,"12 Roda"),_xlfn.MAXIFS(Database!$N$4:$N$1256,Database!$J$4:$J$1256,"12 Roda",Database!$V$4:$V$1256,$B$11)),0) -> 28960 | F5: Kg (maks aktual) | O5: Makassar
B6: Solar PP — 12 Roda (Liter/trip) | C6: =IFERROR(IF($B$11="(Semua Lokasi)",AVERAGEIF(Database!$AR$4:$AR$18,">"&0)/$N$6+AVERAGEIF(Database!$AR$4:$AR$18,">"&0)/$N$7,_xlfn.XLOOKUP($B$11,Database!$AO$4:$AO$18,Database!$AR$4:$AR$18,0,0)/$N$6+_xlfn.XLOOKUP($B$11,Database!$AO$4:$AO$18,Database!$AR$4:$AR$18,0,0)/$N$7),0) -> 258.88831 | D6: =IFERROR(IF($B$11="(Semua Lokasi)",AVERAGEIF(Database!$AZ$4:$AZ$18,">"&0),IF(_xlfn.XLOOKUP($B$11,Database!$AO$4:$AO$18,Database!$AZ$4:$AZ$18,0,0)>0,_xlfn.XLOOKUP($B$11,Database!$AO$4:$AO$18,Database!$AZ$4:$AZ$18,0,0),IFERROR(AVERAGEIFS(Database!$T$4:$T$1256,Database!$J$4:$J$1256,"10 Roda",Database!$V$4:$V$1256,$B$11)*2/$N$8,0))),0) -> 296.11111 | E6: =IFERROR(IF($B$11="(Semua Lokasi)",AVERAGEIF(Database!$AX$4:$AX$18,">"&0),IF(_xlfn.XLOOKUP($B$11,Database!$AO$4:$AO$18,Database!$AX$4:$AX$18,0,0)>0,_xlfn.XLOOKUP($B$11,Database!$AO$4:$AO$18,Database!$AX$4:$AX$18,0,0),IFERROR(AVERAGEIFS(Database!$T$4:$T$1256,Database!$J$4:$J$1256,"12 Roda",Database!$V$4:$V$1256,$B$11)*2/$N$10,0))),0) -> 333.88889 | F6: Liter (PP aktual / estimasi) | M6: [Helper km/L] | N6: 5 | O6: Masamba
B7: Kecepatan Rata-rata | C7: 50 | D7: 50 | E7: 50 | F7: Km/Jam | M7: 10R bermuatan | N7: 7 | O7: Pomala
B8: Harga Solar (estimasi) | C8: 10600 | D8: 10600 | E8: 10600 | F8: Rp/Liter | M8: 10R kosong | N8: 4 | O8: Siumbatu
M9: 12R bermuatan | N9: 6 | O9: Torobulu
M10: 12R kosong | N10: 3
B11: (Semua Lokasi) | N11: 5
B12: B. RINGKASAN PER JENIS TRUK
B13: KPI | C13: 6 Roda | D13: 10 Roda | E13: 12 Roda | F13: Satuan
B14: Total Trip (dari Database) | C14: =COUNTIFS(Database!$J$4:$J$1256,"6 Roda",Database!$V$4:$V$1256,IF($B$11="(Semua Lokasi)","*",$B$11)) -> 659 | D14: =COUNTIFS(Database!$J$4:$J$1256,"10 Roda",Database!$V$4:$V$1256,IF($B$11="(Semua Lokasi)","*",$B$11)) -> 334 | E14: =COUNTIFS(Database!$J$4:$J$1256,"12 Roda",Database!$V$4:$V$1256,IF($B$11="(Semua Lokasi)","*",$B$11)) -> 249 | F14: Trip
B15: Total Netto Terkirim (Kg) | C15: =SUMIFS(Database!$N$4:$N$1256,Database!$J$4:$J$1256,"6 Roda",Database!$V$4:$V$1256,IF($B$11="(Semua Lokasi)","*",$B$11)) -> 6283400 | D15: =SUMIFS(Database!$N$4:$N$1256,Database!$J$4:$J$1256,"10 Roda",Database!$V$4:$V$1256,IF($B$11="(Semua Lokasi)","*",$B$11)) -> 4843040 | E15: =SUMIFS(Database!$N$4:$N$1256,Database!$J$4:$J$1256,"12 Roda",Database!$V$4:$V$1256,IF($B$11="(Semua Lokasi)","*",$B$11)) -> 6969570 | F15: Kg
B16: Avg Netto / Trip (Kg) | C16: =IFERROR(C15/C14,0) -> 9534.7496 | D16: =IFERROR(D15/D14,0) -> 14500.12 | E16: =IFERROR(E15/E14,0) -> 27990.241 | F16: Kg
B17: Kapasitas Maksimum (Kg) | C17: =C5 -> 28440 | D17: =D5 -> 20510 | E17: =E5 -> 28960 | F17: Kg
B18: Utilisasi Kapasitas (%) | C18: =IFERROR(C16/C17,0) -> 0.33525843 | D18: =IFERROR(D16/D17,0) -> 0.70697805 | E18: =IFERROR(E16/E17,0) -> 0.96651385 | F18: %
B19: Avg Jarak per Trip (Km) | C19: =IFERROR(AVERAGEIFS(Database!$T$4:$T$1256,Database!$J$4:$J$1256,"6 Roda",Database!$V$4:$V$1256,IF($B$11="(Semua Lokasi)","*",$B$11),Database!$T$4:$T$1256,">"&0),0) -> 422.54947 | D19: =IFERROR(AVERAGEIFS(Database!$T$4:$T$1256,Database!$J$4:$J$1256,"10 Roda",Database!$V$4:$V$1256,IF($B$11="(Semua Lokasi)","*",$B$11),Database!$T$4:$T$1256,">"&0),0) -> 94.431138 | E19: =IFERROR(AVERAGEIFS(Database!$T$4:$T$1256,Database!$J$4:$J$1256,"12 Roda",Database!$V$4:$V$1256,IF($B$11="(Semua Lokasi)","*",$B$11),Database!$T$4:$T$1256,">"&0),0) -> 96.646586 | F19: Km
B20: Est. Durasi Perjalanan Pulang-Pergi (Jam) | C20: =IFERROR(IF($B$11="(Semua Lokasi)",AVERAGEIF(Database!$AR$4:$AR$18,">"&0)/C7,_xlfn.XLOOKUP($B$11,Database!$AO$4:$AO$18,Database!$AR$4:$AR$18,0,0)/C7),0) -> 15.101818 | D20: =IFERROR(IF($B$11="(Semua Lokasi)",AVERAGEIF(Database!$AR$4:$AR$18,">"&0)/D7,_xlfn.XLOOKUP($B$11,Database!$AO$4:$AO$18,Database!$AR$4:$AR$18,0,0)/D7),0) -> 15.101818 | E20: =IFERROR(IF($B$11="(Semua Lokasi)",AVERAGEIF(Database!$AR$4:$AR$18,">"&0)/E7,_xlfn.XLOOKUP($B$11,Database!$AO$4:$AO$18,Database!$AR$4:$AR$18,0,0)/E7),0) -> 15.101818
B21: Est. Solar Pergi — Bermuatan (L/Trip) | C21: =IFERROR(C6*(1/$N$6)/((1/$N$6)+(1/$N$7)),0) -> 151.01818 | D21: =IFERROR(D6*(1/$N$8)/((1/$N$8)+(1/$N$9)),0) -> 177.66667 | E21: =IFERROR(E6*(1/$N$10)/((1/$N$10)+(1/$N$11)),0) -> 208.68056 | F21: Liter
B22: Est. Solar Balik — Kosong/Ringan (L/Trip) | C22: =IFERROR(C6-C21,0) -> 107.87013 | D22: =IFERROR(D6-D21,0) -> 118.44444 | E22: =IFERROR(E6-E21,0) -> 125.20833 | F22: Liter
B23: Est. Total Solar PP / Trip (Liter) | C23: =C6 -> 258.88831 | D23: =D6 -> 296.11111 | E23: =E6 -> 333.88889 | F23: Liter
B24: Est. Biaya Solar PP / Trip (Rp) | C24: =C23*C8 -> 2744216.1 | D24: =D23*D8 -> 3138777.8 | E24: =E23*E8 -> 3539222.2 | F24: Rp
C25: =C24*C8 -> 2.9088691e+10 | D25: =D24*D8 -> 3.3271044e+10 | E25: =E24*E8 -> 3.7515756e+10
B27: C. ESTIMASI TOTAL BIAYA SOLAR
B28: Komponen | C28: 6 Roda | D28: 10 Roda | E28: 12 Roda | F28: Total Gabungan
B29: Total Jarak Tempuh (Km) | C29: =SUMIFS(Database!$T$4:$T$1256,Database!$J$4:$J$1256,"6 Roda",Database!$T$4:$T$1256,">"&0) -> 277615 | D29: =SUMIFS(Database!$T$4:$T$1256,Database!$J$4:$J$1256,"10 Roda",Database!$T$4:$T$1256,">"&0) -> 31540 | E29: =SUMIFS(Database!$T$4:$T$1256,Database!$J$4:$J$1256,"12 Roda",Database!$T$4:$T$1256,">"&0) -> 24065 | F29: =SUM(C29:E29) -> 333220
B30: Est. Solar Total — Bermuatan (Liter) | C30: =IFERROR(C29/$N$6,0) -> 55523 | D30: {=IFERROR(SUMPRODUCT((COUNTIFS(Database!$J$4:$J$1256,"10 Roda",Database!$V$4:$V$1256,Database!$AO$4:$AO$18))*(Database!$AZ$4:$AZ$18))*((1/$N$7)/((1/$N$7)+(1/$N$8))),0)} -> 9483.6364 | E30: {=IFERROR(SUMPRODUCT((COUNTIFS(Database!$J$4:$J$1256,"12 Roda",Database!$V$4:$V$1256,Database!$AO$4:$AO$18))*(Database!$AX$4:$AX$18))*((1/$N$9)/((1/$N$9)+(1/$N$10))),0)} -> 9648.3333 | F30: =SUM(C30:E30) -> 74654.97
B31: Est. Solar Total — Kosong/Balik (Liter) | C31: =IFERROR(C29/#REF!,0) -> 0 | D31: {=IFERROR(SUMPRODUCT((COUNTIFS(Database!$J$4:$J$1256,"10 Roda",Database!$V$4:$V$1256,Database!$AO$4:$AO$18))*(Database!$AZ$4:$AZ$18))*(1-((1/$N$7)/((1/$N$7)+(1/$N$8)))),0)} -> 16596.364 | E31: {=IFERROR(SUMPRODUCT((COUNTIFS(Database!$J$4:$J$1256,"12 Roda",Database!$V$4:$V$1256,Database!$AO$4:$AO$18))*(Database!$AX$4:$AX$18))*(1-((1/$N$9)/((1/$N$9)+(1/$N$10)))),0)} -> 19296.667 | F31: =SUM(C31:E31) -> 35893.03
B32: Total Solar Konsumsi (Liter) | C32: =C30+C31 -> 55523 | D32: =D30+D31 -> 26080 | E32: =E30+E31 -> 28945 | F32: =SUM(C32:E32) -> 110548
B33: Est. Biaya Solar (Rp) | C33: =C32*C8 -> 588543800 | D33: =D32*D8 -> 276448000 | E33: =E32*E8 -> 306817000 | F33: =SUM(C33:E33) -> 1171808800
B34: Biaya Solar / Kg Netto (Rp) | C34: =IFERROR(C33/C15,0) -> 93.666454 | D34: =IFERROR(D33/D15,0) -> 57.081503 | E34: =IFERROR(E33/E15,0) -> 44.022372 | F34: =IFERROR(F33/SUM(C15:E15),0) -> 64.755092
B35: Biaya Solar / Trip (Rp) | C35: =IFERROR(C33/C14,0) -> 893086.19 | D35: =IFERROR(D33/D14,0) -> 827688.62 | E35: =IFERROR(E33/E14,0) -> 1232196.8 | F35: =IFERROR(F33/SUM(C14:E14),0) -> 943485.35
B38: D. EFISIENSI PER LOKASI TUJUAN
B40: Lokasi | C40: Jarak (Km) | D40: Jenis Truk | E40: Total Trip | F40: Avg Netto (Kg) | G40: Utilisasi (%) | H40: Solar Pergi – Bermuatan (L) | I40: Solar Balik – Kosong (L) | J40: Total Solar PP (L) | K40: Netto/Liter Solar (Kg/L) | L40: Biaya Solar/Ton (Rp)
B41: Bone Bone | C41: 68 | D41: 6 Roda | E41: =COUNTIFS(Database!$J$4:$J$1256,"6 Roda",Database!$V$4:$V$1256,"Bone Bone") -> 78 | F41: =IFERROR(AVERAGEIFS(Database!$N$4:$N$1256,Database!$J$4:$J$1256,"6 Roda",Database!$V$4:$V$1256,"Bone Bone"),0) -> 9827.6923 | G41: =IFERROR(F41/$C5,0) -> 0.3455588 | H41: =IFERROR(C41/$C$6,0) -> 0.26266153 | I41: =IFERROR(C41/#REF!,0) -> 0 | J41: =H41+I41 -> 0.26266153 | K41: =IFERROR(F41/J41,0) -> 37415.804 | L41: =IFERROR((J41*$C8)/(F41/1000),0) -> 283.30275
B42: Bone Bone | C42: 68 | D42: 10 Roda | E42: =COUNTIFS(Database!$J$4:$J$1256,"10 Roda",Database!$V$4:$V$1256,"Bone Bone") -> 177 | F42: =IFERROR(AVERAGEIFS(Database!$N$4:$N$1256,Database!$J$4:$J$1256,"10 Roda",Database!$V$4:$V$1256,"Bone Bone"),0) -> 14645.763 | G42: =IFERROR(F42/$D5,0) -> 0.71407912 | H42: =IFERROR(C42/$D$6,0) -> 0.22964353 | I42: =IFERROR(C42/#REF!,0) -> 0 | J42: =H42+I42 -> 0.22964353 | K42: =IFERROR(F42/J42,0) -> 63776.075 | L42: =IFERROR((J42*$D8)/(F42/1000),0) -> 166.20653
B43: Bone Bone | C43: 68 | D43: 12 Roda | E43: =COUNTIFS(Database!$J$4:$J$1256,"12 Roda",Database!$V$4:$V$1256,"Bone Bone") -> 95 | F43: =IFERROR(AVERAGEIFS(Database!$N$4:$N$1256,Database!$J$4:$J$1256,"12 Roda",Database!$V$4:$V$1256,"Bone Bone"),0) -> 27878.842 | G43: =IFERROR(F43/$E5,0) -> 0.9626672 | H43: =IFERROR(C43/$E$6,0) -> 0.20366057 | I43: =IFERROR(C43/#REF!,0) -> 0 | J43: =H43+I43 -> 0.20366057 | K43: =IFERROR(F43/J43,0) -> 136888.76 | L43: =IFERROR((J43*$E8)/(F43/1000),0) -> 77.435138
B44: Masamba | C44: 53 | D44: 10 Roda | E44: =COUNTIFS(Database!$J$4:$J$1256,"10 Roda",Database!$V$4:$V$1256,"Masamba") -> 70 | F44: =IFERROR(AVERAGEIFS(Database!$N$4:$N$1256,Database!$J$4:$J$1256,"10 Roda",Database!$V$4:$V$1256,"Masamba"),0) -> 14499.286 | G44: =IFERROR(F44/$D5,0) -> 0.70693738 | H44: =IFERROR(C44/$D$6,0) -> 0.17898687 | I44: =IFERROR(C44/#REF!,0) -> 0 | J44: =H44+I44 -> 0.17898687 | K44: =IFERROR(F44/J44,0) -> 81007.54 | L44: =IFERROR((J44*$D8)/(F44/1000),0) -> 130.85202
...

Sheet Harga OAT
A1: ESTIMASI HARGA OAT & MARGIN PER RELASI
A4: PARAMETER GLOBAL
A5: Harga Solar (Rp/L) | B5: 6 Roda | C5: 10 Roda | D5: 12 Roda | E5: Harga Solar
A6: Kapasitas Truk (Kg) | B6: 10000 | C6: 15000 | D6: 29000 | E6: ='Efisiensi Armada'!C8 -> 10600
A7: km/L — Bermuatan | B7: ='Efisiensi Armada'!N6 -> 5 | C7: ='Efisiensi Armada'!N8 -> 4 | D7: ='Efisiensi Armada'!N10 -> 3
A8: km/L — Kosong | B8: ='Efisiensi Armada'!N7 -> 7 | C8: ='Efisiensi Armada'!N9 -> 6 | D8: ='Efisiensi Armada'!N11 -> 5
A9: Target Margin (%) | B9: 0.15
A11: INPUT BIAYA LAIN-LAIN PER RELASI (Rp/trip — isi manual)
A12: Relasi | B12: Produk | C12: Lokasi | D12: Jarak PP | E12: OAT 6R | F12: OAT 10R | G12: OAT 12R | H12: Makan & Jalan | I12: Tol & Retribusi | J12: Penginapan
