Workbook
Name _________ACC2: '[1]Parameter Gaji'!$O$2:$Q$10
Name ________ACC2: #REF!
Name _______ACC2: {#NAME?}
Name ______ACC2: {#NAME?}
Name ______aud2000: #REF!
Name ______Cap98: #REF!
Name ______Cap99: #REF!
Name ______chf2000: #REF!
Name ______dem2000: #REF!
Name ______edi3: [2]POTRET_AFD!$A$445
Name ______gbp2000: #REF!
Name ______hkd2000: #REF!
Name ______jpy2000: #REF!
Name ______MIS98: #REF!
Name ______MIS99: #REF!
Name ______myr2000: #REF!
Name ______nlg2000: #REF!
Name ______nzd2000: #REF!
Name ______sgd2000: #REF!
Name ______TBM98: #REF!
Name ______TBM99: #REF!
Name ______TM98: #REF!
Name ______TM99: #REF!
Name ______usd2000: #REF!
Name _____ACC2: {#NAME?}
Name _____aud2000: #REF!
Name _____Cap98: #REF!
Name _____Cap99: #REF!
Name _____chf2000: #REF!
Name _____dem2000: #REF!
Name _____DUA1: "#ref!"
Name _____DUA1_1: "#ref!"
Name _____gbp2000: #REF!
Name _____hkd2000: #REF!
Name _____jpy2000: #REF!
Name _____MIS98: #REF!
Name _____MIS99: #REF!
Name _____myr2000: #REF!
Name _____nlg2000: #REF!
Name _____nzd2000: #REF!
Name _____sgd2000: #REF!
Name _____tb3: NA()
Name _____TBM98: #REF!
Name _____TBM99: #REF!
Name _____TM98: #REF!
Name _____TM99: #REF!
Name _____usd2000: #REF!
Name ____ACC2: {#NAME?}
Name ____aud2000: #REF!
Name ____Cap98: #REF!
Name ____Cap99: #REF!
Name ____chf2000: #REF!
Name ____dem2000: #REF!
Name ____DUA1: "#ref!"
Name ____DUA1_1: "#ref!"
Name ____gbp2000: #REF!
Name ____hkd2000: #REF!
Name ____jpy2000: #REF!
Name ____MIS98: #REF!
Name ____MIS99: #REF!

Sheet tes
B3: PENERIMAAN CPO | F3: CPO OLAH | I3: REJECT
B4: 2025 | D4: 7584790 | F4: 2025 | G4: 360.98 | I4: CPO | J4: 190.245 | K4: =J4-65.8 -> 124.445
B5: 2026 | D5: 7924550 | F5: 2026 | G5: 11074 | I5: RBDPO | J5: 207.743 | K5: =J5-171.4 -> 36.343
F6: TOTAL | G6: =SUM(G4:G5)*1000 -> 11434980 | I6: RBDPL | J6: 663.465
B7: SUB TOTAL (JANUARI) | D7: 2095330 | I7: STEARIN | J7: 293.21
B8: SUB TOTAL (FEBRUARI) | D8: 2826320 | I8: TOTAL | J8: =SUM(J4:J7) -> 1354.663
B9: SUB TOTAL (MARET) | D9: 657400
B10: SUB TOTAL (APRIL) | D10: 1337360
B11: SUB TOTAL (MEI) | D11: 1008140 | I11: STOK CPO | J11: 5222511
B12: total 2026 | D12: =SUM(D7:D11) -> 7924550 | J12: =D13-G6 -> 4074360
B13: total | D13: =D4+D12 -> 15509340 | J13: =J12+J8 -> 4075714.7
B16: Penerimaan CPO | D16: 15509340
B17: CPO Olah | D17: 11434980
B18: REJECT ALL | D18: 1354.663
D19: =D16-D17-D18 -> 4073005.3
B20: OIL LOSES | D20: 34
B21: STOK SAAT INI | D21: =J11 -> 5222511
B23: SELISIH | D23: =D21-D19 -> 1149505.7

Sheet CEK
C2: REKAP LAPORAN PRODUKSI
C3: REFINERY
B5: No | C5: Tanggal | D5: CPO IN | E5: STOK CPO TIMBANGAN | F5: STOK CPO | G5: CPO Feed (MT) | H5: CPO Reject (MT) | I5: TOTAL STOK CPO AKHIR | J5: RBDPO (MT) | K5: RBDPO FEED (MT) | L5: RBDPO Reject (MT) | M5: STOK RBDPO AKHIR | N5: RDPL | O5: RDPL REJECT | P5: DESPATCH | Q5: TOTAL RBDPL | R5: STEARIN | S5: STEARIN REJECT | T5: DESPATCH | U5: TOTAL STEARIN | V5: PFAD (MT) | W5: BE (KG) | X5: PA (KG) | Y5: SOLAR (L) | AA5: STEAM (MT) | AB5: POWER (KWH) | AC5: POWER (KWH) | AD5: WATER USAGE
AA6: KG/MT
Y7: HPB | Z7: LPB | AB7: (PROD) | AC7: (UTY)
B8: =IF(C8="","",1) -> 1 | C8: 45975 | D8: =128340/1000 -> 128.34 | F8: =1736650/1000 -> 1736.65 | G8: 23.3 | I8: =D8+F8-G8+H8 -> 1841.69 | AE8: 16.918 | AF8: =H13+H14 -> 16.918
B9: =IF(C9="","",+B8+1) -> 2 | C9: 46009 | D9: =246470/1000 -> 246.47 | E9: =(6189300/1000)+D9 -> 6435.77 | F9: =6435770/1000 -> 6435.77 | I9: =F9-G8 -> 6412.47 | Z9: 5322 | AE9: 10.603 | AF9: =AF8-AE10 -> -10.603
B10: =IF(C10="","",+B9+1) -> 3 | C10: 46010 | D10: ='[200]20.12'!$Q$28/1000 -> 255.9 | E10: =E9+D10 -> 6691.67 | F10: =I9+D10 -> 6668.37 | G10: 21.4 | I10: =F10-G10+H10 -> 6646.97 | W10: 301.6 | X10: 10.6 | Y10: 37.9 | Z10: 3613 | AA10: 29.7 | AB10: 152.48 | AE10: =SUM(AE8:AE9) -> 27.521
B11: =IF(C11="","",+B10+1) -> 4 | C11: 46011 | D11: ='[200]22.12'!$Q$25/1000 -> 203.33 | E11: =E10+D11 -> 6895 | F11: =I10+D11 -> 6850.3 | G11: 16.1 | I11: =F11-G11+H11 -> 6834.2 | W11: 129.9 | X11: 9.6 | Y11: 11.83 | Z11: 4239
B12: =IF(C12="","",+B11+1) -> 5 | C12: 46012 | D12: 0 | E12: =E11+D12 -> 6895 | F12: =I11+D12 -> 6834.2 | I12: =F12-G12+H12 -> 6834.2 | Y12: 144 | Z12: 4327 | AB12: 205.56
B13: =IF(C13="","",+B12+1) -> 6 | C13: 46013 | D13: ='[200]23.12'!$Q$20/1000 -> 170.74 | E13: =E12+D13 -> 7065.74 | F13: =I12+D13 -> 7004.94 | G13: 12.5 | I13: =F13-G13+H13 -> 6992.44 | V13: 0.3 | W13: 106.7 | X13: 8.43 | AA13: 33.65 | AB13: 195.06
B14: =IF(C14="","",+B13+1) -> 7 | C14: 46014 | D14: ='[200]24.12'!$Q$20/1000 -> 162.6 | E14: =E13+D14 -> 7228.34 | F14: =I13+D14 -> 7155.04 | G14: 13 | H14: 16.918 | I14: =F14-G14+H14 -> 7158.958 | V14: 0.2 | W14: 104.4 | X14: 7.7556 | Y14: 326.09 | AA14: 10.8 | AB14: 199.37
B15: =IF(C15="","",+B14+1) -> 8 | C15: 46015 | D15: 0 | E15: =E14+D15 -> 7228.34 | F15: =I14+D15 -> 7158.958 | I15: =F15-G15+H15 -> 7158.958 | V15: 0.1 | Z15: 5327 | AA15: 29 | AB15: 198.38
B16: =IF(C16="","",+B15+1) -> 9 | C16: 46016 | D16: 0 | E16: =E15+D16 -> 7228.34 | F16: =I15+D16 -> 7158.958 | I16: =F16-G16+H16 -> 7158.958 | Z16: 6518 | AA16: 13 | AB16: 188.57
B17: =IF(C17="","",+B16+1) -> 10 | C17: 46017 | D17: 0 | E17: =E16+D17 -> 7228.34 | F17: =I16+D17 -> 7158.958 | H17: 10.603 | I17: =F17-G17+H17 -> 7169.561 | Z17: 2089 | AA17: 14 | AB17: 184.13 | AE17: 7169561
B18: =IF(C18="","",+B17+1) -> 11 | C18: 46018 | D18: ='[200]29.12'!$Q$15/1000 -> 156.45 | E18: =E17+D18 -> 7384.79 | F18: =I17+D18 -> 7326.011 | G18: 10.9 | I18: =F18-G18+H18 -> 7315.111 | W18: 99 | X18: 7.24 | Z18: 1696 | AA18: 6.4 | AB18: 190.5 | AC18: 4352 | AE18: =AE17/1000 -> 7169.561
B19: =IF(C19="","",+B18+1) -> 12 | C19: 46019 | D19: 0 | E19: =E18+D19 -> 7384.79 | F19: =I18+D19 -> 7315.111 | G19: 16.3 | I19: =F19-G19+H19 -> 7298.811 | V19: 0.2 | W19: 237.4 | X19: 9.1 | Y19: 239.6 | Z19: 6447 | AA19: 34.2 | AB19: 208.01 | AC19: 5388 | AE19: 7266
B20: =IF(C20="","",+B19+1) -> 13 | C20: 46020 | D20: ='[200]30.12'!$Q$13/1000 -> 99.87 | E20: =E19+D20 -> 7484.66 | F20: =I19+D20 -> 7398.681 | G20: 16.2 | I20: =F20-G20+H20 -> 7382.481 | V20: 1.1 | W20: 162.4 | X20: 9.77 | Y20: 257.8 | Z20: 5009 | AA20: 31.1 | AB20: 199.93 | AC20: 5800 | AE20: =AE19-AE18 -> 96.439
B21: =IF(C21="","",+B20+1) -> 14 | C21: 46021 | D21: ='[200]31.12'!$Q$27/1000 -> 99.94 | E21: =E20+D21 -> 7584.6 | F21: =I20+D21 -> 7482.421 | G21: 163 | H21: 19.845 | I21: =F21-G21+H21 -> 7339.266 | J21: 127 | M21: =J21-K21+L21 -> 127 | V21: 7.3 | W21: 1399 | X21: 80.3 | Y21: 866 | Z21: 6566 | AA21: 36 | AB21: 278.7 | AC21: 6220
B22: =IF(C22="","",+B21+1) -> 15 | C22: 46022 | D22: 0 | E22: =E21+D22 -> 7584.6 | F22: =I21+D22 -> 7339.266 | G22: 85.2 | I22: =(F22-G22+H22) -> 7254.066 | J22: 80 | M22: =J22-K22+L22 -> 80 | V22: 5.8 | W22: 879.3 | X22: 50.9 | Y22: 1072 | Z22: 7293 | AA22: 38.5 | AB22: 255.07 | AC22: 6704 | AE22: =I22*1000 -> 7254066 | AF22: 7253796
B23: =IF(C23="","",+B22+1) -> 16 | C23: 46023 | E23: =E22+D23 -> 7584.6 | F23: =I22+D23 -> 7254.066 | G23: 190.3 | I23: =F23-G23+H23 -> 7063.766 | J23: 177.6 | M23: =J23-K23+L23 -> 177.6 | Q23: =N23-O23-P23 -> 0 | U23: =R23-S23-T23 -> 0 | V23: =0.9+9.62 -> 10.52 | W23: 2071.7 | X23: 113.36 | Y23: 817.5 | Z23: 5576 | AA23: 37.8 | AB23: 266.4 | AC23: 7800 | AE23: 86.49 | AF23: 95.93
B24: =IF(C24="","",+B23+1) -> 17 | C24: 46024 | E24: =E23+D24 -> 7584.6 | F24: =I23+D24 -> 7063.766 | G24: 163.2 | I24: =F24-G24+H24 -> 6900.566 | J24: 177.6 | M24: =J24-K24+L24 -> 177.6 | Q24: =N24-O24-P24 -> 0 | U24: =R24-S24-T24 -> 0 | V24: =4.9+3.7 -> 8.6 | W24: 1603 | X24: 97.89 | Y24: 1146 | Z24: 4642 | AA24: 39.4 | AB24: 279.6 | AC24: 7060 | AE24: 177.6 | AF24: 74.2
B25: =IF(C25="","",+B24+1) -> 18 | C25: 46025 | E25: =E24+D25 -> 7584.6 | F25: =I24+D25 -> 6900.566 | G25: 208.5 | I25: =F25-G25+H25 -> 6692.066 | J25: 198.8 | M25: =J25-K25+L25 -> 198.8 | Q25: =N25-O25-P25 -> 0 | U25: =R25-S25-T25 -> 0 | V25: =0.8+12.2 -> 13 | W25: 2053.1 | X25: 125.1 | Y25: 847.83 | Z25: 7254 | AA25: 44.4 | AB25: 282.2 | AC25: 6551
B26: =IF(C26="","",+B25+1) -> 19 | C26: 46026 | E26: =E25+D26 -> 7584.6 | F26: =I25+D26 -> 6692.066 | G26: 303.8 | I26: =F26-G26+H26 -> 6388.266 | J26: 283 | M26: =J26-K26+L26 -> 283 | Q26: =N26-O26-P26 -> 0 | U26: =R26-S26-T26 -> 0 | V26: =1.8+16.04 -> 17.84 | W26: 3076.8 | X26: 182.4 | Y26: 1026.8 | Z26: 6196 | AA26: 47.8 | AB26: 282.2 | AC26: 8231 | AE26: 276
B27: =IF(C27="","",+B26+1) -> 20 | C27: 46027 | D27: =99680/1000 -> 99.68 | E27: =E26+D27 -> 7684.28 | F27: =I26+D27 -> 6487.946 | G27: 305.8 | I27: =F27-G27+H27 -> 6182.146 | J27: 283 | M27: =J27-K27+L27 -> 283 | Q27: =N27-O27-P27 -> 0 | U27: =R27-S27-T27 -> 0 | V27: =0.8+17.31 -> 18.11 | W27: 3139.4 | X27: 183.7 | Y27: 1088.98 | Z27: 7106 | AA27: 45 | AB27: 308.87 | AC27: 8243
B28: =IF(C28="","",+B27+1) -> 21 | C28: 46028 | D28: =56470/1000 -> 56.47 | E28: =E27+D28 -> 7740.75 | F28: =I27+D28 -> 6238.616 | G28: 233.8 | I28: =F28-G28+H28+L28 -> 6144.816 | J28: 214.1 | L28: 140 | M28: =J28-K28-L28 -> 74.1 | Q28: =N28-O28-P28 -> 0 | U28: =R28-S28-T28 -> 0 | V28: =0.4+12.61 -> 13.01 | W28: 2380.6 | X28: 138.92 | Y28: 1088.98 | Z28: 6164 | AA28: 42.22 | AB28: 297.9106 | AC28: 7978 | AE28: =E22*1000 -> 7584600
B29: =IF(C29="","",+B28+1) -> 22 | C29: 46029 | E29: =E28+D29 -> 7740.75 | F29: =I28+D29 -> 6144.816 | G29: 223.7 | I29: =F29-G29+H29 -> 5921.116 | J29: 209.6 | M29: =J29-K29+L29 -> 209.6 | Q29: =N29-O29-P29 -> 0 | U29: =R29-S29-T29 -> 0 | V29: =11.92+0.9 -> 12.82 | W29: 2264 | X29: 133.86 | Y29: 808.4 | Z29: 6602 | AA29: 40.12 | AB29: 288.3702 | AC29: 7690
B30: =IF(C30="","",+B29+1) -> 23 | C30: 46030 | E30: =E29+D30 -> 7740.75 | F30: =I29+D30 -> 5921.116 | G30: 188.8 | I30: =F30-G30+H30 -> 5732.316 | J30: 172 | M30: =J30-K30+L30 -> 172 | Q30: =N30-O30-P30 -> 0 | U30: =R30-S30-T30 -> 0 | V30: =0.7+9.8 -> 10.5 | W30: 1905 | X30: 110.8 | Y30: 650.6 | Z30: 5714 | AA30: 42.8 | AB30: 281.3339 | AC30: 7655
B31: =IF(C31="","",+B30+1) -> 24 | C31: 46031 | E31: =E30+D31 -> 7740.75 | F31: =I30+D31 -> 5732.316 | G31: 84.7 | I31: =F31-G31+H31 -> 5647.616 | J31: 78.5 | M31: =J31-K31+L31 -> 78.5 | Q31: =N31-O31-P31 -> 0 | U31: =R31-S31-T31 -> 0 | V31: 4.62 | W31: 872.4 | X31: 50.1 | Y31: 632 | Z31: 5559 | AA31: 39.4 | AB31: 0 | AC31: 7534
B32: =IF(C32="","",+B31+1) -> 25 | C32: 46032 | E32: =E31+D32 -> 7740.75 | F32: =I31+D32 -> 5647.616 | G32: 34.9 | I32: =F32-G32+H32 -> 5612.716 | J32: 44.2 | M32: =J32-K32+L32 -> 44.2 | Q32: =N32-O32-P32 -> 0 | U32: =R32-S32-T32 -> 0 | V32: =3.6+5 -> 8.6 | W32: 371.3 | X32: 20.7 | Y32: 309.4 | Z32: 4825 | AA32: 34.9 | AB32: 237.598 | AC32: 6888
B33: =IF(C33="","",+B32+1) -> 26 | C33: 46033 | E33: =E32+D33 -> 7740.75 | F33: =I32+D33 -> 5612.716 | G33: 0 | I33: =F33-G33+H33 -> 5612.716 | J33: 0 | M33: =J33-K33+L33 -> 0 | Q33: =N33-O33-P33 -> 0 | U33: =R33-S33-T33 -> 0 | V33: 0 | W33: 0 | X33: 0 | Y33: 0 | Z33: 3192 | AA33: 22 | AB33: 192.4624 | AC33: 5019
B34: =IF(C34="","",+B33+1) -> 27 | C34: 46034 | E34: =E33+D34 -> 7740.75 | F34: =I33+D34 -> 5612.716 | G34: 0 | I34: =F34-G34+H34 -> 5612.716 | J34: 0 | M34: =J34-K34+L34 -> 0 | Q34: =N34-O34-P34 -> 0 | U34: =R34-S34-T34 -> 0 | V34: 0 | W34: 0 | X34: 0 | Y34: 0 | Z34: 0 | AA34: 0 | AB34: 7.791 | AC34: 1541
B35: =IF(C35="","",+B34+1) -> 28 | C35: 46035 | D35: =198320/1000 -> 198.32 | E35: =E34+D35 -> 7939.07 | F35: =I34+D35 -> 5811.036 | G35: 0 | I35: =F35-G35+H35 -> 5811.036 | J35: 0 | M35: =J35-K35+L35 -> 0 | Q35: =N35-O35-P35 -> 0 | U35: =R35-S35-T35 -> 0 | V35: 0 | W35: 0 | X35: 0 | Y35: 0 | Z35: 0 | AA35: 0 | AB35: 7.564 | AC35: 1615
B36: =IF(C36="","",+B35+1) -> 29 | C36: 46036 | D36: =199370/1000 -> 199.37 | E36: =E35+D36 -> 8138.44 | F36: =I35+D36 -> 6010.406 | G36: 0 | I36: =F36-G36+H36 -> 6010.406 | J36: 0 | K36: 39.001 | M36: =J36-K36+L36 -> -39.001 | Q36: =N36-O36-P36 -> 0 | U36: =R36-S36-T36 -> 0 | V36: 0 | W36: 0 | X36: 0 | Y36: 0 | Z36: 2197 | AA36: 0 | AB36: 8.594 | AC36: 5155
B37: =IF(C37="","",+B36+1) -> 30 | C37: 46037 | D37: =113690/1000 -> 113.69 | E37: =E36+D37 -> 8252.13 | F37: =I36+D37 -> 6124.096 | G37: 0 | I37: =F37-G37+H37 -> 6124.096 | J37: 0 | K37: =131.175 -> 131.175 | L37: 37.486 | M37: =J37-K37+L37 -> -93.689 | N37: 5.776 | Q37: =N37-O37-P37 -> 5.776 | U37: =R37-S37-T37 -> 0 | Z37: 3737 | AC37: 5573
B38: =IF(C38="","",+B37+1) -> 31 | C38: 46038 | D38: 0 | E38: =E37+D38 -> 8252.13 | F38: =I37+D38 -> 6124.096 | G38: 0 | I38: =F38-G38+H38 -> 6124.096 | J38: 0 | K38: 246.539 | L38: 2.879 | M38: =J38-K38-L38 -> -249.418 | N38: 172.243 | Q38: =N38-O38-P38 -> 172.243 | R38: 39.468 | U38: =R38-S38-T38 -> 39.468 | Z38: 6319 | AA38: 8.5 | AB38: 149.2286 | AC38: 6895
B39: =IF(C39="","",+B38+1) -> 32 | C39: 46039 | D39: =115030/1000 -> 115.03 | E39: =E38+D39 -> 8367.16 | F39: =I38+D39 -> 6239.126 | G39: 18.7 | I39: =F39-G39+H39 -> 6220.426 | J39: 0 | K39: 170.318 | M39: =J39-K39-L39 -> -170.318 | N39: 152.928 | Q39: =N39-O39-P39 -> 152.928 | R39: 27.034 | U39: =R39-S39-T39 -> 27.034 | V39: 0.4 | W39: 174 | X39: 11.3 | Y39: 290 | Z39: 8302 | AA39: 31.2 | AB39: 205.5278 | AC39: 11778
B40: =IF(C40="","",+B39+1) -> 33 | C40: 46040 | D40: 0 | E40: =E39+D40 -> 8367.16 | F40: =I39+D40 -> 6220.426 | G40: 74 | I40: =F40-G40+H40 -> 6146.426 | J40: 68.4 | K40: 196.174 | M40: =J40-K40-L40 -> -127.774 | N40: 183.793 | Q40: =N40-O40-P40 -> 183.793 | R40: 15.554 | U40: =R40-S40-T40 -> 15.554 | V40: 3.6 | W40: 809 | X40: 44.2 | Y40: 587 | Z40: 9153 | AA40: 40.4 | AB40: 238.62 | AC40: 11029
B41: =IF(C41="","",+B40+1) -> 34 | C41: 46041 | D41: =115170/1000 -> 115.17 | E41: =E40+D41 -> 8482.33 | F41: =I40+D41 -> 6261.596 | G41: 98.5 | I41: =F41-G41+H41 -> 6163.096 | J41: 98.222 | K41: =164203/1000 -> 164.203 | M41: =J41-K41-L41 -> -65.981 | N41: =129785/1000 -> 129.785 | Q41: =N41-O41-P41 -> 129.785 | R41: 27.688 | U41: =R41-S41-T41 -> 27.688 | V41: 3.152 | W41: 887 | X41: 59.1 | Y41: 485 | Z41: 7527 | AA41: 39 | AB41: 264.3384 | AC41: 11399
B42: =IF(C42="","",+B41+1) -> 35 | C42: 46042 | D42: =143570/1000 -> 143.57 | E42: =E41+D42 -> 8625.9 | F42: =I41+D42 -> 6306.666 | G42: 135.9 | I42: =F42-G42+H42 -> 6170.766 | J42: 121.431 | K42: 196.64 | M42: =J42-K42-L42 -> -75.209 | N42: 158.031 | Q42: =N42-O42-P42 -> 158.031 | R42: 48.707 | U42: =R42-S42-T42 -> 48.707 | V42: 11.056 | W42: 1000.1 | X42: 79.7 | Y42: 560 | Z42: 6721 | AA42: 41 | AB42: 353.0916 | AC42: 13147
...

Sheet Data Center
C2: REKAP LAPORAN PRODUKSI
C3: REFINERY
B5: No | C5: Tanggal | D5: CPO IN | E5: STOK CPO TIMBANGAN | F5: STOK CPO | G5: CPO Feed (MT) | H5: CPO Reject (MT) | I5: TOTAL STOK CPO AKHIR | J5: RBDPO (MT) | K5: RBDPO FEED (MT) | L5: RBDPO Reject (MT) | M5: STOK RBDPO AKHIR | N5: RDPL | O5: RDPL REJECT | P5: DESPATCH | Q5: TOTAL RBDPL | R5: STEARIN | S5: STEARIN REJECT | T5: DESPATCH | U5: TOTAL STEARIN | V5: PFAD (MT) | W5: BE (KG) | X5: PA (KG) | Y5: SOLAR (L) | AA5: STEAM (MT) | AB5: POWER (KWH) | AC5: POWER (KWH) | AD5: WATER USAGE
AA6: KG/MT
Y7: HPB | Z7: LPB | AB7: (PROD) | AC7: (UTY)
B8: =IF(C8="","",1) -> 1 | C8: 45975 | D8: =128340/1000 -> 128.34 | F8: =1736650/1000 -> 1736.65 | G8: 23.3 | I8: =D8+F8-G8+H8 -> 1841.69 | AE8: 16.918 | AF8: =H13+H14 -> 16.918
B9: =IF(C9="","",+B8+1) -> 2 | C9: 46009 | D9: =246470/1000 -> 246.47 | E9: =(6189300/1000)+D9 -> 6435.77 | F9: =6435770/1000 -> 6435.77 | I9: =F9-G8 -> 6412.47 | Z9: 5322 | AE9: 10.603 | AF9: =AF8-AE10 -> -10.603
B10: =IF(C10="","",+B9+1) -> 3 | C10: 46010 | D10: ='[200]20.12'!$Q$28/1000 -> 255.9 | E10: =E9+D10 -> 6691.67 | F10: =I9+D10 -> 6668.37 | G10: 21.4 | I10: =F10-G10+H10 -> 6646.97 | W10: 301.6 | X10: 10.6 | Y10: 37.9 | Z10: 3613 | AA10: 29.7 | AB10: 152.48 | AE10: =SUM(AE8:AE9) -> 27.521
B11: =IF(C11="","",+B10+1) -> 4 | C11: 46011 | D11: ='[200]22.12'!$Q$25/1000 -> 203.33 | E11: =E10+D11 -> 6895 | F11: =I10+D11 -> 6850.3 | G11: 16.1 | I11: =F11-G11+H11 -> 6834.2 | W11: 129.9 | X11: 9.6 | Y11: 11.83 | Z11: 4239
B12: =IF(C12="","",+B11+1) -> 5 | C12: 46012 | D12: 0 | E12: =E11+D12 -> 6895 | F12: =I11+D12 -> 6834.2 | I12: =F12-G12+H12 -> 6834.2 | Y12: 144 | Z12: 4327 | AB12: 205.56
B13: =IF(C13="","",+B12+1) -> 6 | C13: 46013 | D13: ='[200]23.12'!$Q$20/1000 -> 170.74 | E13: =E12+D13 -> 7065.74 | F13: =I12+D13 -> 7004.94 | G13: 12.5 | I13: =F13-G13+H13 -> 6992.44 | V13: 0.3 | W13: 106.7 | X13: 8.43 | AA13: 33.65 | AB13: 195.06
B14: =IF(C14="","",+B13+1) -> 7 | C14: 46014 | D14: ='[200]24.12'!$Q$20/1000 -> 162.6 | E14: =E13+D14 -> 7228.34 | F14: =I13+D14 -> 7155.04 | G14: 13 | H14: 16.918 | I14: =F14-G14+H14 -> 7158.958 | V14: 0.2 | W14: 104.4 | X14: 7.7556 | Y14: 326.09 | AA14: 10.8 | AB14: 199.37
B15: =IF(C15="","",+B14+1) -> 8 | C15: 46015 | D15: 0 | E15: =E14+D15 -> 7228.34 | F15: =I14+D15 -> 7158.958 | I15: =F15-G15+H15 -> 7158.958 | V15: 0.1 | Z15: 5327 | AA15: 29 | AB15: 198.38
B16: =IF(C16="","",+B15+1) -> 9 | C16: 46016 | D16: 0 | E16: =E15+D16 -> 7228.34 | F16: =I15+D16 -> 7158.958 | I16: =F16-G16+H16 -> 7158.958 | Z16: 6518 | AA16: 13 | AB16: 188.57
B17: =IF(C17="","",+B16+1) -> 10 | C17: 46017 | D17: 0 | E17: =E16+D17 -> 7228.34 | F17: =I16+D17 -> 7158.958 | H17: 10.603 | I17: =F17-G17+H17 -> 7169.561 | Z17: 2089 | AA17: 14 | AB17: 184.13 | AE17: 7169561
B18: =IF(C18="","",+B17+1) -> 11 | C18: 46018 | D18: ='[200]29.12'!$Q$15/1000 -> 156.45 | E18: =E17+D18 -> 7384.79 | F18: =I17+D18 -> 7326.011 | G18: 10.9 | I18: =F18-G18+H18 -> 7315.111 | W18: 99 | X18: 7.24 | Z18: 1696 | AA18: 6.4 | AB18: 190.5 | AC18: 4352 | AE18: =AE17/1000 -> 7169.561
B19: =IF(C19="","",+B18+1) -> 12 | C19: 46019 | D19: 0 | E19: =E18+D19 -> 7384.79 | F19: =I18+D19 -> 7315.111 | G19: 16.3 | I19: =F19-G19+H19 -> 7298.811 | V19: 0.2 | W19: 237.4 | X19: 9.1 | Y19: 239.6 | Z19: 6447 | AA19: 34.2 | AB19: 208.01 | AC19: 5388 | AE19: 7266
B20: =IF(C20="","",+B19+1) -> 13 | C20: 46020 | D20: ='[200]30.12'!$Q$13/1000 -> 99.87 | E20: =E19+D20 -> 7484.66 | F20: =I19+D20 -> 7398.681 | G20: 16.2 | I20: =F20-G20+H20 -> 7382.481 | V20: 1.1 | W20: 162.4 | X20: 9.77 | Y20: 257.8 | Z20: 5009 | AA20: 31.1 | AB20: 199.93 | AC20: 5800 | AE20: =AE19-AE18 -> 96.439
B21: =IF(C21="","",+B20+1) -> 14 | C21: 46021 | D21: ='[200]31.12'!$Q$27/1000 -> 99.94 | E21: =E20+D21 -> 7584.6 | F21: =I20+D21 -> 7482.421 | G21: 163 | H21: 19.845 | I21: =F21-G21+H21 -> 7339.266 | J21: 127 | M21: =J21-K21+L21 -> 127 | V21: 7.3 | W21: 1399 | X21: 80.3 | Y21: 866 | Z21: 6566 | AA21: 36 | AB21: 278.7 | AC21: 6220
B22: =IF(C22="","",+B21+1) -> 15 | C22: 46022 | D22: 0 | E22: =E21+D22 -> 7584.6 | F22: =I21+D22 -> 7339.266 | G22: 85.2 | I22: =(F22-G22+H22) -> 7254.066 | J22: 80 | M22: =J22-K22+L22 -> 80 | V22: 5.8 | W22: 879.3 | X22: 50.9 | Y22: 1072 | Z22: 7293 | AA22: 38.5 | AB22: 255.07 | AC22: 6704 | AE22: =I22*1000 -> 7254066 | AF22: 7253796
B23: =IF(C23="","",+B22+1) -> 16 | C23: 46023 | E23: =E22+D23 -> 7584.6 | F23: =I22+D23 -> 7254.066 | G23: 190.3 | I23: =F23-G23+H23 -> 7063.766 | J23: 177.6 | M23: =J23-K23+L23 -> 177.6 | Q23: =N23-O23-P23 -> 0 | U23: =R23-S23-T23 -> 0 | V23: =0.9+9.62 -> 10.52 | W23: 2071.7 | X23: 113.36 | Y23: 817.5 | Z23: 5576 | AA23: 37.8 | AB23: 266.4 | AC23: 7800 | AE23: 86.49 | AF23: 95.93
B24: =IF(C24="","",+B23+1) -> 17 | C24: 46024 | E24: =E23+D24 -> 7584.6 | F24: =I23+D24 -> 7063.766 | G24: 163.2 | I24: =F24-G24+H24 -> 6900.566 | J24: 177.6 | M24: =J24-K24+L24 -> 177.6 | Q24: =N24-O24-P24 -> 0 | U24: =R24-S24-T24 -> 0 | V24: =4.9+3.7 -> 8.6 | W24: 1603 | X24: 97.89 | Y24: 1146 | Z24: 4642 | AA24: 39.4 | AB24: 279.6 | AC24: 7060 | AE24: 177.6 | AF24: 74.2
B25: =IF(C25="","",+B24+1) -> 18 | C25: 46025 | E25: =E24+D25 -> 7584.6 | F25: =I24+D25 -> 6900.566 | G25: 208.5 | I25: =F25-G25+H25 -> 6692.066 | J25: 198.8 | M25: =J25-K25+L25 -> 198.8 | Q25: =N25-O25-P25 -> 0 | U25: =R25-S25-T25 -> 0 | V25: =0.8+12.2 -> 13 | W25: 2053.1 | X25: 125.1 | Y25: 847.83 | Z25: 7254 | AA25: 44.4 | AB25: 282.2 | AC25: 6551
B26: =IF(C26="","",+B25+1) -> 19 | C26: 46026 | E26: =E25+D26 -> 7584.6 | F26: =I25+D26 -> 6692.066 | G26: 303.8 | I26: =F26-G26+H26 -> 6388.266 | J26: 283 | M26: =J26-K26+L26 -> 283 | Q26: =N26-O26-P26 -> 0 | U26: =R26-S26-T26 -> 0 | V26: =1.8+16.04 -> 17.84 | W26: 3076.8 | X26: 182.4 | Y26: 1026.8 | Z26: 6196 | AA26: 47.8 | AB26: 282.2 | AC26: 8231 | AE26: 276
B27: =IF(C27="","",+B26+1) -> 20 | C27: 46027 | D27: =99680/1000 -> 99.68 | E27: =E26+D27 -> 7684.28 | F27: =I26+D27 -> 6487.946 | G27: 305.8 | I27: =F27-G27+H27 -> 6182.146 | J27: 283 | M27: =J27-K27+L27 -> 283 | Q27: =N27-O27-P27 -> 0 | U27: =R27-S27-T27 -> 0 | V27: =0.8+17.31 -> 18.11 | W27: 3139.4 | X27: 183.7 | Y27: 1088.98 | Z27: 7106 | AA27: 45 | AB27: 308.87 | AC27: 8243
B28: =IF(C28="","",+B27+1) -> 21 | C28: 46028 | D28: =56470/1000 -> 56.47 | E28: =E27+D28 -> 7740.75 | F28: =I27+D28 -> 6238.616 | G28: 233.8 | H28: =L28 -> 140 | I28: =F28-G28+H28 -> 6144.816 | J28: 214.1 | L28: 140 | M28: =J28-K28-L28 -> 74.1 | Q28: =N28-O28-P28 -> 0 | U28: =R28-S28-T28 -> 0 | V28: =0.4+12.61 -> 13.01 | W28: 2380.6 | X28: 138.92 | Y28: 1088.98 | Z28: 6164 | AA28: 42.22 | AB28: 297.9106 | AC28: 7978 | AE28: =E22*1000 -> 7584600
B29: =IF(C29="","",+B28+1) -> 22 | C29: 46029 | E29: =E28+D29 -> 7740.75 | F29: =I28+D29 -> 6144.816 | G29: 223.7 | I29: =F29-G29+H29 -> 5921.116 | J29: 209.6 | M29: =J29-K29+L29 -> 209.6 | Q29: =N29-O29-P29 -> 0 | U29: =R29-S29-T29 -> 0 | V29: =11.92+0.9 -> 12.82 | W29: 2264 | X29: 133.86 | Y29: 808.4 | Z29: 6602 | AA29: 40.12 | AB29: 288.3702 | AC29: 7690
B30: =IF(C30="","",+B29+1) -> 23 | C30: 46030 | E30: =E29+D30 -> 7740.75 | F30: =I29+D30 -> 5921.116 | G30: 188.8 | I30: =F30-G30+H30 -> 5732.316 | J30: 172 | M30: =J30-K30+L30 -> 172 | Q30: =N30-O30-P30 -> 0 | U30: =R30-S30-T30 -> 0 | V30: =0.7+9.8 -> 10.5 | W30: 1905 | X30: 110.8 | Y30: 650.6 | Z30: 5714 | AA30: 42.8 | AB30: 281.3339 | AC30: 7655
B31: =IF(C31="","",+B30+1) -> 24 | C31: 46031 | E31: =E30+D31 -> 7740.75 | F31: =I30+D31 -> 5732.316 | G31: 84.7 | I31: =F31-G31+H31 -> 5647.616 | J31: 78.5 | M31: =J31-K31+L31 -> 78.5 | Q31: =N31-O31-P31 -> 0 | U31: =R31-S31-T31 -> 0 | V31: 4.62 | W31: 872.4 | X31: 50.1 | Y31: 632 | Z31: 5559 | AA31: 39.4 | AB31: 0 | AC31: 7534
B32: =IF(C32="","",+B31+1) -> 25 | C32: 46032 | E32: =E31+D32 -> 7740.75 | F32: =I31+D32 -> 5647.616 | G32: 34.9 | I32: =F32-G32+H32 -> 5612.716 | J32: 44.2 | M32: =J32-K32+L32 -> 44.2 | Q32: =N32-O32-P32 -> 0 | U32: =R32-S32-T32 -> 0 | V32: =3.6+5 -> 8.6 | W32: 371.3 | X32: 20.7 | Y32: 309.4 | Z32: 4825 | AA32: 34.9 | AB32: 237.598 | AC32: 6888
B33: =IF(C33="","",+B32+1) -> 26 | C33: 46033 | E33: =E32+D33 -> 7740.75 | F33: =I32+D33 -> 5612.716 | G33: 0 | I33: =F33-G33+H33 -> 5612.716 | J33: 0 | M33: =J33-K33+L33 -> 0 | Q33: =N33-O33-P33 -> 0 | U33: =R33-S33-T33 -> 0 | V33: 0 | W33: 0 | X33: 0 | Y33: 0 | Z33: 3192 | AA33: 22 | AB33: 192.4624 | AC33: 5019
B34: =IF(C34="","",+B33+1) -> 27 | C34: 46034 | E34: =E33+D34 -> 7740.75 | F34: =I33+D34 -> 5612.716 | G34: 0 | I34: =F34-G34+H34 -> 5612.716 | J34: 0 | M34: =J34-K34+L34 -> 0 | Q34: =N34-O34-P34 -> 0 | U34: =R34-S34-T34 -> 0 | V34: 0 | W34: 0 | X34: 0 | Y34: 0 | Z34: 0 | AA34: 0 | AB34: 7.791 | AC34: 1541
B35: =IF(C35="","",+B34+1) -> 28 | C35: 46035 | D35: =198320/1000 -> 198.32 | E35: =E34+D35 -> 7939.07 | F35: =I34+D35 -> 5811.036 | G35: 0 | I35: =F35-G35+H35 -> 5811.036 | J35: 0 | M35: =J35-K35+L35 -> 0 | Q35: =N35-O35-P35 -> 0 | U35: =R35-S35-T35 -> 0 | V35: 0 | W35: 0 | X35: 0 | Y35: 0 | Z35: 0 | AA35: 0 | AB35: 7.564 | AC35: 1615
B36: =IF(C36="","",+B35+1) -> 29 | C36: 46036 | D36: =199370/1000 -> 199.37 | E36: =E35+D36 -> 8138.44 | F36: =I35+D36 -> 6010.406 | G36: 0 | I36: =F36-G36+H36 -> 6010.406 | J36: 0 | K36: 39.001 | M36: =J36-K36+L36 -> -39.001 | Q36: =N36-O36-P36 -> 0 | U36: =R36-S36-T36 -> 0 | V36: 0 | W36: 0 | X36: 0 | Y36: 0 | Z36: 2197 | AA36: 0 | AB36: 8.594 | AC36: 5155
B37: =IF(C37="","",+B36+1) -> 30 | C37: 46037 | D37: =113690/1000 -> 113.69 | E37: =E36+D37 -> 8252.13 | F37: =I36+D37 -> 6124.096 | G37: 0 | I37: =F37-G37+H37 -> 6124.096 | J37: 0 | K37: =131.175 -> 131.175 | L37: 37.486 | M37: =J37-K37+L37 -> -93.689 | N37: 5.776 | Q37: =N37-O37-P37 -> 5.776 | U37: =R37-S37-T37 -> 0 | Z37: 3737 | AC37: 5573
B38: =IF(C38="","",+B37+1) -> 31 | C38: 46038 | D38: 0 | E38: =E37+D38 -> 8252.13 | F38: =I37+D38 -> 6124.096 | G38: 0 | H38: =L38 -> 2.879 | I38: =F38-G38+H38 -> 6126.975 | J38: 0 | K38: 246.539 | L38: 2.879 | M38: =J38-K38-L38 -> -249.418 | N38: 172.243 | Q38: =N38-O38-P38 -> 172.243 | R38: 39.468 | U38: =R38-S38-T38 -> 39.468 | Z38: 6319 | AA38: 8.5 | AB38: 149.2286 | AC38: 6895
B39: =IF(C39="","",+B38+1) -> 32 | C39: 46039 | D39: =115030/1000 -> 115.03 | E39: =E38+D39 -> 8367.16 | F39: =I38+D39 -> 6242.005 | G39: 18.7 | I39: =F39-G39+H39 -> 6223.305 | J39: 0 | K39: 170.318 | M39: =J39-K39-L39 -> -170.318 | N39: 152.928 | Q39: =N39-O39-P39 -> 152.928 | R39: 27.034 | U39: =R39-S39-T39 -> 27.034 | V39: 0.4 | W39: 174 | X39: 11.3 | Y39: 290 | Z39: 8302 | AA39: 31.2 | AB39: 205.5278 | AC39: 11778
B40: =IF(C40="","",+B39+1) -> 33 | C40: 46040 | D40: 0 | E40: =E39+D40 -> 8367.16 | F40: =I39+D40 -> 6223.305 | G40: 74 | I40: =F40-G40+H40 -> 6149.305 | J40: 68.4 | K40: 196.174 | M40: =J40-K40-L40 -> -127.774 | N40: 183.793 | Q40: =N40-O40-P40 -> 183.793 | R40: 15.554 | U40: =R40-S40-T40 -> 15.554 | V40: 3.6 | W40: 809 | X40: 44.2 | Y40: 587 | Z40: 9153 | AA40: 40.4 | AB40: 238.62 | AC40: 11029
B41: =IF(C41="","",+B40+1) -> 34 | C41: 46041 | D41: =115170/1000 -> 115.17 | E41: =E40+D41 -> 8482.33 | F41: =I40+D41 -> 6264.475 | G41: 98.5 | I41: =F41-G41+H41 -> 6165.975 | J41: 98.222 | K41: =164203/1000 -> 164.203 | M41: =J41-K41-L41 -> -65.981 | N41: =129785/1000 -> 129.785 | Q41: =N41-O41-P41 -> 129.785 | R41: 27.688 | U41: =R41-S41-T41 -> 27.688 | V41: 3.152 | W41: 887 | X41: 59.1 | Y41: 485 | Z41: 7527 | AA41: 39 | AB41: 264.3384 | AC41: 11399
B42: =IF(C42="","",+B41+1) -> 35 | C42: 46042 | D42: =143570/1000 -> 143.57 | E42: =E41+D42 -> 8625.9 | F42: =I41+D42 -> 6309.545 | G42: 135.9 | I42: =F42-G42+H42 -> 6173.645 | J42: 121.431 | K42: 196.64 | M42: =J42-K42-L42 -> -75.209 | N42: 158.031 | Q42: =N42-O42-P42 -> 158.031 | R42: 48.707 | U42: =R42-S42-T42 -> 48.707 | V42: 11.056 | W42: 1000.1 | X42: 79.7 | Y42: 560 | Z42: 6721 | AA42: 41 | AB42: 353.0916 | AC42: 13147
...

Sheet Rekap Perbulan
C2: REKAP LAPORAN PRODUKSI
C3: REFINERY
B5: No | C5: Tanggal | D5: CPO IN | E5: STOK CPO TIMBANGAN | F5: STOK CPO | G5: CPO Feed (MT) | H5: CPO Reject (MT) | I5: TOTAL STOK CPO AKHIR | J5: RBDPO (MT) | K5: RBDPO FEED (MT) | L5: RBDPO Reject (MT) | M5: STOK RBDPO AKHIR | N5: RDPL | O5: RDPL REJECT | P5: DESPATCH | Q5: TOTAL RBDPL | R5: STEARIN | S5: STEARIN REJECT | T5: DESPATCH | U5: TOTAL STEARIN | V5: PFAD (MT) | W5: BE (KG) | X5: PA (KG) | Y5: SOLAR (L) | AA5: STEAM (MT) | AB5: POWER (KWH) | AC5: POWER (KWH) | AD5: WATER USAGE
AA6: KG/MT
Y7: HPB | Z7: LPB | AB7: (PROD) | AC7: (UTY)
B8: SUB TOTAL (DESEMBER) | D8: ='Data Center'!D184*1000 -> 1523640 | G8: ='Data Center'!G184*1000 -> 377900 | H8: ='Data Center'!H184*1000 -> 47366 | I8: ='Data Center'!I184*1000 -> 0 | J8: ='Data Center'!J184*1000 -> 207000 | K8: ='Data Center'!K184*1000 -> 0 | L8: ='Data Center'!L184*1000 -> 0 | M8: ='Data Center'!M184*1000 -> 207000 | N8: ='Data Center'!N184*1000 -> 0 | ... V8: ='Data Center'!V184*1000 -> 15000 | X8: =SUM(#REF!) -> #REF! | Y8: =SUM(#REF!) -> #REF! | Z8: =SUM(#REF!) -> #REF! | AA8: =SUM(#REF!) -> #REF! | AB8: =SUM(#REF!) -> #REF! | AC8: =SUM(#REF!) -> #REF! | AD8: =SUM(#REF!) -> #REF!
B9: SUB TOTAL (JANUARI) | D9: ='Data Center'!D185*1000 -> 2095330 | F9: 5757.675 | G9: ='Data Center'!G185*1000 -> 3740600 | H9: ='Data Center'!H185*1000 -> 142879 | I9: ='Data Center'!I185*1000 -> 5751675 | J9: ='Data Center'!J185*1000 -> 3373811 | K9: ='Data Center'!K185*1000 -> 2598105 | L9: ='Data Center'!L185*1000 -> 180365 | M9: ='Data Center'!M185*1000 -> 813192 | N9: ='Data Center'!N185*1000 -> 1952337 | ... V9: ='Data Center'!V185*1000 -> 231383 | W9: =SUM(#REF!) -> #REF! | X9: =SUM(#REF!) -> #REF! | Y9: =SUM(#REF!) -> #REF! | Z9: =SUM(#REF!) -> #REF! | AA9: =SUM(#REF!) -> #REF! | AB9: =SUM(#REF!) -> #REF! | AC9: =SUM(#REF!) -> #REF! | AD9: =SUM(#REF!) -> #REF!
B10: SUB TOTAL (FEBRUARI) | D10: ='Data Center'!D186*1000 -> 2826320 | F10: 7126.617 | G10: ='Data Center'!G186*1000 -> 1485000 | H10: ='Data Center'!H186*1000 -> 0 | I10: ='Data Center'!I186*1000 -> 7126617 | J10: ='Data Center'!J186*1000 -> 1404348 | K10: ='Data Center'!K186*1000 -> 298158 | L10: ='Data Center'!L186*1000 -> 18411 | M10: ='Data Center'!M186*1000 -> 1106190 | N10: ='Data Center'!N186*1000 -> 196033 | ... V10: ='Data Center'!V186*1000 -> 81681 | W10: =SUM(#REF!) -> #REF! | X10: =SUM(#REF!) -> #REF! | Y10: =SUM(#REF!) -> #REF! | Z10: =SUM(#REF!) -> #REF! | AA10: =SUM(#REF!) -> #REF! | AB10: =SUM(#REF!) -> #REF! | AC10: =SUM(#REF!) -> #REF! | AD10: =SUM(#REF!) -> #REF!
B11: SUB TOTAL (MARET) | D11: ='Data Center'!D187*1000 -> 657400 | F11: 7546.099 | G11: ='Data Center'!G187*1000 -> 583500 | H11: ='Data Center'!H187*1000 -> 0 | I11: ='Data Center'!I187*1000 -> 7261399 | J11: ='Data Center'!J187*1000 -> 511635 | K11: ='Data Center'!K187*1000 -> 721953 | L11: ='Data Center'!L187*1000 -> 0 | M11: ='Data Center'!M187*1000 -> -210318 | N11: ='Data Center'!N187*1000 -> 455021 | ... V11: ='Data Center'!V187*1000 -> 50061 | W11: =SUM(#REF!) -> #REF! | X11: =SUM(#REF!) -> #REF! | Y11: =SUM(#REF!) -> #REF! | Z11: =SUM(#REF!) -> #REF! | AA11: =SUM(#REF!) -> #REF! | AB11: =SUM(#REF!) -> #REF! | AC11: =SUM(#REF!) -> #REF! | AD11: =SUM(#REF!) -> #REF!
B12: SUB TOTAL (APRIL) | D12: ='Data Center'!D188*1000 -> 1337360 | F12: 7176.379 | G12: ='Data Center'!G188*1000 -> 1641800 | H12: ='Data Center'!H188*1000 -> 0 | I12: ='Data Center'!I188*1000 -> 7511380 | J12: ='Data Center'!J188*1000 -> 1558014 | K12: ='Data Center'!K188*1000 -> 2892045 | L12: ='Data Center'!L188*1000 -> 8967 | M12: ='Data Center'!M188*1000 -> -1325064 | N12: ='Data Center'!N188*1000 -> 2136047 | ... V12: ='Data Center'!V188*1000 -> 98737 | W12: =SUM(#REF!) -> #REF! | X12: =SUM(#REF!) -> #REF! | Y12: =SUM(#REF!) -> #REF! | Z12: =SUM(#REF!) -> #REF! | AA12: =SUM(#REF!) -> #REF! | AB12: =SUM(#REF!) -> #REF! | AC12: =SUM(#REF!) -> #REF! | AD12: =SUM(#REF!) -> #REF!
B13: SUB TOTAL (MEI) | D13: ='Data Center'!D189*1000 -> 1008140 | G13: ='Data Center'!G189*1000 -> 3623100 | H13: ='Data Center'!H189*1000 -> 0 | I13: ='Data Center'!I189*1000 -> 5222481 | J13: ='Data Center'!J189*1000 -> 3361910 | K13: ='Data Center'!K189*1000 -> 3909664 | L13: ='Data Center'!L189*1000 -> 0 | M13: ='Data Center'!M189*1000 -> -547754 | N13: ='Data Center'!N189*1000 -> 2858591 | ... V13: ='Data Center'!V189*1000 -> 217126
B14: GRAND TOTAL | D14: =D8+D9+D10+D11+D12+D13 -> 9448190 | E14: =E8+E9+E10+E11+E12 -> 0 | F14: 7176.379 | G14: =G8+G9+G10+G11+G12+G13 -> 11451900 | H14: =H8+H9+H10+H11+H12+H13 -> 190245 | I14: =I8+I9+I10+I11+I12+I13 -> 32873552 | J14: =J8+J9+J10+J11+J12+J13 -> 10416718 | K14: =K8+K9+K10+K11+K12+K13 -> 10419925 | L14: =L8+L9+L10+L11+L12+L13 -> 207743 | M14: =M8+M9+M10+M11+M12+M13 -> 43246 | N14: =N8+N9+N10+N11+N12+N13 -> 7598029 | ... V14: =V8+V9+V10+V11+V12+V13 -> 693988 | W14: =W8+W9+W10+W11+W12 -> #REF! | X14: =X8+X9+X10+X11+X12 -> #REF! | Y14: =Y8+Y9+Y10+Y11+Y12 -> #REF! | Z14: =Z8+Z9+Z10+Z11+Z12 -> #REF! | AA14: =AA8+AA9+AA10+AA11+AA12 -> #REF! | AB14: =AB8+AB9+AB10+AB11+AB12 -> #REF! | AC14: =AC8+AC9+AC10+AC11+AC12 -> #REF! | AD14: =AD8+AD9+AD10+AD11+AD12 -> #REF!

Sheet Refinery
B5: BULAN | C5: CPO | E5: VARIANCE | G5: RBDPO | I5: VARIANCE | K5: PFAD | M5: VARIANCE | O5: RBDPL | Q5: VARIANCE | S5: RBDPS | U5: VARIANCE
C6: SOUNDING | D6: DC | E6: (KG) | F6: (%) | G6: SOUNDING | H6: DC | I6: (KG) | J6: (%) | K6: SOUNDING | L6: DC | M6: (KG) | N6: (%) | O6: SOUNDING | P6: DC | Q6: (KG) | R6: (%) | S6: SOUNDING | T6: DC | U6: (KG) | V6: (%)
B7: 45992 | C7: 7206883 | D7: 7253796 | E7: =IFERROR(C7-D7,0) -> -46913 | F7: =IFERROR(E7/D7,0) -> -0.0064673724 | G7: 207000 | H7: 207000 | I7: =IFERROR(G7-H7,0) -> 0 | J7: =IFERROR(I7/H7,0) -> 0 | M7: =IFERROR(K7-L7,0) -> 0 | N7: =IFERROR(M7/L7,0) -> 0 | Q7: =IFERROR(O7-P7,0) -> 0 | R7: =IFERROR(Q7/P7,0) -> 0 | U7: =IFERROR(S7-T7,0) -> 0 | V7: =IFERROR(U7/T7,0) -> 0
B8: 46023 | C8: 5746782 | D8: 5751675 | E8: =IFERROR(C8-D8,0) -> -4893 | F8: =IFERROR(E8/D8,0) -> -0.00085070871 | G8: 1026631 | H8: 1020193 | I8: =IFERROR(G8-H8,0) -> 6438 | J8: =IFERROR(I8/H8,0) -> 0.0063105706 | K8: 234544 | L8: 246383 | M8: =IFERROR(K8-L8,0) -> -11839 | N8: =IFERROR(M8/L8,0) -> -0.048051205 | O8: 1942232 | P8: 1952465 | Q8: =IFERROR(O8-P8,0) -> -10233 | R8: =IFERROR(Q8/P8,0) -> -0.0052410671 | S8: 529522 | T8: 529521 | U8: =IFERROR(S8-T8,0) -> 1 | V8: =IFERROR(U8/T8,0) -> 1.8884992e-06
B9: 46054 | C9: 7085558 | D9: 7126547 | E9: =IFERROR(C9-D9,0) -> -40989 | F9: =IFERROR(E9/D9,0) -> -0.0057515933 | G9: 2132821 | H9: 2126383 | I9: =IFERROR(G9-H9,0) -> 6438 | J9: =IFERROR(I9/H9,0) -> 0.0030276766 | K9: 316225 | L9: 328064 | M9: =IFERROR(K9-L9,0) -> -11839 | N9: =IFERROR(M9/L9,0) -> -0.036087471 | O9: 1968928 | P9: 1968997 | Q9: =IFERROR(O9-P9,0) -> -69 | R9: =IFERROR(Q9/P9,0) -> -3.5043223e-05 | S9: 573563 | T9: 573535 | U9: =IFERROR(S9-T9,0) -> 28 | V9: =IFERROR(U9/T9,0) -> 4.8820037e-05
B10: 46082 | C10: 7246916 | D10: 7261329 | E10: =IFERROR(C10-D10,0) -> -14413 | F10: =IFERROR(E10/D10,0) -> -0.0019848984 | G10: 1877573 | H10: 1916065 | I10: =IFERROR(G10-H10,0) -> -38492 | J10: =IFERROR(I10/H10,0) -> -0.020089089 | K10: 366286 | L10: 378125 | M10: =IFERROR(K10-L10,0) -> -11839 | N10: =IFERROR(M10/L10,0) -> -0.031309752 | O10: 1518888 | P10: 1520296 | Q10: =IFERROR(O10-P10,0) -> -1408 | R10: =IFERROR(Q10/P10,0) -> -0.00092613544 | S10: 806957 | T10: 806956 | U10: =IFERROR(S10-T10,0) -> 1 | V10: =IFERROR(U10/T10,0) -> 1.2392249e-06
B11: 46113 | C11: 7473826 | D11: 7511310 | E11: =IFERROR(C11-D11,0) -> -37484 | F11: =IFERROR(E11/D11,0) -> -0.0049903412 | G11: 654291 | H11: 591001 | I11: =IFERROR(G11-H11,0) -> 63290 | J11: =IFERROR(I11/H11,0) -> 0.1070895 | K11: 472190 | L11: 476862 | M11: =IFERROR(K11-L11,0) -> -4672 | N11: =IFERROR(M11/L11,0) -> -0.0097973837 | O11: 645355 | P11: 649832 | Q11: =IFERROR(O11-P11,0) -> -4477 | R11: =IFERROR(Q11/P11,0) -> -0.006889473 | S11: 1560892 | T11: 1560792 | U11: =IFERROR(S11-T11,0) -> 100 | V11: =IFERROR(U11/T11,0) -> 6.4070036e-05
B12: 46143 | C12: 5221054 | D12: 5222511 | E12: =IFERROR(C12-D12,0) -> -1457 | F12: =IFERROR(E12/D12,0) -> -0.00027898457 | G12: 106537 | H12: 43247 | I12: =IFERROR(G12-H12,0) -> 63290 | J12: =IFERROR(I12/H12,0) -> 1.4634541 | K12: 691301 | L12: 695973 | M12: =IFERROR(K12-L12,0) -> -4672 | N12: =IFERROR(M12/L12,0) -> -0.0067129041 | O12: 1210355 | P12: 1209581 | Q12: =IFERROR(O12-P12,0) -> 774 | R12: =IFERROR(Q12/P12,0) -> 0.000639891 | S12: 2143527 | T12: 2143517 | U12: =IFERROR(S12-T12,0) -> 10 | V12: =IFERROR(U12/T12,0) -> 4.6652301e-06
B13: 46174 | E13: =IFERROR(C13-D13,0) -> 0 | F13: =IFERROR(E13/D13,0) -> 0
B14: 46204 | E14: =IFERROR(C14-D14,0) -> 0 | F14: =IFERROR(E14/D14,0) -> 0
B15: 46235 | E15: =IFERROR(C15-D15,0) -> 0 | F15: =IFERROR(E15/D15,0) -> 0
B16: 46266 | E16: =IFERROR(C16-D16,0) -> 0 | F16: =IFERROR(E16/D16,0) -> 0
B17: 46296 | E17: =IFERROR(C17-D17,0) -> 0 | F17: =IFERROR(E17/D17,0) -> 0
B18: 46327 | E18: =IFERROR(C18-D18,0) -> 0 | F18: =IFERROR(E18/D18,0) -> 0
B19: 46357 | E19: =IFERROR(C19-D19,0) -> 0 | F19: =IFERROR(E19/D19,0) -> 0
B20: SUB TOTAL | E20: =SUM(E7:E19) -> -146149 | F20: =SUM(F7:F19) -> -0.020323899 | I20: =SUM(I7:I19) -> 100964 | J20: =SUM(J7:J19) -> 1.5597928 | M20: =SUM(M7:M19) -> -44861 | N20: =SUM(N7:N19) -> -0.13195872 | Q20: =SUM(Q7:Q19) -> -15413 | R20: =SUM(R7:R19) -> -0.012451828 | U20: =SUM(U7:U19) -> 140 | V20: =SUM(V7:V19) -> 0.00012068303

Sheet selisih
B2: tgl 23 | F2: tgl 24 | K2: selisih | M2: tgl 25
B3: T01 : 1.777.454 MT | D3: 1777454 | F3: T01 : 1.468.857 MT | I3: 1468857 | K3: =D3-I3 -> 308597 | M3: T01 : 1.172.598 MT | P3: 1172598 | R3: =I3-P3 -> 296259
B4: T02 : 1.806.069 MT | D4: 1806069 | F4: T02 : 1.806.069 MT | I4: 1806069 | K4: =D4-I4 -> 0 | M4: T02 : 1.806.069 MT | P4: 1806069 | R4: =I4-P4 -> 0
B5: T03 : 2.506.156 MT | D5: 2506156 | F5: T03 : 2.506.156 MT | I5: 2506156 | K5: =D5-I5 -> 0 | M5: T03 : 2.506.156 MT | P5: 2506156 | R5: =I5-P5 -> 0
B6: T04 : 167.419 MT | D6: 167419 | F6: T04 : 186.095 MT | I6: 186095 | K6: =D6-I6 -> -18676 | M6: T04 : 206.746 MT | P6: 206746 | R6: =I6-P6 -> -20651
B7: T05 : 253.524 MT | D7: 253524 | F7: T05 : 334.367 MT | I7: 334367 | K7: =D7-I7 -> -80843 | M7: T05 : 408.450 MT | P7: 408450 | R7: =I7-P7 -> -74083
B8: T06 : - | F8: T06 : - | K8: =D8-I8 -> 0 | M8: T06 : - | R8: =I8-P8 -> 0
B9: T07 : 536.860 MT | D9: 536860 | F9: T07 : 536.860 MT | I9: 536860 | K9: =D9-I9 -> 0 | M9: T07 : 536.860 MT | P9: 536860 | R9: =I9-P9 -> 0
B10: T08 : 527.920 MT | D10: 527920 | F10: T08 : 527.920 MT | I10: 527920 | K10: =D10-I10 -> 0 | M10: T08 : 527.920 MT | P10: 527920 | R10: =I10-P10 -> 0
B11: T09 : 50.991 MT | D11: 50991 | F11: T09 : 284.250 MT | I11: 284250 | K11: =D11-I11 -> -233259 | M11: T09 : 485.723 MT | P11: 485723 | R11: =I11-P11 -> -201473
B12: T10 : - | F12: T10 : - | K12: =D12-I12 -> 0 | M12: T10 : - | R12: =I12-P12 -> 0
B13: T11 : - | F13: T11 : - | K13: =D13-I13 -> 0 | M13: T11 : - | R13: =I13-P13 -> 0
B14: T12 : - | F14: T12 : - | K14: =D14-I14 -> 0 | M14: T12 : - | R14: =I14-P14 -> 0
B15: T13 : 573.084 MT | D15: 573084 | F15: T13 : 287.795 MT | I15: 285289 | K15: =D15-I15 -> 287795 | M15: T13 : 526.618 MT | P15: 526618 | R15: =I15-P15 -> -241329
B16: T14 : 450.208 MT | D16: 450208 | F16: T14 : 732.176 MT | I16: 732176 | K16: =D16-I16 -> -281968 | M16: T14 : 543.223 MT | P16: 543223 | R16: =I16-P16 -> 188953

Sheet 04 JUN
E4: FORM
E6: LAPORAN HARIAN PENJUALAN DAILY REPORT COMMERCE
B12: Tanggal Date | C12: CPO | G12: RBDPO | M12: OLEIN | R12: STEARIN | W12: PFAD
C13: CPO Masuk CPO In | D13: Stok Awal Opening Stock | E13: Proses Proccessing | F13: Stok Akhir Clossing Stock | G13: Stok Awal Opening Stock | H13: Produksi Production | I13: Proses Process | J13: Kembalikan Reject | K13: Pengiriman Dispatch | L13: Stok Akhir Clossing Stock | M13: Stok Awal Opening Stock | N13: Produksi Production | O13: Kembalikan Reject | P13: Pengiriman Dispatch | Q13: Stok Akhir Clossing Stock | R13: Stok Awal Opening Stock | S13: Produksi Production | T13: Kembalikan Reject | U13: Pengiriman Dispatch | V13: Stok Akhir Clossing Stock | W13: Stok Awal Opening Stock | X13: Produksi Production | Y13: Pengiriman Dispatch | Z13: Stok Akhir Clossing Stock
B14: Tank Capacity | F14: 7.500 MT | L14: 1.000 MT | Q14: 2.500 MT | V14: 2.000 MT | Z14: 1000 MT
B15: 46174 | C15: 0 | D15: ='[199]31 Mei'!$F$52 -> 5222511 | E15: 0 | F15: =C15+D15-E15 -> 5222511 | G15: ='[199]31 Mei'!$L$52 -> 43247 | H15: 0 | I15: 0 | J15: 0 | K15: 0 | L15: =G15+H15-I15-J15-K15 -> 43247 | M15: ='[199]31 Mei'!$Q$52 -> 903121 | N15: 0 | O15: 0 | P15: 0 | Q15: =M15+N15-O15-P15 -> 903121 | R15: ='[199]31 Mei'!$V$52 -> 2143517 | S15: 0 | T15: 0 | U15: 0 | V15: =R15+S15-U15 -> 2143517 | W15: ='[199]31 Mei'!$Z$52 -> 695973 | X15: 0 | Y15: 0 | Z15: =W15+X15-Y15 -> 695973
B16: 46175 | C16: 132340 | D16: =F15 -> 5222511 | E16: 0 | F16: =C16+D16-E16 -> 5354851 | G16: =L15 -> 43247 | H16: 0 | I16: 0 | J16: 0 | K16: 0 | L16: =G16+H16-I16-J16-K16 -> 43247 | M16: =Q15 -> 903121 | N16: 0 | O16: 0 | P16: 136060 | Q16: =M16+N16-O16-P16 -> 767061 | R16: =V15 -> 2143517 | S16: 0 | T16: 0 | U16: 0 | V16: =R16+S16-U16 -> 2143517 | W16: =Z15 -> 695973 | X16: 0 | Y16: 0 | Z16: =W16+X16-Y16 -> 695973
B17: 46176 | C17: 131990 | D17: =F16 -> 5354851 | E17: 0 | F17: =C17+D17-E17 -> 5486841 | G17: =L16 -> 43247 | H17: 0 | I17: 0 | J17: 0 | K17: 0 | L17: =G17+H17-I17-J17-K17 -> 43247 | M17: =Q16 -> 767061 | N17: 0 | O17: 0 | P17: 75600 | Q17: =M17+N17-O17-P17 -> 691461 | R17: =V16 -> 2143517 | S17: 0 | T17: 0 | U17: 0 | V17: =R17+S17-U17 -> 2143517 | W17: =Z16 -> 695973 | X17: 0 | Y17: 0 | Z17: =W17+X17-Y17 -> 695973
B18: 46177 | C18: 141020 | D18: =F17 -> 5486841 | E18: 0 | F18: =C18+D18-E18 -> 5627861 | G18: =L17 -> 43247 | H18: 0 | I18: 0 | J18: 0 | K18: 0 | L18: =G18+H18-I18-J18-K18 -> 43247 | M18: =Q17 -> 691461 | N18: 0 | O18: 0 | P18: 27800 | Q18: =M18+N18-O18-P18 -> 663661 | R18: =V17 -> 2143517 | S18: 0 | T18: 0 | U18: 0 | V18: =R18+S18-U18 -> 2143517 | W18: =Z17 -> 695973 | X18: 0 | Y18: 0 | Z18: =W18+X18-Y18 -> 695973
B19: 46178 | C19: 0 | D19: =F18 -> 5627861 | E19: 0 | F19: =C19+D19-E19 -> 5627861 | G19: =L18 -> 43247 | H19: 0 | I19: 0 | J19: 0 | K19: 0 | L19: =G19+H19-I19-J19-K19 -> 43247 | M19: =Q18 -> 663661 | N19: 0 | O19: 0 | P19: 0 | Q19: =M19+N19-O19-P19 -> 663661 | R19: =V18 -> 2143517 | S19: 0 | T19: 0 | U19: 0 | V19: =R19+S19-U19 -> 2143517 | W19: =Z18 -> 695973 | X19: 0 | Y19: 0 | Z19: =W19+X19-Y19 -> 695973
B20: 46179 | C20: 0 | D20: =F19 -> 5627861 | E20: 0 | F20: =C20+D20-E20 -> 5627861 | G20: =L19 -> 43247 | H20: 0 | I20: 0 | J20: 0 | K20: 0 | L20: =G20+H20-I20-J20-K20 -> 43247 | M20: =Q19 -> 663661 | N20: 0 | O20: 0 | P20: 0 | Q20: =M20+N20-O20-P20 -> 663661 | R20: =V19 -> 2143517 | S20: 0 | T20: 0 | U20: 0 | V20: =R20+S20-U20 -> 2143517 | W20: =Z19 -> 695973 | X20: 0 | Y20: 0 | Z20: =W20+X20-Y20 -> 695973
B21: 46180 | C21: 0 | D21: =F20 -> 5627861 | E21: 0 | F21: =C21+D21-E21 -> 5627861 | G21: =L20 -> 43247 | H21: 0 | I21: 0 | J21: 0 | K21: 0 | L21: =G21+H21-I21-J21-K21 -> 43247 | M21: =Q20 -> 663661 | N21: 0 | O21: 0 | P21: 0 | Q21: =M21+N21-O21-P21 -> 663661 | R21: =V20 -> 2143517 | S21: 0 | T21: 0 | U21: 0 | V21: =R21+S21-U21 -> 2143517 | W21: =Z20 -> 695973 | X21: 0 | Y21: 0 | Z21: =W21+X21-Y21 -> 695973
B22: 46181 | C22: 0 | D22: =F21 -> 5627861 | E22: 0 | F22: =C22+D22-E22 -> 5627861 | G22: =L21 -> 43247 | H22: 0 | I22: 0 | J22: 0 | K22: 0 | L22: =G22+H22-I22-J22-K22 -> 43247 | M22: =Q21 -> 663661 | N22: 0 | O22: 0 | P22: 0 | Q22: =M22+N22-O22-P22 -> 663661 | R22: =V21 -> 2143517 | S22: 0 | T22: 0 | U22: 0 | V22: =R22+S22-U22 -> 2143517 | W22: =Z21 -> 695973 | X22: 0 | Y22: 0 | Z22: =W22+X22-Y22 -> 695973
B23: 46182 | C23: 0 | D23: =F22 -> 5627861 | E23: 0 | F23: =C23+D23-E23 -> 5627861 | G23: =L22 -> 43247 | H23: 0 | I23: 0 | J23: 0 | K23: 0 | L23: =G23+H23-I23-J23-K23 -> 43247 | M23: =Q22 -> 663661 | N23: 0 | O23: 0 | P23: 0 | Q23: =M23+N23-O23-P23 -> 663661 | R23: =V22 -> 2143517 | S23: 0 | T23: 0 | U23: 0 | V23: =R23+S23-U23 -> 2143517 | W23: =Z22 -> 695973 | X23: 0 | Y23: 0 | Z23: =W23+X23-Y23 -> 695973
B24: 46183 | C24: 0 | D24: =F23 -> 5627861 | E24: 0 | F24: =C24+D24-E24 -> 5627861 | G24: =L23 -> 43247 | H24: 0 | I24: 0 | J24: 0 | K24: 0 | L24: =G24+H24-I24-J24-K24 -> 43247 | M24: =Q23 -> 663661 | N24: 0 | O24: 0 | P24: 0 | Q24: =M24+N24-O24-P24 -> 663661 | R24: =V23 -> 2143517 | S24: 0 | T24: 0 | U24: 0 | V24: =R24+S24-U24 -> 2143517 | W24: =Z23 -> 695973 | X24: 0 | Y24: 0 | Z24: =W24+X24-Y24 -> 695973
B25: 46184 | C25: 0 | D25: =F24 -> 5627861 | E25: 0 | F25: =C25+D25-E25 -> 5627861 | G25: =L24 -> 43247 | H25: 0 | I25: 0 | J25: 0 | K25: 0 | L25: =G25+H25-I25-J25-K25 -> 43247 | M25: =Q24 -> 663661 | N25: 0 | O25: 0 | P25: 0 | Q25: =M25+N25-O25-P25 -> 663661 | R25: =V24 -> 2143517 | S25: 0 | T25: 0 | U25: 0 | V25: =R25+S25-U25 -> 2143517 | W25: =Z24 -> 695973 | X25: 0 | Y25: 0 | Z25: =W25+X25-Y25 -> 695973
B26: 46185 | C26: 0 | D26: =F25 -> 5627861 | E26: 0 | F26: =C26+D26-E26 -> 5627861 | G26: =L25 -> 43247 | H26: 0 | I26: 0 | J26: 0 | K26: 0 | L26: =G26+H26-I26-J26-K26 -> 43247 | M26: =Q25 -> 663661 | N26: 0 | O26: 0 | P26: 0 | Q26: =M26+N26-O26-P26 -> 663661 | R26: =V25 -> 2143517 | S26: 0 | T26: 0 | U26: 0 | V26: =R26+S26-U26 -> 2143517 | W26: =Z25 -> 695973 | X26: 0 | Y26: 0 | Z26: =W26+X26-Y26 -> 695973
B27: 46186 | C27: 0 | D27: =F26 -> 5627861 | E27: 0 | F27: =C27+D27-E27 -> 5627861 | G27: =L26 -> 43247 | H27: 0 | I27: 0 | J27: 0 | K27: 0 | L27: =G27+H27-I27+J27-K27 -> 43247 | M27: =Q26 -> 663661 | N27: 0 | O27: 0 | P27: 0 | Q27: =M27+N27-O27-P27 -> 663661 | R27: =V26 -> 2143517 | S27: 0 | T27: 0 | U27: 0 | V27: =R27+S27-U27 -> 2143517 | W27: =Z26 -> 695973 | X27: 0 | Y27: 0 | Z27: =W27+X27-Y27 -> 695973
B28: 46187 | C28: 0 | D28: =F27 -> 5627861 | E28: 0 | F28: =C28+D28-E28 -> 5627861 | G28: =L27 -> 43247 | H28: 0 | I28: 0 | J28: 0 | K28: 0 | L28: =G28+H28-I28+J28-K28 -> 43247 | M28: =Q27 -> 663661 | N28: 0 | O28: 0 | P28: 0 | Q28: =M28+N28-O28-P28 -> 663661 | R28: =V27 -> 2143517 | S28: 0 | T28: 0 | U28: 0 | V28: =R28+S28-U28 -> 2143517 | W28: =Z27 -> 695973 | X28: 0 | Y28: 0 | Z28: =W28+X28-Y28 -> 695973
B29: 46188 | C29: 0 | D29: =F28 -> 5627861 | E29: 0 | F29: =C29+D29-E29+T29 -> 5627861 | G29: =L28 -> 43247 | H29: 0 | I29: 0 | J29: 0 | K29: 0 | L29: =G29+H29-I29+J29-K29 -> 43247 | M29: =Q28 -> 663661 | N29: 0 | O29: 0 | P29: 0 | Q29: =M29+N29-O29-P29 -> 663661 | R29: =V28 -> 2143517 | S29: 0 | T29: 0 | U29: 0 | V29: =R29+S29-T29-U29 -> 2143517 | W29: =Z28 -> 695973 | X29: 0 | Y29: 0 | Z29: =W29+X29-Y29 -> 695973
B30: 46189 | C30: 0 | D30: =F29 -> 5627861 | E30: 0 | F30: =C30+D30-E30 -> 5627861 | G30: =L29 -> 43247 | H30: 0 | I30: 0 | J30: 0 | K30: 0 | L30: =G30+H30-I30+J30-K30 -> 43247 | M30: =Q29 -> 663661 | N30: 0 | O30: 0 | P30: 0 | Q30: =M30+N30-O30-P30 -> 663661 | R30: =V29 -> 2143517 | S30: 0 | T30: 0 | U30: 0 | V30: =R30+S30-U30 -> 2143517 | W30: =Z29 -> 695973 | X30: 0 | Y30: 0 | Z30: =W30+X30-Y30 -> 695973
B31: 46190 | C31: 0 | D31: =F30 -> 5627861 | E31: 0 | F31: =C31+D31-E31 -> 5627861 | G31: =L30 -> 43247 | H31: 0 | I31: 0 | J31: 0 | K31: 0 | L31: =G31+H31-I31+J31-K31 -> 43247 | M31: =Q30 -> 663661 | N31: 0 | O31: 0 | P31: 0 | Q31: =M31+N31-O31-P31 -> 663661 | R31: =V30 -> 2143517 | S31: 0 | T31: 0 | U31: 0 | V31: =R31+S31-U31 -> 2143517 | W31: =Z30 -> 695973 | X31: 0 | Y31: 0 | Z31: =W31+X31-Y31 -> 695973
B32: 46191 | C32: 0 | D32: =F31 -> 5627861 | E32: 0 | F32: =C32+D32-E32 -> 5627861 | G32: =L31 -> 43247 | H32: 0 | I32: 0 | J32: 0 | K32: 0 | L32: =G32+H32-I32+J32-K32 -> 43247 | M32: =Q31 -> 663661 | N32: 0 | O32: 0 | P32: 0 | Q32: =M32+N32-O32-P32 -> 663661 | R32: =V31 -> 2143517 | S32: 0 | T32: 0 | U32: 0 | V32: =R32+S32-U32 -> 2143517 | W32: =Z31 -> 695973 | X32: 0 | Y32: 0 | Z32: =W32+X32-Y32 -> 695973
B33: 46192 | C33: 0 | D33: =F32 -> 5627861 | E33: 0 | F33: =C33+D33-E33 -> 5627861 | G33: =L32 -> 43247 | H33: 0 | I33: 0 | J33: 0 | K33: 0 | L33: =G33+H33-I33+J33-K33 -> 43247 | M33: =Q32 -> 663661 | N33: 0 | O33: 0 | P33: 0 | Q33: =M33+N33-O33-P33 -> 663661 | R33: =V32 -> 2143517 | S33: 0 | T33: 0 | U33: 0 | V33: =R33+S33-U33 -> 2143517 | W33: =Z32 -> 695973 | X33: 0 | Y33: 0 | Z33: =W33+X33-Y33 -> 695973
B34: 46193 | C34: 0 | D34: =F33 -> 5627861 | E34: 0 | F34: =C34+D34-E34 -> 5627861 | G34: =L33 -> 43247 | H34: 0 | I34: 0 | J34: 0 | K34: 0 | L34: =G34+H34-I34+J34-K34 -> 43247 | M34: =Q33 -> 663661 | N34: 0 | O34: 0 | P34: 0 | Q34: =M34+N34-O34-P34 -> 663661 | R34: =V33 -> 2143517 | S34: 0 | T34: 0 | U34: 0 | V34: =R34+S34-U34 -> 2143517 | W34: =Z33 -> 695973 | X34: 0 | Y34: 0 | Z34: =W34+X34-Y34 -> 695973
B35: 46194 | C35: 0 | D35: =F34 -> 5627861 | E35: 0 | F35: =C35+D35-E35 -> 5627861 | G35: =L34 -> 43247 | H35: 0 | I35: 0 | J35: 0 | K35: 0 | L35: =G35+H35-I35+J35-K35 -> 43247 | M35: =Q34 -> 663661 | N35: 0 | O35: 0 | P35: 0 | Q35: =M35+N35-O35-P35 -> 663661 | R35: =V34 -> 2143517 | S35: 0 | T35: 0 | U35: 0 | V35: =R35+S35-U35 -> 2143517 | W35: =Z34 -> 695973 | X35: 0 | Y35: 0 | Z35: =W35+X35-Y35 -> 695973
B36: 46195 | C36: 0 | D36: =F35 -> 5627861 | E36: 0 | F36: =C36+D36-E36 -> 5627861 | G36: =L35 -> 43247 | H36: 0 | I36: 0 | J36: 0 | K36: 0 | L36: =G36+H36-I36+J36-K36 -> 43247 | M36: =Q35 -> 663661 | N36: 0 | O36: 0 | P36: 0 | Q36: =M36+N36-O36-P36 -> 663661 | R36: =V35 -> 2143517 | S36: 0 | T36: 0 | U36: 0 | V36: =R36+S36-U36 -> 2143517 | W36: =Z35 -> 695973 | X36: 0 | Y36: 0 | Z36: =W36+X36-Y36 -> 695973
B37: 46196 | C37: 0 | D37: =F36 -> 5627861 | E37: 0 | F37: =C37+D37-E37+O37 -> 5627861 | G37: =L36 -> 43247 | H37: 0 | I37: 0 | J37: 0 | K37: 0 | L37: =G37+H37-I37+J37-K37 -> 43247 | M37: =Q36 -> 663661 | N37: 0 | O37: 0 | P37: 0 | Q37: =M37+N37-O37-P37 -> 663661 | R37: =V36 -> 2143517 | S37: 0 | T37: 0 | U37: 0 | V37: =R37+S37-U37 -> 2143517 | W37: =Z36 -> 695973 | X37: 0 | Y37: 0 | Z37: =W37+X37-Y37 -> 695973 | AB37: =421849 -> 421849
B38: 46197 | C38: 0 | D38: =F37 -> 5627861 | E38: 0 | F38: =C38+D38-E38+O38 -> 5627861 | G38: =L37 -> 43247 | H38: 0 | I38: 0 | J38: 0 | K38: 0 | L38: =G38+H38-I38+J38-K38 -> 43247 | M38: =Q37 -> 663661 | N38: 0 | O38: 0 | P38: 0 | Q38: =M38+N38-O38-P38 -> 663661 | R38: =V37 -> 2143517 | S38: 0 | T38: 0 | U38: 0 | V38: =R38+S38-U38 -> 2143517 | W38: =Z37 -> 695973 | X38: 0 | Y38: 0 | Z38: =W38+X38-Y38 -> 695973 | AB38: 8199
B39: 46198 | C39: 0 | D39: =F38 -> 5627861 | E39: 0 | F39: =C39+D39-E39+O39 -> 5627861 | G39: =L38 -> 43247 | H39: 0 | I39: 0 | J39: 0 | K39: 0 | L39: =G39+H39-I39+J39-K39 -> 43247 | M39: =Q38 -> 663661 | N39: 0 | O39: 0 | P39: 0 | Q39: =M39+N39-O39-P39 -> 663661 | R39: =V38 -> 2143517 | S39: 0 | T39: 0 | U39: 0 | V39: =R39+S39-U39 -> 2143517 | W39: =Z38 -> 695973 | X39: 0 | Y39: 0 | Z39: =W39+X39-Y39 -> 695973
B40: 46199 | C40: 0 | D40: =F39 -> 5627861 | E40: 0 | F40: =C40+D40-E40+O40 -> 5627861 | G40: =L39 -> 43247 | H40: 0 | I40: 0 | J40: 0 | K40: 0 | L40: =G40+H40-I40+J40-K40 -> 43247 | M40: =Q39 -> 663661 | N40: 0 | O40: 0 | P40: 0 | Q40: =M40+N40-O40-P40 -> 663661 | R40: =V39 -> 2143517 | S40: 0 | T40: 0 | U40: 0 | V40: =R40+S40-U40 -> 2143517 | W40: =Z39 -> 695973 | X40: 0 | Y40: 0 | Z40: =W40+X40-Y40 -> 695973 | AB40: =AB37-AB38 -> 413650
B41: 46200 | C41: 0 | D41: =F40 -> 5627861 | E41: 0 | F41: =C41+D41-E41+O41 -> 5627861 | G41: =L40 -> 43247 | H41: 0 | I41: 0 | J41: 0 | K41: 0 | L41: =G41+H41-I41+J41-K41 -> 43247 | M41: =Q40 -> 663661 | N41: 0 | O41: 0 | P41: 0 | Q41: =M41+N41-O41-P41 -> 663661 | R41: =V40 -> 2143517 | S41: 0 | T41: 0 | U41: 0 | V41: =R41+S41-U41 -> 2143517 | W41: =Z40 -> 695973 | X41: 0 | Y41: 0 | Z41: =W41+X41-Y41 -> 695973
B42: 46201 | C42: 0 | D42: =F41 -> 5627861 | E42: 0 | F42: =C42+D42-E42+O42 -> 5627861 | G42: =L41 -> 43247 | H42: 0 | I42: 0 | J42: 0 | K42: 0 | L42: =G42+H42-I42+J42-K42 -> 43247 | M42: =Q41 -> 663661 | N42: 0 | O42: 0 | P42: 0 | Q42: =M42+N42-O42-P42 -> 663661 | R42: =V41 -> 2143517 | S42: 0 | T42: 0 | U42: 0 | V42: =R42+S42-U42 -> 2143517 | W42: =Z41 -> 695973 | X42: 0 | Y42: 0 | Z42: =W42+X42-Y42 -> 695973
B43: 46202 | C43: 0 | D43: =F42 -> 5627861 | E43: 0 | F43: =C43+D43-E43+O43 -> 5627861 | G43: =L42 -> 43247 | H43: 0 | I43: 0 | J43: 0 | K43: 0 | L43: =G43+H43-I43+J43-K43 -> 43247 | M43: =Q42 -> 663661 | N43: 0 | O43: 0 | P43: 0 | Q43: =M43+N43-O43-P43 -> 663661 | R43: =V42 -> 2143517 | S43: 0 | T43: 0 | U43: 0 | V43: =R43+S43-U43 -> 2143517 | W43: =Z42 -> 695973 | X43: 0 | Y43: 0 | Z43: =W43+X43-Y43 -> 695973
B44: 46203 | C44: 0 | D44: =F43 -> 5627861 | E44: 0 | F44: =C44+D44-E44+O44 -> 5627861 | G44: =L43 -> 43247 | H44: 0 | I44: 0 | J44: 0 | K44: 0 | L44: =G44+H44-I44+J44-K44 -> 43247 | M44: =Q43 -> 663661 | N44: 0 | O44: 0 | P44: 0 | Q44: =M44+N44-O44-P44 -> 663661 | R44: =V43 -> 2143517 | S44: 0 | T44: 0 | U44: 0 | V44: =R44+S44-U44 -> 2143517 | W44: =Z43 -> 695973 | X44: 0 | Y44: 0 | Z44: =W44+X44-Y44 -> 695973
B45: 46204 | C45: 0 | D45: =F44 -> 5627861 | E45: 0 | F45: =C45+D45-E45+O45 -> 5627861 | G45: =L44 -> 43247 | H45: 0 | I45: 0 | J45: 0 | K45: 0 | L45: =G45+H45-I45+J45-K45 -> 43247 | M45: =Q44 -> 663661 | N45: 0 | O45: 0 | P45: 0 | Q45: =M45+N45-O45-P45 -> 663661 | R45: =V44 -> 2143517 | S45: 0 | T45: 0 | U45: 0 | V45: =R45+S45-U45 -> 2143517 | W45: =Z44 -> 695973 | X45: 0 | Y45: 0 | Z45: =W45+X45-Y45 -> 695973
B46: Total | C46: =SUM(C15:C45) -> 405350 | E46: =SUM(E15:E45) -> 0 | F46: =F45 -> 5627861 | H46: =SUM(H15:H45) -> 0 | I46: =SUM(I15:I45) -> 0 | J46: =SUM(J15:J45) -> 0 | K46: =SUM(K15:K45) -> 0 | L46: =L45 -> 43247 | N46: =SUM(N15:N45) -> 0 | O46: =SUM(O15:O45) -> 0 | P46: =SUM(P15:P45) -> 239460 | Q46: =Q45 -> 663661 | S46: =SUM(S15:S45) -> 0 | T46: =SUM(T15:T45) -> 0 | U46: =SUM(U15:U45) -> 0 | V46: =V45 -> 2143517 | X46: =SUM(X15:X45) -> 0 | Y46: =SUM(Y15:Y45) -> 0 | Z46: =Z45 -> 695973

Sheet 04 Juni
B1: STORAGE TANKS | J1: PRODUCTION DETAILS | O1: SHIPMENT/SALE | Q1: OIL IN PLANT | R1: CLOSING | T1: SOUNDING | U1: 5221054
B2: No Tank | C2: Commodity | D2: Cap (MT) | E2: Opening | F2: In | G2: Output | H2: Closing | J2: Material Name | K2: Kg Today | L2: Kg Todate | M2: % Today | N2: % Todate | O2: Today | P2: Todate | Q2: Today | R2: Today | T2: SELISIH | U2: =H6-U1 -> 406807
B3: ST 01 | C3: CPO | D3: 2500 | E3: ='[203]03 Juni'!H11 -> 541254 | G3: 0 | H3: =E3+F3-G3 -> 541254 | J3: REFINERY PLANT | S3: =H6 -> 5627861
B4: ST 02 | C4: CPO | D4: 2500 | E4: ='[203]03 Juni'!H12 -> 2593880 | F4: 0 | G4: 0 | H4: =E4+F4-G4 -> 2593880 | J4: CPO USED | K4: =G6 -> 0 | L4: =K4 -> 0 | R4: =E6+O60-K4+Q4 -> 5627861 | S4: 5612646
B5: ST 03 | C5: CPO | D5: 2500 | E5: ='[203]03 Juni'!H13 -> 2351707 | F5: =O60 -> 141020 | G5: 0 | H5: =E5+F5-G5 -> 2492727 | J5: RBDPO PROD | K5: =F27 -> 0 | L5: =K5 -> 0 | M5: =IFERROR(K5/K4,0) -> 0 | N5: =IFERROR(L5/L4,0) -> 0 | R5: =E27+K5-K9-O5 -> 43247 | S5: =S3-S4 -> 15215 | W5: 498748
B6: TOTAL | C6: =SUM(D3:D5) -> 7500 | E6: =SUM(E3:E5) -> 5486841 | F6: =SUM(F3:F5) -> 141020 | G6: =SUM(G3:G5) -> 0 | H6: =SUM(H3:H5) -> 5627861 | J6: PFAD PROD | K6: =F15 -> 0 | L6: =K6 -> 0 | M6: =IFERROR(K6/K4,0) -> 0 | N6: =IFERROR(L6/L5,0) -> 0 | R6: =E15+E9+K6-O6 -> 695973 | S6: =L5+L6 -> 0
J7: OIL LOSSES | K7: =K4-K5-K6 -> 0 | L7: =K7 -> 0 | M7: =IFERROR(K7/K4,0) -> 0 | N7: =IFERROR(L7/L6,0) -> 0 | W7: 26924
B8: ST 04 | C8: PFAD | D8: 500 | E8: ='[203]03 Juni'!H16 -> 476862 | F8: 0 | G8: 0 | H8: =E8+F8-G8 -> 476862 | J8: FRACTINATION PLANT | S8: =L4-S6 -> 0 | U8: =7208127/1000 -> 7208.127 | W8: 2547143 | X8: 27440
B9: TOTAL | C9: =SUM(D6:D8) -> 500 | E9: =SUM(E8) -> 476862 | F9: =SUM(F8) -> 0 | G9: =SUM(G8) -> 0 | H9: =SUM(H8)+H15 -> 695973 | J9: RBDPO USED | K9: =G27 -> 0 | L9: =K9 -> 0 | S9: =300*N5 -> 0 | W9: 2241639
J10: OLEIN PROD | K10: =F25 -> 0 | L10: =K10 -> 0 | M10: =IFERROR(K10/K9,0) -> 0 | N10: =IFERROR(L10/L9,0) -> 0 | O10: =G25 -> 27800 | P10: =O10+'[203]03 Juni'!P18 -> 239460 | R10: =E25+K10-O10 -> 663661 | S10: =300000 -> 300000 | U10: -500.23
B11: ST 05 | C11: STEARIN | D11: 500 | E11: ='[203]03 Juni'!H19 -> 504204 | F11: 0 | G11: 0 | H11: =E11+F11-G11 -> 504204 | J11: STEARIN PROD | K11: =F28+F11 -> 0 | L11: =K11 -> 0 | M11: =IFERROR(K11/K9,0) -> 0 | N11: =IFERROR(L11/L9,0) -> 0 | O11: =G11 -> 0 | P11: =O11 -> 0 | R11: =E13+K11-O11 -> 2143517 | S11: =S8/S10 -> 0 | W11: =4815706+X8 -> 4843146
B12: ST 06 | C12: STEARIN | D12: 500 | E12: ='[203]03 Juni'!H20 -> 554452 | F12: 0 | G12: 0 | H12: =E12+F12-G12 -> 554452 | J12: PACKAGING PLANT | S12: =S8/L4 -> #DIV/0! | T12: =H29-R5 -> 0 | W12: =H6 -> 5627861
B13: TOTAL | C13: =SUM(D11:D12) -> 1000 | E13: =SUM(E11:E12)+E28 -> 2143517 | F13: =SUM(F11:F12) -> 0 | G13: =SUM(G11:G12) -> 0 | H13: =SUM(H11:H12)+H28 -> 2143517 | J13: Material Name | K13: Kg Today | L13: Liter Today | M13: Kg Todate | O13: Liter Todate | Q13: Pcs Today | R13: Pcs Todate | W13: =W12-W11 -> 784715 | Y13: =W12/W11/100% -> 1.1620259
J14: OLEIN USED | S14: 10962 | U14: 22000
B15: ST 07 | C15: PFAD | D15: 500 | E15: ='[203]03 Juni'!H23 -> 219111 | F15: 0 | G15: 0 | H15: =E15+F15-G15 -> 219111 | J15: POUCH 1L | U15: =U14/311800 -> 0.07055805
B16: ST 08 | C16: OLEIN | D16: 500 | E16: ='[203]03 Juni'!H24 -> 0 | F16: 0 | G16: 0 | H16: =E16+F16-G16 -> 0 | J16: POUCH 2L | W16: =H25-W13 -> -121054
B17: ST 09 | C17: OLEIN | D17: 500 | E17: ='[203]03 Juni'!H25 -> 0 | F17: 0 | G17: 0 | H17: =E17+F17-G17 -> 0 | J17: PILLOW 0,9 L | S17: =R10-H25 -> 0
B18: ST 10 | C18: OLEIN | D18: 500 | E18: ='[203]03 Juni'!H26 -> 164508 | F18: 0 | G18: 27800 | H18: =E18+F18-G18 -> 136708 | J18: DRUM 200 L
B19: ST 11 | C19: OLEIN | D19: 500 | E19: ='[203]03 Juni'!H27 -> 0 | F19: 0 | G19: 0 | H19: =E19+F19-G19 -> 0
B20: ST 12 | C20: OLEIN | D20: 500 | E20: ='[203]03 Juni'!H28 -> 526953 | F20: 0 | G20: 0 | H20: =E20+F20-G20 -> 526953 | J20: CHEMICALS & UTILITY CONSUMPTION USED | U20: =631356-568066 -> 63290
B21: BUFFER 1 | C21: OLEIN | D21: 100 | E21: ='[203]03 Juni'!H29 -> 0 | F21: 0 | G21: 0 | H21: =E21+F21-G21 -> 0 | J21: Material Name | K21: Used Today | L21: Used Todate | M21: % Today | N21: % Todate | O21: Receipt Today | P21: Receipt Todate | Q21: Stock in Plant | R21: Warehouse/Tank | T21: selisih soundingan | U21: =791266-727976 -> 63290
B22: BUFFER 2 | C22: OLEIN | D22: 100 | E22: ='[203]03 Juni'!H30 -> 0 | F22: 0 | G22: 0 | H22: =E22+F22-G22 -> 0 | J22: REFINERY & FRACTIONATION PLANT
B23: BUFFER 3 | C23: OLEIN | D23: 50 | E23: ='[203]03 Juni'!H31 -> 0 | F23: 0 | G23: 0 | H23: =E23+F23-G23 -> 0 | J23: CHEMICALS
B24: BUFFER 4 | C24: OLEIN | D24: 50 | E24: ='[203]02 Juni'!H32 -> 0 | F24: 0 | G24: 0 | H24: =E24+F24-G24 -> 0 | J24: BLEACHING EARTH (Kg) | L24: =K24 -> 0 | M24: =IFERROR(K24/K4,0) -> 0 | N24: =IFERROR(L24/L4,0) -> 0 | Q24: ='[201]31 Mei'!Q32-K24+T24 -> 19379.5 | R24: ='[203]03 Juni'!R32+O24-T24 -> 71000 | S24: BE REFINERY
B25: TOTAL | C25: =SUM(D15:D24) -> 3300 | E25: =SUM(E16:E24) -> 691461 | F25: =SUM(F16:F24) -> 0 | G25: =SUM(G15:G24) -> 27800 | H25: =SUM(H16:H24) -> 663661 | J25: PHOSPORIC ACID (Kg) | L25: =K25 -> 0 | M25: =IFERROR(K25/K4,0) -> 0 | N25: =IFERROR(L25/L4,0) -> 0 | Q25: ='[201]31 Mei'!Q33-K25+T25 -> -68.986 | R25: ='[203]03 Juni'!R33+O25-T25 -> 2555 | S25: PA REFINERY | U25: =R25/35 -> 73
J26: FUEL HPB (L) | L26: =K26 -> 0 | M26: =IFERROR(K26/K4,0) -> 0 | N26: =IFERROR(L26/L4,0) -> 0 | O26: 0 | P26: =O26 -> 0 | Q26: ='[201]31 Mei'!Q34-K26+T27 -> 1591.38 | R26: ='[203]03 Juni'!R34+O26-T26 -> 21835.91 | S26: SOLAR ALL | T26: 95 | W26: 20000000
B27: ST 13 | C27: RBDPO | D27: 1000 | E27: ='[203]03 Juni'!H35 -> 43247 | F27: 0 | G27: 0 | H27: =E27+F27-G27 -> 43247 | J27: UTILITIES | S27: SOLAR REFENRY | W27: 20000000
B28: ST 14 | C28: STEARIN | D28: 1000 | E28: ='[203]03 Juni'!H36 -> 1084861 | F28: 0 | G28: 0 | H28: =E28+F28-G28 -> 1084861 | J28: POWER REFINING (Kwh/MT) | K28: =8890/1000 -> 8.89 | L28: =K28+'[203]03 Juni'!L36 -> 35.138 | M28: =IFERROR(K28/K4,0) -> 0 | N28: =IFERROR(L28/L4,0) -> 0 | W28: 5000000
B29: TOTAL | C29: =SUM(D27:D28) -> 2000 | F29: =F27 -> 0 | G29: =SUM(G27:G28) -> 0 | H29: =SUM(H27) -> 43247 | J29: STEAM LPB (Kg/MT) | K29: 0 | L29: =K29 -> 0 | M29: =IFERROR(K29/K4,0) -> 0 | N29: =IFERROR(L29/L4,0) -> 0 | W29: 18000000
B30: PACKAGING PLANT | J30: WATER REFINING & FRACT (Kg/MT) | L30: =K30 -> 0 | M30: =IFERROR(K30/K4,0) -> 0 | N30: =IFERROR(L30/L4,0) -> 0 | W30: 750000
B31: Material Name | E31: Used Today | G31: Used Todate | H31: Repacking Today | W31: 100000
B32: VIT A (gram) | H32: =E32 -> 0 | J32: Repacking Todate | K32: Reject Today | L32: Reject Todate | M32: Receipt Today | O32: Receipt Todate | Q32: Stock In Plant | R32: Warehouse | W32: 545000
B33: POUCH 1L | W33: 450000
B34: POUCH 2L | W34: 646000
B35: PILLOW 0,9 L | H35: =E35 -> 0
B36: CARTON POUCH 1L | W36: =SUM(W26:W35) -> 65491000
B37: CARTON POUCH 2L | W37: =100000000-500000 -> 99500000
B38: CARTON PILLOW 0,9 L | W38: =W37-W36 -> 34009000
B39: DRUM 200L
B40: PLESTER
...
