Workbook

Sheet INFO TANGKI
A1: INFO TANGKI - DATA FILLING & RETENSI - MARET 2026
A2: Isi sheet ini dengan info tanggal filling setiap tangki. Data digunakan otomatis oleh sheet EVALUASI STABILITAS.
A3: NO | B3: TANGKI | C3: PRODUK | D3: AWAL FILLING | E3: AKHIR FILLING | F3: RETENTION TIME (hari) | G3: TONASE (kg) | H3: BE YANG DIGUNAKAN | I3: CATATAN | J3: HARI TERSIMPAN (s/d Hari Ini)
A4: 1 | B4: CPO ST01 | C4: CPO | F4: =IF(AND(D4<>"",E4<>""),E4-D4,"") | G4: {=IFERROR(INDEX('MUTASI STOK'!K5:K34,MATCH(2,1/('MUTASI STOK'!K5:K34>0),1)),0)} -> 2506149 | J4: =IF(E4<>"",TODAY()-E4,IF(D4<>"",TODAY()-D4,""))
A5: 2 | B5: CPO ST02 | C5: CPO | F5: =IF(AND(D5<>"",E5<>""),E5-D5,"") | G5: {=IFERROR(INDEX('MUTASI STOK'!U5:U34,MATCH(2,1/('MUTASI STOK'!U5:U34>0),1)),0)} -> 2577692 | J5: =IF(E5<>"",TODAY()-E5,IF(D5<>"",TODAY()-D5,""))
A6: 3 | B6: CPO ST03 | C6: CPO | F6: =IF(AND(D6<>"",E6<>""),E6-D6,"") | G6: {=IFERROR(INDEX('MUTASI STOK'!AE5:AE34,MATCH(2,1/('MUTASI STOK'!AE5:AE34>0),1)),0)} -> 2443036 | J6: =IF(E6<>"",TODAY()-E6,IF(D6<>"",TODAY()-D6,""))
A7: 4 | B7: PFAD ST04 | C7: PFAD | F7: =IF(AND(D7<>"",E7<>""),E7-D7,"") | G7: {=IFERROR(INDEX('MUTASI STOK'!AL5:AL34,MATCH(2,1/('MUTASI STOK'!AL5:AL34>0),1)),0)} -> 328064 | J7: =IF(E7<>"",TODAY()-E7,IF(D7<>"",TODAY()-D7,""))
A8: 5 | B8: Stearin ST05 | C8: Stearin | F8: =IF(AND(D8<>"",E8<>""),E8-D8,"") | G8: {=IFERROR(INDEX('MUTASI STOK'!AS5:AS34,MATCH(2,1/('MUTASI STOK'!AS5:AS34>0),1)),0)} -> 529521 | J8: =IF(E8<>"",TODAY()-E8,IF(D8<>"",TODAY()-D8,""))
A9: 6 | B9: Stearin ST06 | C9: Stearin | F9: =IF(AND(D9<>"",E9<>""),E9-D9,"") | G9: {=IFERROR(INDEX('MUTASI STOK'!AZ5:AZ34,MATCH(2,1/('MUTASI STOK'!AZ5:AZ34>0),1)),0)} -> 44014 | J9: =IF(E9<>"",TODAY()-E9,IF(D9<>"",TODAY()-D9,""))
A10: 7 | B10: Olein ST07 | C10: Olein | D10: 15 Jan 2026 | E10: 20 Jan 2026 | F10: =IF(AND(D10<>"",E10<>""),E10-D10,"") -> 5 | G10: {=IFERROR(INDEX('MUTASI STOK'!BJ5:BJ34,MATCH(2,1/('MUTASI STOK'!BJ5:BJ34>0),1)),0)} -> 536860 | H10: CLARIANT OPTIMUM | J10: =IF(E10<>"",TODAY()-E10,IF(D10<>"",TODAY()-D10,"")) -> 65
A11: 8 | B11: Olein ST08 | C11: Olein | D11: 20 Jan 2026 | E11: 23 Jan 2026 | F11: =IF(AND(D11<>"",E11<>""),E11-D11,"") -> 3 | G11: {=IFERROR(INDEX('MUTASI STOK'!BT5:BT34,MATCH(2,1/('MUTASI STOK'!BT5:BT34>0),1)),0)} -> 278400 | H11: CLARIANT OPTIMUM | J11: =IF(E11<>"",TODAY()-E11,IF(D11<>"",TODAY()-D11,"")) -> 62
A12: 9 | B12: Olein ST09 | C12: Olein | D12: 23 Jan 2026 | E12: 26 Jan 2026 | F12: =IF(AND(D12<>"",E12<>""),E12-D12,"") -> 3 | G12: {=IFERROR(INDEX('MUTASI STOK'!CD5:CD34,MATCH(2,1/('MUTASI STOK'!CD5:CD34>0),1)),0)} -> 508583 | H12: CLARIANT OPTIMUM | J12: =IF(E12<>"",TODAY()-E12,IF(D12<>"",TODAY()-D12,"")) -> 59
A13: 10 | B13: Olein ST10 | C13: Olein | D13: 04 Jan 2026 | E13: 04 Feb 2026 | F13: =IF(AND(D13<>"",E13<>""),E13-D13,"") -> 31 | G13: {=IFERROR(INDEX('MUTASI STOK'!CN5:CN34,MATCH(2,1/('MUTASI STOK'!CN5:CN34>0),1)),0)} -> 510730 | H13: CLARIANT OPTIMUM | J13: =IF(E13<>"",TODAY()-E13,IF(D13<>"",TODAY()-D13,"")) -> 50
A14: 11 | B14: Olein ST11 | C14: Olein | D14: 04 Feb 2026 | E14: 04 Feb 2026 | F14: =IF(AND(D14<>"",E14<>""),E14-D14,"") -> 0 | G14: {=IFERROR(INDEX('MUTASI STOK'!CX5:CX34,MATCH(2,1/('MUTASI STOK'!CX5:CX34>0),1)),0)} -> 26023 | H14: CLARIANT OPTIMUM | J14: =IF(E14<>"",TODAY()-E14,IF(D14<>"",TODAY()-D14,"")) -> 50
A15: 12 | B15: RBDPO ST13 | C15: RBDPO | F15: =IF(AND(D15<>"",E15<>""),E15-D15,"") | G15: {=IFERROR(INDEX('MUTASI STOK'!DE5:DE34,MATCH(2,1/('MUTASI STOK'!DE5:DE34>0),1)),0)} -> 1164563 | J15: =IF(E15<>"",TODAY()-E15,IF(D15<>"",TODAY()-D15,""))
A16: 13 | B16: RBDPO ST14 | C16: RBDPO | F16: =IF(AND(D16<>"",E16<>""),E16-D16,"") | G16: {=IFERROR(INDEX('MUTASI STOK'!DL5:DL34,MATCH(2,1/('MUTASI STOK'!DL5:DL34>0),1)),0)} -> 961820 | J16: =IF(E16<>"",TODAY()-E16,IF(D16<>"",TODAY()-D16,""))
A17: 14 | B17: Buffer 2 | C17: Olein | F17: =IF(AND(D17<>"",E17<>""),E17-D17,"") | G17: {=IFERROR(INDEX('MUTASI STOK'!DS5:DS34,MATCH(2,1/('MUTASI STOK'!DS5:DS34>0),1)),0)} -> 32951 | J17: =IF(E17<>"",TODAY()-E17,IF(D17<>"",TODAY()-D17,""))

Sheet EVALUASI STABILITAS
A1: EVALUASI STABILITAS MUTU PRODUK SELAMA PENYIMPANAN DI TANGKI - PT WIJAYA INTI NUSANTARA SAWIT - MARET 2026
A2: Laporan ini otomatis mengambil data dari sheet INPUT KUALITAS. Kesimpulan dan laju kenaikan FFA dihitung otomatis berdasarkan data harian yang diinput.
A3: ST 07 OLEIN | 15 Jan 2026 s/d 20 Jan 2026 | Retensi: 70 hari
A4: ST 07 OLEIN Tonase : 536,860 kg Awal Filling : 15 Jan 2026 Akhir Filling: 20 Jan 2026 As of : 31 Maret 2026 | I4: PARAMETER | K4: Awal (20 Jan 2026) | M4: 31 Maret 2026 (Akhir Bulan) | O4: Perubahan | V4: TGL-ST 0 | W4: FFA ST 07 OLEIN
I5: FFA | K5: 0.059 | M5: =IFERROR(LOOKUP(2,1/('INPUT KUALITAS'!AP6:AP35<>""),'INPUT KUALITAS'!AP6:AP35),"-") -> 0.084 | O5: =IFERROR(IF(M5="-","-",TEXT(M5-0.059,"0.000")&" ("&IF(M5>0.059,"NAIK","TURUN")&")"),"-") -> 0.000 (NAIK) | V5: 01/Mar | W5: =IF('INPUT KUALITAS'!AP6="",NA(),'INPUT KUALITAS'!AP6) -> 0.083
I6: Moist | K6: 0.05 | M6: =IFERROR(LOOKUP(2,1/('INPUT KUALITAS'!AR6:AR35<>""),'INPUT KUALITAS'!AR6:AR35),"-") -> 0.07 | O6: =IFERROR(IF(M6="-","-",TEXT(ABS(M6-0.05),"0.00")&" (NAIK)"),"-") -> 000 (NAIK) | V6: 02/Mar | W6: =IF('INPUT KUALITAS'!AP7="",NA(),'INPUT KUALITAS'!AP7) -> 0.083
I7: Colour | K7: 2.1 | M7: =IFERROR(LOOKUP(2,1/('INPUT KUALITAS'!AQ6:AQ35<>""),'INPUT KUALITAS'!AQ6:AQ35),"-") -> 2.2R/22Y | O7: =IFERROR(IF(M7="-","-",TEXT(ABS(M7-2.1),"0.00")&" ()"),"-") -> - | V7: 03/Mar | W7: =IF('INPUT KUALITAS'!AP8="",NA(),'INPUT KUALITAS'!AP8) -> 0.083
I8: IV | K8: 56.21 | M8: =IFERROR(LOOKUP(2,1/('INPUT KUALITAS'!AS6:AS35<>""),'INPUT KUALITAS'!AS6:AS35),"-") -> 56.01 | O8: =IFERROR(IF(M8="-","-",TEXT(M8-56.21,"0.00")&" ("&IF(M8<56.21,"TURUN","NAIK")&")"),"-") -> 000 (TURUN) | V8: 04/Mar | W8: =IF('INPUT KUALITAS'!AP9="",NA(),'INPUT KUALITAS'!AP9) -> #N/A
I9: CP | K9: 9.8 | M9: =IFERROR(LOOKUP(2,1/('INPUT KUALITAS'!AT6:AT35<>""),'INPUT KUALITAS'!AT6:AT35),"-") -> 10 | O9: =IFERROR(IF(M9="-","-",TEXT(ABS(M9-9.8),"0.00")&" (NAIK)"),"-") -> 000 (NAIK) | V9: 05/Mar | W9: =IF('INPUT KUALITAS'!AP10="",NA(),'INPUT KUALITAS'!AP10) -> 0.083
A10: KESIMPULAN OTOMATIS | V10: 06/Mar | W10: =IF('INPUT KUALITAS'!AP11="",NA(),'INPUT KUALITAS'!AP11) -> 0.084
A11: =IFERROR("✅ FFA NAIK "&TEXT(ROUND((LOOKUP(2,1/('INPUT KUALITAS'!AP6:AP35<>""),'INPUT KUALITAS'!AP6:AP35)-LOOKUP(1,1/('INPUT KUALITAS'!AP6:AP35<>""),'INPUT KUALITAS'!AP6:AP35))/4,3),"0.000")&" SETIAP MINGGU (rata-rata selama Maret 2026)","Data belum cukup untuk menghitung laju FFA") -> ✅ FFA NAIK 0.000 SETIAP MINGGU (rata-rata selama Maret 2026) | V11: 07/Mar | W11: =IF('INPUT KUALITAS'!AP12="",NA(),'INPUT KUALITAS'!AP12) -> 0.084
A12: ✅ COLOR: Awal 2.1 → Akhir Bulan (lihat data). Tidak menunjukkan kenaikan signifikan selama penyimpanan. | V12: 08/Mar | W12: =IF('INPUT KUALITAS'!AP13="",NA(),'INPUT KUALITAS'!AP13) -> #N/A
A13: ℹ️ IV: Awal 56.21 → Perubahan minimal selama penyimpanan. CP: Awal 9.8°C → Pantau bila mendekati batas 10°C. | V13: 09/Mar | W13: =IF('INPUT KUALITAS'!AP14="",NA(),'INPUT KUALITAS'!AP14) -> #N/A
A14: 📝 Note: BE yang digunakan CLARIANT OPTIMUM | V14: 10/Mar | W14: =IF('INPUT KUALITAS'!AP15="",NA(),'INPUT KUALITAS'!AP15) -> #N/A
V15: 11/Mar | W15: =IF('INPUT KUALITAS'!AP16="",NA(),'INPUT KUALITAS'!AP16) -> #N/A
V16: 12/Mar | W16: =IF('INPUT KUALITAS'!AP17="",NA(),'INPUT KUALITAS'!AP17) -> #N/A
V17: 13/Mar | W17: =IF('INPUT KUALITAS'!AP18="",NA(),'INPUT KUALITAS'!AP18) -> #N/A
V18: 14/Mar | W18: =IF('INPUT KUALITAS'!AP19="",NA(),'INPUT KUALITAS'!AP19) -> #N/A
V19: 15/Mar | W19: =IF('INPUT KUALITAS'!AP20="",NA(),'INPUT KUALITAS'!AP20) -> #N/A
V20: 16/Mar | W20: =IF('INPUT KUALITAS'!AP21="",NA(),'INPUT KUALITAS'!AP21) -> #N/A
V21: 17/Mar | W21: =IF('INPUT KUALITAS'!AP22="",NA(),'INPUT KUALITAS'!AP22) -> #N/A
V22: 18/Mar | W22: =IF('INPUT KUALITAS'!AP23="",NA(),'INPUT KUALITAS'!AP23) -> #N/A
V23: 19/Mar | W23: =IF('INPUT KUALITAS'!AP24="",NA(),'INPUT KUALITAS'!AP24) -> #N/A
V24: 20/Mar | W24: =IF('INPUT KUALITAS'!AP25="",NA(),'INPUT KUALITAS'!AP25) -> #N/A
V25: 21/Mar | W25: =IF('INPUT KUALITAS'!AP26="",NA(),'INPUT KUALITAS'!AP26) -> #N/A
V26: 22/Mar | W26: =IF('INPUT KUALITAS'!AP27="",NA(),'INPUT KUALITAS'!AP27) -> #N/A
... V33: 29/Mar | W33: =IF('INPUT KUALITAS'!AP34="",NA(),'INPUT KUALITAS'!AP34) -> #N/A
A34: ST 08 OLEIN | 20 Jan 2026 s/d 23 Jan 2026 | Retensi: 67 hari | V34: 30/Mar | W34: =IF('INPUT KUALITAS'!AP35="",NA(),'INPUT KUALITAS'!AP35) -> #N/A
A35: ST 08 OLEIN Tonase : 390,600 kg Awal Filling : 20 Jan 2026 Akhir Filling: 23 Jan 2026 As of : 31 Maret 2026 | I35: PARAMETER | K35: Awal (23 Jan 2026) | M35: 31 Maret 2026 (Akhir Bulan) | O35: Perubahan | V35: TGL-ST 0 | W35: FFA ST 08 OLEIN
I36: FFA | K36: 0.051 | M36: =IFERROR(LOOKUP(2,1/('INPUT KUALITAS'!AV6:AV35<>""),'INPUT KUALITAS'!AV6:AV35),"-") -> 0.076 | O36: =IFERROR(IF(M36="-","-",TEXT(M36-0.051,"0.000")&" ("&IF(M36>0.051,"NAIK","TURUN")&")"),"-") -> 0.000 (NAIK) | V36: 01/Mar | W36: =IF('INPUT KUALITAS'!AV6="",NA(),'INPUT KUALITAS'!AV6) -> 0.072
I37: Moist | K37: 0.04 | M37: =IFERROR(LOOKUP(2,1/('INPUT KUALITAS'!AX6:AX35<>""),'INPUT KUALITAS'!AX6:AX35),"-") -> 0.07 | O37: =IFERROR(IF(M37="-","-",TEXT(ABS(M37-0.04),"0.00")&" (NAIK)"),"-") -> 000 (NAIK) | V37: 02/Mar | W37: =IF('INPUT KUALITAS'!AV7="",NA(),'INPUT KUALITAS'!AV7) -> 0.072
I38: Colour | K38: 2.1 | M38: =IFERROR(LOOKUP(2,1/('INPUT KUALITAS'!AW6:AW35<>""),'INPUT KUALITAS'!AW6:AW35),"-") -> 2.1R/21Y | O38: =IFERROR(IF(M38="-","-",TEXT(ABS(M38-2.1),"0.00")&" ()"),"-") -> - | V38: 03/Mar | W38: =IF('INPUT KUALITAS'!AV8="",NA(),'INPUT KUALITAS'!AV8) -> 0.072
I39: IV | K39: 57.85 | M39: =IFERROR(LOOKUP(2,1/('INPUT KUALITAS'!AY6:AY35<>""),'INPUT KUALITAS'!AY6:AY35),"-") -> 57.65 | O39: =IFERROR(IF(M39="-","-",TEXT(M39-57.85,"0.00")&" ("&IF(M39<57.85,"TURUN","NAIK")&")"),"-") -> 000 (TURUN) | V39: 04/Mar | W39: =IF('INPUT KUALITAS'!AV9="",NA(),'INPUT KUALITAS'!AV9) -> #N/A
I40: CP | K40: 8.8 | M40: =IFERROR(LOOKUP(2,1/('INPUT KUALITAS'!AZ6:AZ35<>""),'INPUT KUALITAS'!AZ6:AZ35),"-") -> 9 | O40: =IFERROR(IF(M40="-","-",TEXT(ABS(M40-8.8),"0.00")&" (NAIK)"),"-") -> 000 (NAIK) | V40: 05/Mar | W40: =IF('INPUT KUALITAS'!AV10="",NA(),'INPUT KUALITAS'!AV10) -> 0.076
A41: KESIMPULAN OTOMATIS | V41: 06/Mar | W41: =IF('INPUT KUALITAS'!AV11="",NA(),'INPUT KUALITAS'!AV11) -> 0.076
A42: =IFERROR("✅ FFA NAIK "&TEXT(ROUND((LOOKUP(2,1/('INPUT KUALITAS'!AV6:AV35<>""),'INPUT KUALITAS'!AV6:AV35)-LOOKUP(1,1/('INPUT KUALITAS'!AV6:AV35<>""),'INPUT KUALITAS'!AV6:AV35))/4,3),"0.000")&" SETIAP MINGGU (rata-rata selama Maret 2026)","Data belum cukup untuk menghitung laju FFA") -> ✅ FFA NAIK 0.000 SETIAP MINGGU (rata-rata selama Maret 2026) | V42: 07/Mar | W42: =IF('INPUT KUALITAS'!AV12="",NA(),'INPUT KUALITAS'!AV12) -> 0.076
A43: ✅ COLOR: Awal 2.1 → Akhir Bulan (lihat data). Tidak menunjukkan kenaikan signifikan selama penyimpanan. | V43: 08/Mar | W43: =IF('INPUT KUALITAS'!AV13="",NA(),'INPUT KUALITAS'!AV13) -> #N/A
A44: ℹ️ IV: Awal 57.85 → Perubahan minimal selama penyimpanan. CP: Awal 8.8°C → Pantau bila mendekati batas 10°C. | V44: 09/Mar | W44: =IF('INPUT KUALITAS'!AV14="",NA(),'INPUT KUALITAS'!AV14) -> #N/A
A45: 📝 Note: BE yang digunakan CLARIANT OPTIMUM | V45: 10/Mar | W45: =IF('INPUT KUALITAS'!AV15="",NA(),'INPUT KUALITAS'!AV15) -> #N/A
V46: 11/Mar | W46: =IF('INPUT KUALITAS'!AV16="",NA(),'INPUT KUALITAS'!AV16) -> #N/A
...

Sheet MUTASI STOK
A1: MUTASI STOK HARIAN - SEMUA TANGKI - MARET 2026
A2: Kolom BIRU = Input manual | Kolom KUNING = No DO (input) | Kolom PINK = Tujuan/Pembeli (input) | Kolom HIJAU = Sisa Stok (otomatis)
A3: TANGGAL | B3: CPO ST01 | L3: CPO ST02 | V3: CPO ST03 | AF3: PFAD ST04 | AM3: Stearin ST05 | AT3: Stearin ST06 | BA3: Olein ST07 | BK3: Olein ST08 | BU3: Olein ST09 | CE3: Olein ST10 | CO3: Olein ST11 | CY3: RBDPO ST13 | DF3: RBDPO ST14 | DM3: Buffer 2
B4: Stok Awal (kg) | C4: Masuk (kg) | D4: No DO Masuk | E4: Keluar (kg) | F4: No DO Keluar | G4: Tujuan / Pembeli | H4: Keluar 2 (kg) | I4: No DO Keluar 2 | J4: Tujuan 2 / Pembeli 2 | K4: Sisa Stok (kg) | L4: Stok Awal (kg) | M4: Masuk (kg) | N4: No DO Masuk | O4: Keluar (kg) | P4: No DO Keluar | Q4: Tujuan / Pembeli | R4: Keluar 2 (kg) | S4: No DO Keluar 2 | T4: Tujuan 2 / Pembeli 2 | U4: Sisa Stok (kg) | V4: Stok Awal (kg) | W4: Masuk (kg) | X4: No DO Masuk | Y4: Keluar (kg) | Z4: No DO Keluar | AA4: Tujuan / Pembeli | AB4: Keluar 2 (kg) | AC4: No DO Keluar 2 | AD4: Tujuan 2 / Pembeli 2 | AE4: Sisa Stok (kg) | AF4: Stok Awal (kg) | AG4: Masuk (kg) | AH4: No DO Masuk | AI4: Keluar (kg) | AJ4: No DO Keluar | AK4: Tujuan / Pembeli | AL4: Sisa Stok (kg) | AM4: Stok Awal (kg) | AN4: Masuk (kg) | AO4: No DO Masuk | AP4: Keluar (kg) | AQ4: No DO Keluar | AR4: Tujuan / Pembeli | AS4: Sisa Stok (kg) | AT4: Stok Awal (kg) | AU4: Masuk (kg) | AV4: No DO Masuk | AW4: Keluar (kg) | AX4: No DO Keluar | AY4: Tujuan / Pembeli | AZ4: Sisa Stok (kg) | BA4: Stok Awal (kg) | BB4: Masuk (kg) | BC4: No DO Masuk | BD4: Keluar (kg) | BE4: No DO Keluar | BF4: Tujuan / Pembeli | BG4: Keluar 2 (kg) | BH4: No DO Keluar 2 | BI4: Tujuan 2 / Pembeli 2 | BJ4: Sisa Stok (kg) | BK4: Stok Awal (kg) | BL4: Masuk (kg) | BM4: No DO Masuk | BN4: Keluar (kg) | BO4: No DO Keluar | BP4: Tujuan / Pembeli | BQ4: Keluar 2 (kg) | BR4: No DO Keluar 2 | BS4: Tujuan 2 / Pembeli 2 | BT4: Sisa Stok (kg) | BU4: Stok Awal (kg) | BV4: Masuk (kg) | BW4: No DO Masuk | BX4: Keluar (kg) | BY4: No DO Keluar | BZ4: Tujuan / Pembeli | CA4: Keluar 2 (kg) | CB4: No DO Keluar 2 | CC4: Tujuan 2 / Pembeli 2 | CD4: Sisa Stok (kg) | CE4: Stok Awal (kg) | CF4: Masuk (kg) | CG4: No DO Masuk | CH4: Keluar (kg) | CI4: No DO Keluar | CJ4: Tujuan / Pembeli | CK4: Keluar 2 (kg) | CL4: No DO Keluar 2 | CM4: Tujuan 2 / Pembeli 2 | CN4: Sisa Stok (kg) | CO4: Stok Awal (kg) | CP4: Masuk (kg) | CQ4: No DO Masuk | CR4: Keluar (kg) | CS4: No DO Keluar | CT4: Tujuan / Pembeli | CU4: Keluar 2 (kg) | CV4: No DO Keluar 2 | CW4: Tujuan 2 / Pembeli 2 | CX4: Sisa Stok (kg) | CY4: Stok Awal (kg) | CZ4: Masuk (kg) | DA4: No DO Masuk | DB4: Keluar (kg) | DC4: No DO Keluar | DD4: Tujuan / Pembeli | DE4: Sisa Stok (kg) | DF4: Stok Awal (kg) | DG4: Masuk (kg) | DH4: No DO Masuk | DI4: Keluar (kg) | DJ4: No DO Keluar | DK4: Tujuan / Pembeli | DL4: Sisa Stok (kg) | DM4: Stok Awal (kg) | DN4: Masuk (kg) | DO4: No DO Masuk | DP4: Keluar (kg) | DQ4: No DO Keluar | DR4: Tujuan / Pembeli | DS4: Sisa Stok (kg)
A5: 01 Mar (Min) | B5: 2506149 | K5: =IF(B5="","",IF(AND(C5="",E5="",H5=""),B5,B5+IF(C5="",0,C5)-IF(E5="",0,E5)-IF(H5="",0,H5))) -> 2506149 | L5: 2577692 | U5: =IF(L5="","",IF(AND(M5="",O5="",R5=""),L5,L5+IF(M5="",0,M5)-IF(O5="",0,O5)-IF(R5="",0,R5))) -> 2577692 | V5: 2443036 | AE5: =IF(V5="","",IF(AND(W5="",Y5="",AB5=""),V5,V5+IF(W5="",0,W5)-IF(Y5="",0,Y5)-IF(AB5="",0,AB5))) -> 2443036 | AF5: 328064 | AL5: =IF(AF5="","",IF(AND(AG5="",AI5=""),AF5,AF5+IF(AG5="",0,AG5)-IF(AI5="",0,AI5))) -> 328064 | AM5: 529521 | AS5: =IF(AM5="","",IF(AND(AN5="",AP5=""),AM5,AM5+IF(AN5="",0,AN5)-IF(AP5="",0,AP5))) -> 529521 | AT5: 44014 | AZ5: =IF(AT5="","",IF(AND(AU5="",AW5=""),AT5,AT5+IF(AU5="",0,AU5)-IF(AW5="",0,AW5))) -> 44014 | BA5: 536860 | BJ5: =IF(BA5="","",IF(AND(BB5="",BD5="",BG5=""),BA5,BA5+IF(BB5="",0,BB5)-IF(BD5="",0,BD5)-IF(BG5="",0,BG5))) -> 536860 | BK5: 390600 | BN5: 36750 | BP5: Bukit Jejer Lestari/Palu | BT5: =IF(BK5="","",IF(AND(BL5="",BN5="",BQ5=""),BK5,BK5+IF(BL5="",0,BL5)-IF(BN5="",0,BN5)-IF(BQ5="",0,BQ5))) -> 353850 | BU5: 508583 | CD5: =IF(BU5="","",IF(AND(BV5="",BX5="",CA5=""),BU5,BU5+IF(BV5="",0,BV5)-IF(BX5="",0,BX5)-IF(CA5="",0,CA5))) -> 508583 | CE5: 510730 | CN5: =IF(CE5="","",IF(AND(CF5="",CH5="",CK5=""),CE5,CE5+IF(CF5="",0,CF5)-IF(CH5="",0,CH5)-IF(CK5="",0,CK5))) -> 510730 | CO5: 26023 | CX5: =IF(CO5="","",IF(AND(CP5="",CR5="",CU5=""),CO5,CO5+IF(CP5="",0,CP5)-IF(CR5="",0,CR5)-IF(CU5="",0,CU5))) -> 26023 | CY5: 1164563 | DE5: =IF(CY5="","",IF(AND(CZ5="",DB5=""),CY5,CY5+IF(CZ5="",0,CZ5)-IF(DB5="",0,DB5))) -> 1164563 | DF5: 961820 | DL5: =IF(DF5="","",IF(AND(DG5="",DI5=""),DF5,DF5+IF(DG5="",0,DG5)-IF(DI5="",0,DI5))) -> 961820 | DM5: 32951 | DS5: =IF(DM5="","",IF(AND(DN5="",DP5=""),DM5,DM5+IF(DN5="",0,DN5)-IF(DP5="",0,DP5))) -> 32951
A6: 02 Mar (Sen) | B6: =K5 -> 2506149 | K6: =IF(B6="","",IF(AND(C6="",E6="",H6=""),B6,B6+IF(C6="",0,C6)-IF(E6="",0,E6)-IF(H6="",0,H6))) -> 2506149 | L6: =U5 -> 2577692 | U6: =IF(L6="","",IF(AND(M6="",O6="",R6=""),L6,L6+IF(M6="",0,M6)-IF(O6="",0,O6)-IF(R6="",0,R6))) -> 2577692 | V6: =AE5 -> 2443036 | AE6: =IF(V6="","",IF(AND(W6="",Y6="",AB6=""),V6,V6+IF(W6="",0,W6)-IF(Y6="",0,Y6)-IF(AB6="",0,AB6))) -> 2443036 | AF6: =AL5 -> 328064 | AL6: =IF(AF6="","",IF(AND(AG6="",AI6=""),AF6,AF6+IF(AG6="",0,AG6)-IF(AI6="",0,AI6))) -> 328064 | AM6: =AS5 -> 529521 | AS6: =IF(AM6="","",IF(AND(AN6="",AP6=""),AM6,AM6+IF(AN6="",0,AN6)-IF(AP6="",0,AP6))) -> 529521 | AT6: =AZ5 -> 44014 | AZ6: =IF(AT6="","",IF(AND(AU6="",AW6=""),AT6,AT6+IF(AU6="",0,AU6)-IF(AW6="",0,AW6))) -> 44014 | BA6: =BJ5 -> 536860 | BJ6: =IF(BA6="","",IF(AND(BB6="",BD6="",BG6=""),BA6,BA6+IF(BB6="",0,BB6)-IF(BD6="",0,BD6)-IF(BG6="",0,BG6))) -> 536860 | BK6: =BT5 -> 353850 | BT6: =IF(BK6="","",IF(AND(BL6="",BN6="",BQ6=""),BK6,BK6+IF(BL6="",0,BL6)-IF(BN6="",0,BN6)-IF(BQ6="",0,BQ6))) -> 353850 | BU6: =CD5 -> 508583 | CD6: =IF(BU6="","",IF(AND(BV6="",BX6="",CA6=""),BU6,BU6+IF(BV6="",0,BV6)-IF(BX6="",0,BX6)-IF(CA6="",0,CA6))) -> 508583 | CE6: =CN5 -> 510730 | CN6: =IF(CE6="","",IF(AND(CF6="",CH6="",CK6=""),CE6,CE6+IF(CF6="",0,CF6)-IF(CH6="",0,CH6)-IF(CK6="",0,CK6))) -> 510730 | CO6: =CX5 -> 26023 | CX6: =IF(CO6="","",IF(AND(CP6="",CR6="",CU6=""),CO6,CO6+IF(CP6="",0,CP6)-IF(CR6="",0,CR6)-IF(CU6="",0,CU6))) -> 26023 | CY6: =DE5 -> 1164563 | DE6: =IF(CY6="","",IF(AND(CZ6="",DB6=""),CY6,CY6+IF(CZ6="",0,CZ6)-IF(DB6="",0,DB6))) -> 1164563 | DF6: =DL5 -> 961820 | DL6: =IF(DF6="","",IF(AND(DG6="",DI6=""),DF6,DF6+IF(DG6="",0,DG6)-IF(DI6="",0,DI6))) -> 961820 | DM6: =DS5 -> 32951 | DS6: =IF(DM6="","",IF(AND(DN6="",DP6=""),DM6,DM6+IF(DN6="",0,DN6)-IF(DP6="",0,DP6))) -> 32951
A7: 03 Mar (Sel) | B7: =K6 -> 2506149 | K7: =IF(B7="","",IF(AND(C7="",E7="",H7=""),B7,B7+IF(C7="",0,C7)-IF(E7="",0,E7)-IF(H7="",0,H7))) -> 2506149 | L7: =U6 -> 2577692 | U7: =IF(L7="","",IF(AND(M7="",O7="",R7=""),L7,L7+IF(M7="",0,M7)-IF(O7="",0,O7)-IF(R7="",0,R7))) -> 2577692 | V7: =AE6 -> 2443036 | AE7: =IF(V7="","",IF(AND(W7="",Y7="",AB7=""),V7,V7+IF(W7="",0,W7)-IF(Y7="",0,Y7)-IF(AB7="",0,AB7))) -> 2443036 | AF7: =AL6 -> 328064 | AL7: =IF(AF7="","",IF(AND(AG7="",AI7=""),AF7,AF7+IF(AG7="",0,AG7)-IF(AI7="",0,AI7))) -> 328064 | AM7: =AS6 -> 529521 | AS7: =IF(AM7="","",IF(AND(AN7="",AP7=""),AM7,AM7+IF(AN7="",0,AN7)-IF(AP7="",0,AP7))) -> 529521 | AT7: =AZ6 -> 44014 | AZ7: =IF(AT7="","",IF(AND(AU7="",AW7=""),AT7,AT7+IF(AU7="",0,AU7)-IF(AW7="",0,AW7))) -> 44014 | BA7: =BJ6 -> 536860 | BJ7: =IF(BA7="","",IF(AND(BB7="",BD7="",BG7=""),BA7,BA7+IF(BB7="",0,BB7)-IF(BD7="",0,BD7)-IF(BG7="",0,BG7))) -> 536860 | BK7: =BT6 -> 353850 | BT7: =IF(BK7="","",IF(AND(BL7="",BN7="",BQ7=""),BK7,BK7+IF(BL7="",0,BL7)-IF(BN7="",0,BN7)-IF(BQ7="",0,BQ7))) -> 353850 | BU7: =CD6 -> 508583 | CD7: =IF(BU7="","",IF(AND(BV7="",BX7="",CA7=""),BU7,BU7+IF(BV7="",0,BV7)-IF(BX7="",0,BX7)-IF(CA7="",0,CA7))) -> 508583 | CE7: =CN6 -> 510730 | CN7: =IF(CE7="","",IF(AND(CF7="",CH7="",CK7=""),CE7,CE7+IF(CF7="",0,CF7)-IF(CH7="",0,CH7)-IF(CK7="",0,CK7))) -> 510730 | CO7: =CX6 -> 26023 | CX7: =IF(CO7="","",IF(AND(CP7="",CR7="",CU7=""),CO7,CO7+IF(CP7="",0,CP7)-IF(CR7="",0,CR7)-IF(CU7="",0,CU7))) -> 26023 | CY7: =DE6 -> 1164563 | DE7: =IF(CY7="","",IF(AND(CZ7="",DB7=""),CY7,CY7+IF(CZ7="",0,CZ7)-IF(DB7="",0,DB7))) -> 1164563 | DF7: =DL6 -> 961820 | DL7: =IF(DF7="","",IF(AND(DG7="",DI7=""),DF7,DF7+IF(DG7="",0,DG7)-IF(DI7="",0,DI7))) -> 961820 | DM7: =DS6 -> 32951 | DS7: =IF(DM7="","",IF(AND(DN7="",DP7=""),DM7,DM7+IF(DN7="",0,DN7)-IF(DP7="",0,DP7))) -> 32951
A8: 04 Mar (Rab) | B8: =K7 -> 2506149 | K8: =IF(B8="","",IF(AND(C8="",E8="",H8=""),B8,B8+IF(C8="",0,C8)-IF(E8="",0,E8)-IF(H8="",0,H8))) -> 2506149 | L8: =U7 -> 2577692 | U8: =IF(L8="","",IF(AND(M8="",O8="",R8=""),L8,L8+IF(M8="",0,M8)-IF(O8="",0,O8)-IF(R8="",0,R8))) -> 2577692 | V8: =AE7 -> 2443036 | AE8: =IF(V8="","",IF(AND(W8="",Y8="",AB8=""),V8,V8+IF(W8="",0,W8)-IF(Y8="",0,Y8)-IF(AB8="",0,AB8))) -> 2443036 | AF8: =AL7 -> 328064 | AL8: =IF(AF8="","",IF(AND(AG8="",AI8=""),AF8,AF8+IF(AG8="",0,AG8)-IF(AI8="",0,AI8))) -> 328064 | AM8: =AS7 -> 529521 | AS8: =IF(AM8="","",IF(AND(AN8="",AP8=""),AM8,AM8+IF(AN8="",0,AN8)-IF(AP8="",0,AP8))) -> 529521 | AT8: =AZ7 -> 44014 | AZ8: =IF(AT8="","",IF(AND(AU8="",AW8=""),AT8,AT8+IF(AU8="",0,AU8)-IF(AW8="",0,AW8))) -> 44014 | BA8: =BJ7 -> 536860 | BJ8: =IF(BA8="","",IF(AND(BB8="",BD8="",BG8=""),BA8,BA8+IF(BB8="",0,BB8)-IF(BD8="",0,BD8)-IF(BG8="",0,BG8))) -> 536860 | BK8: =BT7 -> 353850 | BT8: =IF(BK8="","",IF(AND(BL8="",BN8="",BQ8=""),BK8,BK8+IF(BL8="",0,BL8)-IF(BN8="",0,BN8)-IF(BQ8="",0,BQ8))) -> 353850 | BU8: =CD7 -> 508583 | CD8: =IF(BU8="","",IF(AND(BV8="",BX8="",CA8=""),BU8,BU8+IF(BV8="",0,BV8)-IF(BX8="",0,BX8)-IF(CA8="",0,CA8))) -> 508583 | CE8: =CN7 -> 510730 | CN8: =IF(CE8="","",IF(AND(CF8="",CH8="",CK8=""),CE8,CE8+IF(CF8="",0,CF8)-IF(CH8="",0,CH8)-IF(CK8="",0,CK8))) -> 510730 | CO8: =CX7 -> 26023 | CX8: =IF(CO8="","",IF(AND(CP8="",CR8="",CU8=""),CO8,CO8+IF(CP8="",0,CP8)-IF(CR8="",0,CR8)-IF(CU8="",0,CU8))) -> 26023 | CY8: =DE7 -> 1164563 | DE8: =IF(CY8="","",IF(AND(CZ8="",DB8=""),CY8,CY8+IF(CZ8="",0,CZ8)-IF(DB8="",0,DB8))) -> 1164563 | DF8: =DL7 -> 961820 | DL8: =IF(DF8="","",IF(AND(DG8="",DI8=""),DF8,DF8+IF(DG8="",0,DG8)-IF(DI8="",0,DI8))) -> 961820 | DM8: =DS7 -> 32951 | DS8: =IF(DM8="","",IF(AND(DN8="",DP8=""),DM8,DM8+IF(DN8="",0,DN8)-IF(DP8="",0,DP8))) -> 32951
A9: 05 Mar (Kam) | B9: =K8 -> 2506149 | K9: =IF(B9="","",IF(AND(C9="",E9="",H9=""),B9,B9+IF(C9="",0,C9)-IF(E9="",0,E9)-IF(H9="",0,H9))) -> 2506149 | L9: =U8 -> 2577692 | U9: =IF(L9="","",IF(AND(M9="",O9="",R9=""),L9,L9+IF(M9="",0,M9)-IF(O9="",0,O9)-IF(R9="",0,R9))) -> 2577692 | V9: =AE8 -> 2443036 | AE9: =IF(V9="","",IF(AND(W9="",Y9="",AB9=""),V9,V9+IF(W9="",0,W9)-IF(Y9="",0,Y9)-IF(AB9="",0,AB9))) -> 2443036 | AF9: =AL8 -> 328064 | AL9: =IF(AF9="","",IF(AND(AG9="",AI9=""),AF9,AF9+IF(AG9="",0,AG9)-IF(AI9="",0,AI9))) -> 328064 | AM9: =AS8 -> 529521 | AS9: =IF(AM9="","",IF(AND(AN9="",AP9=""),AM9,AM9+IF(AN9="",0,AN9)-IF(AP9="",0,AP9))) -> 529521 | AT9: =AZ8 -> 44014 | AZ9: =IF(AT9="","",IF(AND(AU9="",AW9=""),AT9,AT9+IF(AU9="",0,AU9)-IF(AW9="",0,AW9))) -> 44014 | BA9: =BJ8 -> 536860 | BJ9: =IF(BA9="","",IF(AND(BB9="",BD9="",BG9=""),BA9,BA9+IF(BB9="",0,BB9)-IF(BD9="",0,BD9)-IF(BG9="",0,BG9))) -> 536860 | BK9: =BT8 -> 353850 | BN9: 9060 | BP9: Bukit Jejer Lestari/Palu | BT9: =IF(BK9="","",IF(AND(BL9="",BN9="",BQ9=""),BK9,BK9+IF(BL9="",0,BL9)-IF(BN9="",0,BN9)-IF(BQ9="",0,BQ9))) -> 344790 | BU9: =CD8 -> 508583 | CD9: =IF(BU9="","",IF(AND(BV9="",BX9="",CA9=""),BU9,BU9+IF(BV9="",0,BV9)-IF(BX9="",0,BX9)-IF(CA9="",0,CA9))) -> 508583 | CE9: =CN8 -> 510730 | CN9: =IF(CE9="","",IF(AND(CF9="",CH9="",CK9=""),CE9,CE9+IF(CF9="",0,CF9)-IF(CH9="",0,CH9)-IF(CK9="",0,CK9))) -> 510730 | CO9: =CX8 -> 26023 | CX9: =IF(CO9="","",IF(AND(CP9="",CR9="",CU9=""),CO9,CO9+IF(CP9="",0,CP9)-IF(CR9="",0,CR9)-IF(CU9="",0,CU9))) -> 26023 | CY9: =DE8 -> 1164563 | DE9: =IF(CY9="","",IF(AND(CZ9="",DB9=""),CY9,CY9+IF(CZ9="",0,CZ9)-IF(DB9="",0,DB9))) -> 1164563 | DF9: =DL8 -> 961820 | DL9: =IF(DF9="","",IF(AND(DG9="",DI9=""),DF9,DF9+IF(DG9="",0,DG9)-IF(DI9="",0,DI9))) -> 961820 | DM9: =DS8 -> 32951 | DS9: =IF(DM9="","",IF(AND(DN9="",DP9=""),DM9,DM9+IF(DN9="",0,DN9)-IF(DP9="",0,DP9))) -> 32951
A10: 06 Mar (Jum) | B10: =K9 -> 2506149 | K10: =IF(B10="","",IF(AND(C10="",E10="",H10=""),B10,B10+IF(C10="",0,C10)-IF(E10="",0,E10)-IF(H10="",0,H10))) -> 2506149 | L10: =U9 -> 2577692 | U10: =IF(L10="","",IF(AND(M10="",O10="",R10=""),L10,L10+IF(M10="",0,M10)-IF(O10="",0,O10)-IF(R10="",0,R10))) -> 2577692 | V10: =AE9 -> 2443036 | AE10: =IF(V10="","",IF(AND(W10="",Y10="",AB10=""),V10,V10+IF(W10="",0,W10)-IF(Y10="",0,Y10)-IF(AB10="",0,AB10))) -> 2443036 | AF10: =AL9 -> 328064 | AL10: =IF(AF10="","",IF(AND(AG10="",AI10=""),AF10,AF10+IF(AG10="",0,AG10)-IF(AI10="",0,AI10))) -> 328064 | AM10: =AS9 -> 529521 | AS10: =IF(AM10="","",IF(AND(AN10="",AP10=""),AM10,AM10+IF(AN10="",0,AN10)-IF(AP10="",0,AP10))) -> 529521 | AT10: =AZ9 -> 44014 | AZ10: =IF(AT10="","",IF(AND(AU10="",AW10=""),AT10,AT10+IF(AU10="",0,AU10)-IF(AW10="",0,AW10))) -> 44014 | BA10: =BJ9 -> 536860 | BJ10: =IF(BA10="","",IF(AND(BB10="",BD10="",BG10=""),BA10,BA10+IF(BB10="",0,BB10)-IF(BD10="",0,BD10)-IF(BG10="",0,BG10))) -> 536860 | BK10: =BT9 -> 344790 | BN10: 18240 | BP10: Bukit Jejer Lestari/Palu | BQ10: 48150 | BS10: Halilintar Sakti Abadi/UPG | BT10: =IF(BK10="","",IF(AND(BL10="",BN10="",BQ10=""),BK10,BK10+IF(BL10="",0,BL10)-IF(BN10="",0,BN10)-IF(BQ10="",0,BQ10))) -> 278400 | BU10: =CD9 -> 508583 | CD10: =IF(BU10="","",IF(AND(BV10="",BX10="",CA10=""),BU10,BU10+IF(BV10="",0,BV10)-IF(BX10="",0,BX10)-IF(CA10="",0,CA10))) -> 508583 | CE10: =CN9 -> 510730 | CN10: =IF(CE10="","",IF(AND(CF10="",CH10="",CK10=""),CE10,CE10+IF(CF10="",0,CF10)-IF(CH10="",0,CH10)-IF(CK10="",0,CK10))) -> 510730 | CO10: =CX9 -> 26023 | CX10: =IF(CO10="","",IF(AND(CP10="",CR10="",CU10=""),CO10,CO10+IF(CP10="",0,CP10)-IF(CR10="",0,CR10)-IF(CU10="",0,CU10))) -> 26023 | CY10: =DE9 -> 1164563 | DE10: =IF(CY10="","",IF(AND(CZ10="",DB10=""),CY10,CY10+IF(CZ10="",0,CZ10)-IF(DB10="",0,DB10))) -> 1164563 | DF10: =DL9 -> 961820 | DL10: =IF(DF10="","",IF(AND(DG10="",DI10=""),DF10,DF10+IF(DG10="",0,DG10)-IF(DI10="",0,DI10))) -> 961820 | DM10: =DS9 -> 32951 | DS10: =IF(DM10="","",IF(AND(DN10="",DP10=""),DM10,DM10+IF(DN10="",0,DN10)-IF(DP10="",0,DP10))) -> 32951
A11: 07 Mar (Sab) | B11: =K10 -> 2506149 | K11: =IF(B11="","",IF(AND(C11="",E11="",H11=""),B11,B11+IF(C11="",0,C11)-IF(E11="",0,E11)-IF(H11="",0,H11))) -> 2506149 | L11: =U10 -> 2577692 | U11: =IF(L11="","",IF(AND(M11="",O11="",R11=""),L11,L11+IF(M11="",0,M11)-IF(O11="",0,O11)-IF(R11="",0,R11))) -> 2577692 | V11: =AE10 -> 2443036 | AE11: =IF(V11="","",IF(AND(W11="",Y11="",AB11=""),V11,V11+IF(W11="",0,W11)-IF(Y11="",0,Y11)-IF(AB11="",0,AB11))) -> 2443036 | AF11: =AL10 -> 328064 | AL11: =IF(AF11="","",IF(AND(AG11="",AI11=""),AF11,AF11+IF(AG11="",0,AG11)-IF(AI11="",0,AI11))) -> 328064 | AM11: =AS10 -> 529521 | AS11: =IF(AM11="","",IF(AND(AN11="",AP11=""),AM11,AM11+IF(AN11="",0,AN11)-IF(AP11="",0,AP11))) -> 529521 | AT11: =AZ10 -> 44014 | AZ11: =IF(AT11="","",IF(AND(AU11="",AW11=""),AT11,AT11+IF(AU11="",0,AU11)-IF(AW11="",0,AW11))) -> 44014 | BA11: =BJ10 -> 536860 | BJ11: =IF(BA11="","",IF(AND(BB11="",BD11="",BG11=""),BA11,BA11+IF(BB11="",0,BB11)-IF(BD11="",0,BD11)-IF(BG11="",0,BG11))) -> 536860 | BK11: =BT10 -> 278400 | BT11: =IF(BK11="","",IF(AND(BL11="",BN11="",BQ11=""),BK11,BK11+IF(BL11="",0,BL11)-IF(BN11="",0,BN11)-IF(BQ11="",0,BQ11))) -> 278400 | BU11: =CD10 -> 508583 | CD11: =IF(BU11="","",IF(AND(BV11="",BX11="",CA11=""),BU11,BU11+IF(BV11="",0,BV11)-IF(BX11="",0,BX11)-IF(CA11="",0,CA11))) -> 508583 | CE11: =CN10 -> 510730 | CN11: =IF(CE11="","",IF(AND(CF11="",CH11="",CK11=""),CE11,CE11+IF(CF11="",0,CF11)-IF(CH11="",0,CH11)-IF(CK11="",0,CK11))) -> 510730 | CO11: =CX10 -> 26023 | CX11: =IF(CO11="","",IF(AND(CP11="",CR11="",CU11=""),CO11,CO11+IF(CP11="",0,CP11)-IF(CR11="",0,CR11)-IF(CU11="",0,CU11))) -> 26023 | CY11: =DE10 -> 1164563 | DE11: =IF(CY11="","",IF(AND(CZ11="",DB11=""),CY11,CY11+IF(CZ11="",0,CZ11)-IF(DB11="",0,DB11))) -> 1164563 | DF11: =DL10 -> 961820 | DL11: =IF(DF11="","",IF(AND(DG11="",DI11=""),DF11,DF11+IF(DG11="",0,DG11)-IF(DI11="",0,DI11))) -> 961820 | DM11: =DS10 -> 32951 | DS11: =IF(DM11="","",IF(AND(DN11="",DP11=""),DM11,DM11+IF(DN11="",0,DN11)-IF(DP11="",0,DP11))) -> 32951
A12: 08 Mar (Min) | B12: =K11 -> 2506149 | K12: =IF(B12="","",IF(AND(C12="",E12="",H12=""),B12,B12+IF(C12="",0,C12)-IF(E12="",0,E12)-IF(H12="",0,H12))) -> 2506149 | L12: =U11 -> 2577692 | U12: =IF(L12="","",IF(AND(M12="",O12="",R12=""),L12,L12+IF(M12="",0,M12)-IF(O12="",0,O12)-IF(R12="",0,R12))) -> 2577692 | V12: =AE11 -> 2443036 | AE12: =IF(V12="","",IF(AND(W12="",Y12="",AB12=""),V12,V12+IF(W12="",0,W12)-IF(Y12="",0,Y12)-IF(AB12="",0,AB12))) -> 2443036 | AF12: =AL11 -> 328064 | AL12: =IF(AF12="","",IF(AND(AG12="",AI12=""),AF12,AF12+IF(AG12="",0,AG12)-IF(AI12="",0,AI12))) -> 328064 | AM12: =AS11 -> 529521 | AS12: =IF(AM12="","",IF(AND(AN12="",AP12=""),AM12,AM12+IF(AN12="",0,AN12)-IF(AP12="",0,AP12))) -> 529521 | AT12: =AZ11 -> 44014 | AZ12: =IF(AT12="","",IF(AND(AU12="",AW12=""),AT12,AT12+IF(AU12="",0,AU12)-IF(AW12="",0,AW12))) -> 44014 | BA12: =BJ11 -> 536860 | BJ12: =IF(BA12="","",IF(AND(BB12="",BD12="",BG12=""),BA12,BA12+IF(BB12="",0,BB12)-IF(BD12="",0,BD12)-IF(BG12="",0,BG12))) -> 536860 | BK12: =BT11 -> 278400 | BT12: =IF(BK12="","",IF(AND(BL12="",BN12="",BQ12=""),BK12,BK12+IF(BL12="",0,BL12)-IF(BN12="",0,BN12)-IF(BQ12="",0,BQ12))) -> 278400 | BU12: =CD11 -> 508583 | CD12: =IF(BU12="","",IF(AND(BV12="",BX12="",CA12=""),BU12,BU12+IF(BV12="",0,BV12)-IF(BX12="",0,BX12)-IF(CA12="",0,CA12))) -> 508583 | CE12: =CN11 -> 510730 | CN12: =IF(CE12="","",IF(AND(CF12="",CH12="",CK12=""),CE12,CE12+IF(CF12="",0,CF12)-IF(CH12="",0,CH12)-IF(CK12="",0,CK12))) -> 510730 | CO12: =CX11 -> 26023 | CX12: =IF(CO12="","",IF(AND(CP12="",CR12="",CU12=""),CO12,CO12+IF(CP12="",0,CP12)-IF(CR12="",0,CR12)-IF(CU12="",0,CU12))) -> 26023 | CY12: =DE11 -> 1164563 | DE12: =IF(CY12="","",IF(AND(CZ12="",DB12=""),CY12,CY12+IF(CZ12="",0,CZ12)-IF(DB12="",0,DB12))) -> 1164563 | DF12: =DL11 -> 961820 | DL12: =IF(DF12="","",IF(AND(DG12="",DI12=""),DF12,DF12+IF(DG12="",0,DG12)-IF(DI12="",0,DI12))) -> 961820 | DM12: =DS11 -> 32951 | DS12: =IF(DM12="","",IF(AND(DN12="",DP12=""),DM12,DM12+IF(DN12="",0,DN12)-IF(DP12="",0,DP12))) -> 32951
A13: 09 Mar (Sen) | B13: =K12 -> 2506149 | K13: =IF(B13="","",IF(AND(C13="",E13="",H13=""),B13,B13+IF(C13="",0,C13)-IF(E13="",0,E13)-IF(H13="",0,H13))) -> 2506149 | L13: =U12 -> 2577692 | U13: =IF(L13="","",IF(AND(M13="",O13="",R13=""),L13,L13+IF(M13="",0,M13)-IF(O13="",0,O13)-IF(R13="",0,R13))) -> 2577692 | V13: =AE12 -> 2443036 | AE13: =IF(V13="","",IF(AND(W13="",Y13="",AB13=""),V13,V13+IF(W13="",0,W13)-IF(Y13="",0,Y13)-IF(AB13="",0,AB13))) -> 2443036 | AF13: =AL12 -> 328064 | AL13: =IF(AF13="","",IF(AND(AG13="",AI13=""),AF13,AF13+IF(AG13="",0,AG13)-IF(AI13="",0,AI13))) -> 328064 | AM13: =AS12 -> 529521 | AS13: =IF(AM13="","",IF(AND(AN13="",AP13=""),AM13,AM13+IF(AN13="",0,AN13)-IF(AP13="",0,AP13))) -> 529521 | AT13: =AZ12 -> 44014 | AZ13: =IF(AT13="","",IF(AND(AU13="",AW13=""),AT13,AT13+IF(AU13="",0,AU13)-IF(AW13="",0,AW13))) -> 44014 | BA13: =BJ12 -> 536860 | BJ13: =IF(BA13="","",IF(AND(BB13="",BD13="",BG13=""),BA13,BA13+IF(BB13="",0,BB13)-IF(BD13="",0,BD13)-IF(BG13="",0,BG13))) -> 536860 | BK13: =BT12 -> 278400 | BT13: =IF(BK13="","",IF(AND(BL13="",BN13="",BQ13=""),BK13,BK13+IF(BL13="",0,BL13)-IF(BN13="",0,BN13)-IF(BQ13="",0,BQ13))) -> 278400 | BU13: =CD12 -> 508583 | CD13: =IF(BU13="","",IF(AND(BV13="",BX13="",CA13=""),BU13,BU13+IF(BV13="",0,BV13)-IF(BX13="",0,BX13)-IF(CA13="",0,CA13))) -> 508583 | CE13: =CN12 -> 510730 | CN13: =IF(CE13="","",IF(AND(CF13="",CH13="",CK13=""),CE13,CE13+IF(CF13="",0,CF13)-IF(CH13="",0,CH13)-IF(CK13="",0,CK13))) -> 510730 | CO13: =CX12 -> 26023 | CX13: =IF(CO13="","",IF(AND(CP13="",CR13="",CU13=""),CO13,CO13+IF(CP13="",0,CP13)-IF(CR13="",0,CR13)-IF(CU13="",0,CU13))) -> 26023 | CY13: =DE12 -> 1164563 | DE13: =IF(CY13="","",IF(AND(CZ13="",DB13=""),CY13,CY13+IF(CZ13="",0,CZ13)-IF(DB13="",0,DB13))) -> 1164563 | DF13: =DL12 -> 961820 | DL13: =IF(DF13="","",IF(AND(DG13="",DI13=""),DF13,DF13+IF(DG13="",0,DG13)-IF(DI13="",0,DI13))) -> 961820 | DM13: =DS12 -> 32951 | DS13: =IF(DM13="","",IF(AND(DN13="",DP13=""),DM13,DM13+IF(DN13="",0,DN13)-IF(DP13="",0,DP13))) -> 32951
A14: 10 Mar (Sel) | B14: =K13 -> 2506149 | K14: =IF(B14="","",IF(AND(C14="",E14="",H14=""),B14,B14+IF(C14="",0,C14)-IF(E14="",0,E14)-IF(H14="",0,H14))) -> 2506149 | L14: =U13 -> 2577692 | U14: =IF(L14="","",IF(AND(M14="",O14="",R14=""),L14,L14+IF(M14="",0,M14)-IF(O14="",0,O14)-IF(R14="",0,R14))) -> 2577692 | V14: =AE13 -> 2443036 | AE14: =IF(V14="","",IF(AND(W14="",Y14="",AB14=""),V14,V14+IF(W14="",0,W14)-IF(Y14="",0,Y14)-IF(AB14="",0,AB14))) -> 2443036 | AF14: =AL13 -> 328064 | AL14: =IF(AF14="","",IF(AND(AG14="",AI14=""),AF14,AF14+IF(AG14="",0,AG14)-IF(AI14="",0,AI14))) -> 328064 | AM14: =AS13 -> 529521 | AS14: =IF(AM14="","",IF(AND(AN14="",AP14=""),AM14,AM14+IF(AN14="",0,AN14)-IF(AP14="",0,AP14))) -> 529521 | AT14: =AZ13 -> 44014 | AZ14: =IF(AT14="","",IF(AND(AU14="",AW14=""),AT14,AT14+IF(AU14="",0,AU14)-IF(AW14="",0,AW14))) -> 44014 | BA14: =BJ13 -> 536860 | BJ14: =IF(BA14="","",IF(AND(BB14="",BD14="",BG14=""),BA14,BA14+IF(BB14="",0,BB14)-IF(BD14="",0,BD14)-IF(BG14="",0,BG14))) -> 536860 | BK14: =BT13 -> 278400 | BT14: =IF(BK14="","",IF(AND(BL14="",BN14="",BQ14=""),BK14,BK14+IF(BL14="",0,BL14)-IF(BN14="",0,BN14)-IF(BQ14="",0,BQ14))) -> 278400 | BU14: =CD13 -> 508583 | CD14: =IF(BU14="","",IF(AND(BV14="",BX14="",CA14=""),BU14,BU14+IF(BV14="",0,BV14)-IF(BX14="",0,BX14)-IF(CA14="",0,CA14))) -> 508583 | CE14: =CN13 -> 510730 | CN14: =IF(CE14="","",IF(AND(CF14="",CH14="",CK14=""),CE14,CE14+IF(CF14="",0,CF14)-IF(CH14="",0,CH14)-IF(CK14="",0,CK14))) -> 510730 | CO14: =CX13 -> 26023 | CX14: =IF(CO14="","",IF(AND(CP14="",CR14="",CU14=""),CO14,CO14+IF(CP14="",0,CP14)-IF(CR14="",0,CR14)-IF(CU14="",0,CU14))) -> 26023 | CY14: =DE13 -> 1164563 | DE14: =IF(CY14="","",IF(AND(CZ14="",DB14=""),CY14,CY14+IF(CZ14="",0,CZ14)-IF(DB14="",0,DB14))) -> 1164563 | DF14: =DL13 -> 961820 | DL14: =IF(DF14="","",IF(AND(DG14="",DI14=""),DF14,DF14+IF(DG14="",0,DG14)-IF(DI14="",0,DI14))) -> 961820 | DM14: =DS13 -> 32951 | DS14: =IF(DM14="","",IF(AND(DN14="",DP14=""),DM14,DM14+IF(DN14="",0,DN14)-IF(DP14="",0,DP14))) -> 32951
A15: 11 Mar (Rab) | B15: =K14 -> 2506149 | K15: =IF(B15="","",IF(AND(C15="",E15="",H15=""),B15,B15+IF(C15="",0,C15)-IF(E15="",0,E15)-IF(H15="",0,H15))) -> 2506149 | L15: =U14 -> 2577692 | U15: =IF(L15="","",IF(AND(M15="",O15="",R15=""),L15,L15+IF(M15="",0,M15)-IF(O15="",0,O15)-IF(R15="",0,R15))) -> 2577692 | V15: =AE14 -> 2443036 | AE15: =IF(V15="","",IF(AND(W15="",Y15="",AB15=""),V15,V15+IF(W15="",0,W15)-IF(Y15="",0,Y15)-IF(AB15="",0,AB15))) -> 2443036 | AF15: =AL14 -> 328064 | AL15: =IF(AF15="","",IF(AND(AG15="",AI15=""),AF15,AF15+IF(AG15="",0,AG15)-IF(AI15="",0,AI15))) -> 328064 | AM15: =AS14 -> 529521 | AS15: =IF(AM15="","",IF(AND(AN15="",AP15=""),AM15,AM15+IF(AN15="",0,AN15)-IF(AP15="",0,AP15))) -> 529521 | AT15: =AZ14 -> 44014 | AZ15: =IF(AT15="","",IF(AND(AU15="",AW15=""),AT15,AT15+IF(AU15="",0,AU15)-IF(AW15="",0,AW15))) -> 44014 | BA15: =BJ14 -> 536860 | BJ15: =IF(BA15="","",IF(AND(BB15="",BD15="",BG15=""),BA15,BA15+IF(BB15="",0,BB15)-IF(BD15="",0,BD15)-IF(BG15="",0,BG15))) -> 536860 | BK15: =BT14 -> 278400 | BT15: =IF(BK15="","",IF(AND(BL15="",BN15="",BQ15=""),BK15,BK15+IF(BL15="",0,BL15)-IF(BN15="",0,BN15)-IF(BQ15="",0,BQ15))) -> 278400 | BU15: =CD14 -> 508583 | CD15: =IF(BU15="","",IF(AND(BV15="",BX15="",CA15=""),BU15,BU15+IF(BV15="",0,BV15)-IF(BX15="",0,BX15)-IF(CA15="",0,CA15))) -> 508583 | CE15: =CN14 -> 510730 | CN15: =IF(CE15="","",IF(AND(CF15="",CH15="",CK15=""),CE15,CE15+IF(CF15="",0,CF15)-IF(CH15="",0,CH15)-IF(CK15="",0,CK15))) -> 510730 | CO15: =CX14 -> 26023 | CX15: =IF(CO15="","",IF(AND(CP15="",CR15="",CU15=""),CO15,CO15+IF(CP15="",0,CP15)-IF(CR15="",0,CR15)-IF(CU15="",0,CU15))) -> 26023 | CY15: =DE14 -> 1164563 | DE15: =IF(CY15="","",IF(AND(CZ15="",DB15=""),CY15,CY15+IF(CZ15="",0,CZ15)-IF(DB15="",0,DB15))) -> 1164563 | DF15: =DL14 -> 961820 | DL15: =IF(DF15="","",IF(AND(DG15="",DI15=""),DF15,DF15+IF(DG15="",0,DG15)-IF(DI15="",0,DI15))) -> 961820 | DM15: =DS14 -> 32951 | DS15: =IF(DM15="","",IF(AND(DN15="",DP15=""),DM15,DM15+IF(DN15="",0,DN15)-IF(DP15="",0,DP15))) -> 32951
A16: 12 Mar (Kam) | B16: =K15 -> 2506149 | K16: =IF(B16="","",IF(AND(C16="",E16="",H16=""),B16,B16+IF(C16="",0,C16)-IF(E16="",0,E16)-IF(H16="",0,H16))) -> 2506149 | L16: =U15 -> 2577692 | U16: =IF(L16="","",IF(AND(M16="",O16="",R16=""),L16,L16+IF(M16="",0,M16)-IF(O16="",0,O16)-IF(R16="",0,R16))) -> 2577692 | V16: =AE15 -> 2443036 | AE16: =IF(V16="","",IF(AND(W16="",Y16="",AB16=""),V16,V16+IF(W16="",0,W16)-IF(Y16="",0,Y16)-IF(AB16="",0,AB16))) -> 2443036 | AF16: =AL15 -> 328064 | AL16: =IF(AF16="","",IF(AND(AG16="",AI16=""),AF16,AF16+IF(AG16="",0,AG16)-IF(AI16="",0,AI16))) -> 328064 | AM16: =AS15 -> 529521 | AS16: =IF(AM16="","",IF(AND(AN16="",AP16=""),AM16,AM16+IF(AN16="",0,AN16)-IF(AP16="",0,AP16))) -> 529521 | AT16: =AZ15 -> 44014 | AZ16: =IF(AT16="","",IF(AND(AU16="",AW16=""),AT16,AT16+IF(AU16="",0,AU16)-IF(AW16="",0,AW16))) -> 44014 | BA16: =BJ15 -> 536860 | BJ16: =IF(BA16="","",IF(AND(BB16="",BD16="",BG16=""),BA16,BA16+IF(BB16="",0,BB16)-IF(BD16="",0,BD16)-IF(BG16="",0,BG16))) -> 536860 | BK16: =BT15 -> 278400 | BT16: =IF(BK16="","",IF(AND(BL16="",BN16="",BQ16=""),BK16,BK16+IF(BL16="",0,BL16)-IF(BN16="",0,BN16)-IF(BQ16="",0,BQ16))) -> 278400 | BU16: =CD15 -> 508583 | CD16: =IF(BU16="","",IF(AND(BV16="",BX16="",CA16=""),BU16,BU16+IF(BV16="",0,BV16)-IF(BX16="",0,BX16)-IF(CA16="",0,CA16))) -> 508583 | CE16: =CN15 -> 510730 | CN16: =IF(CE16="","",IF(AND(CF16="",CH16="",CK16=""),CE16,CE16+IF(CF16="",0,CF16)-IF(CH16="",0,CH16)-IF(CK16="",0,CK16))) -> 510730 | CO16: =CX15 -> 26023 | CX16: =IF(CO16="","",IF(AND(CP16="",CR16="",CU16=""),CO16,CO16+IF(CP16="",0,CP16)-IF(CR16="",0,CR16)-IF(CU16="",0,CU16))) -> 26023 | CY16: =DE15 -> 1164563 | DE16: =IF(CY16="","",IF(AND(CZ16="",DB16=""),CY16,CY16+IF(CZ16="",0,CZ16)-IF(DB16="",0,DB16))) -> 1164563 | DF16: =DL15 -> 961820 | DL16: =IF(DF16="","",IF(AND(DG16="",DI16=""),DF16,DF16+IF(DG16="",0,DG16)-IF(DI16="",0,DI16))) -> 961820 | DM16: =DS15 -> 32951 | DS16: =IF(DM16="","",IF(AND(DN16="",DP16=""),DM16,DM16+IF(DN16="",0,DN16)-IF(DP16="",0,DP16))) -> 32951
A17: 13 Mar (Jum) | B17: =K16 -> 2506149 | K17: =IF(B17="","",IF(AND(C17="",E17="",H17=""),B17,B17+IF(C17="",0,C17)-IF(E17="",0,E17)-IF(H17="",0,H17))) -> 2506149 | L17: =U16 -> 2577692 | U17: =IF(L17="","",IF(AND(M17="",O17="",R17=""),L17,L17+IF(M17="",0,M17)-IF(O17="",0,O17)-IF(R17="",0,R17))) -> 2577692 | V17: =AE16 -> 2443036 | AE17: =IF(V17="","",IF(AND(W17="",Y17="",AB17=""),V17,V17+IF(W17="",0,W17)-IF(Y17="",0,Y17)-IF(AB17="",0,AB17))) -> 2443036 | AF17: =AL16 -> 328064 | AL17: =IF(AF17="","",IF(AND(AG17="",AI17=""),AF17,AF17+IF(AG17="",0,AG17)-IF(AI17="",0,AI17))) -> 328064 | AM17: =AS16 -> 529521 | AS17: =IF(AM17="","",IF(AND(AN17="",AP17=""),AM17,AM17+IF(AN17="",0,AN17)-IF(AP17="",0,AP17))) -> 529521 | AT17: =AZ16 -> 44014 | AZ17: =IF(AT17="","",IF(AND(AU17="",AW17=""),AT17,AT17+IF(AU17="",0,AU17)-IF(AW17="",0,AW17))) -> 44014 | BA17: =BJ16 -> 536860 | BJ17: =IF(BA17="","",IF(AND(BB17="",BD17="",BG17=""),BA17,BA17+IF(BB17="",0,BB17)-IF(BD17="",0,BD17)-IF(BG17="",0,BG17))) -> 536860 | BK17: =BT16 -> 278400 | BT17: =IF(BK17="","",IF(AND(BL17="",BN17="",BQ17=""),BK17,BK17+IF(BL17="",0,BL17)-IF(BN17="",0,BN17)-IF(BQ17="",0,BQ17))) -> 278400 | BU17: =CD16 -> 508583 | CD17: =IF(BU17="","",IF(AND(BV17="",BX17="",CA17=""),BU17,BU17+IF(BV17="",0,BV17)-IF(BX17="",0,BX17)-IF(CA17="",0,CA17))) -> 508583 | CE17: =CN16 -> 510730 | CN17: =IF(CE17="","",IF(AND(CF17="",CH17="",CK17=""),CE17,CE17+IF(CF17="",0,CF17)-IF(CH17="",0,CH17)-IF(CK17="",0,CK17))) -> 510730 | CO17: =CX16 -> 26023 | CX17: =IF(CO17="","",IF(AND(CP17="",CR17="",CU17=""),CO17,CO17+IF(CP17="",0,CP17)-IF(CR17="",0,CR17)-IF(CU17="",0,CU17))) -> 26023 | CY17: =DE16 -> 1164563 | DE17: =IF(CY17="","",IF(AND(CZ17="",DB17=""),CY17,CY17+IF(CZ17="",0,CZ17)-IF(DB17="",0,DB17))) -> 1164563 | DF17: =DL16 -> 961820 | DL17: =IF(DF17="","",IF(AND(DG17="",DI17=""),DF17,DF17+IF(DG17="",0,DG17)-IF(DI17="",0,DI17))) -> 961820 | DM17: =DS16 -> 32951 | DS17: =IF(DM17="","",IF(AND(DN17="",DP17=""),DM17,DM17+IF(DN17="",0,DN17)-IF(DP17="",0,DP17))) -> 32951
A18: 14 Mar (Sab) | B18: =K17 -> 2506149 | K18: =IF(B18="","",IF(AND(C18="",E18="",H18=""),B18,B18+IF(C18="",0,C18)-IF(E18="",0,E18)-IF(H18="",0,H18))) -> 2506149 | L18: =U17 -> 2577692 | U18: =IF(L18="","",IF(AND(M18="",O18="",R18=""),L18,L18+IF(M18="",0,M18)-IF(O18="",0,O18)-IF(R18="",0,R18))) -> 2577692 | V18: =AE17 -> 2443036 | AE18: =IF(V18="","",IF(AND(W18="",Y18="",AB18=""),V18,V18+IF(W18="",0,W18)-IF(Y18="",0,Y18)-IF(AB18="",0,AB18))) -> 2443036 | AF18: =AL17 -> 328064 | AL18: =IF(AF18="","",IF(AND(AG18="",AI18=""),AF18,AF18+IF(AG18="",0,AG18)-IF(AI18="",0,AI18))) -> 328064 | AM18: =AS17 -> 529521 | AS18: =IF(AM18="","",IF(AND(AN18="",AP18=""),AM18,AM18+IF(AN18="",0,AN18)-IF(AP18="",0,AP18))) -> 529521 | AT18: =AZ17 -> 44014 | AZ18: =IF(AT18="","",IF(AND(AU18="",AW18=""),AT18,AT18+IF(AU18="",0,AU18)-IF(AW18="",0,AW18))) -> 44014 | BA18: =BJ17 -> 536860 | BJ18: =IF(BA18="","",IF(AND(BB18="",BD18="",BG18=""),BA18,BA18+IF(BB18="",0,BB18)-IF(BD18="",0,BD18)-IF(BG18="",0,BG18))) -> 536860 | BK18: =BT17 -> 278400 | BT18: =IF(BK18="","",IF(AND(BL18="",BN18="",BQ18=""),BK18,BK18+IF(BL18="",0,BL18)-IF(BN18="",0,BN18)-IF(BQ18="",0,BQ18))) -> 278400 | BU18: =CD17 -> 508583 | CD18: =IF(BU18="","",IF(AND(BV18="",BX18="",CA18=""),BU18,BU18+IF(BV18="",0,BV18)-IF(BX18="",0,BX18)-IF(CA18="",0,CA18))) -> 508583 | CE18: =CN17 -> 510730 | CN18: =IF(CE18="","",IF(AND(CF18="",CH18="",CK18=""),CE18,CE18+IF(CF18="",0,CF18)-IF(CH18="",0,CH18)-IF(CK18="",0,CK18))) -> 510730 | CO18: =CX17 -> 26023 | CX18: =IF(CO18="","",IF(AND(CP18="",CR18="",CU18=""),CO18,CO18+IF(CP18="",0,CP18)-IF(CR18="",0,CR18)-IF(CU18="",0,CU18))) -> 26023 | CY18: =DE17 -> 1164563 | DE18: =IF(CY18="","",IF(AND(CZ18="",DB18=""),CY18,CY18+IF(CZ18="",0,CZ18)-IF(DB18="",0,DB18))) -> 1164563 | DF18: =DL17 -> 961820 | DL18: =IF(DF18="","",IF(AND(DG18="",DI18=""),DF18,DF18+IF(DG18="",0,DG18)-IF(DI18="",0,DI18))) -> 961820 | DM18: =DS17 -> 32951 | DS18: =IF(DM18="","",IF(AND(DN18="",DP18=""),DM18,DM18+IF(DN18="",0,DN18)-IF(DP18="",0,DP18))) -> 32951
A19: 15 Mar (Min) | B19: =K18 -> 2506149 | K19: =IF(B19="","",IF(AND(C19="",E19="",H19=""),B19,B19+IF(C19="",0,C19)-IF(E19="",0,E19)-IF(H19="",0,H19))) -> 2506149 | L19: =U18 -> 2577692 | U19: =IF(L19="","",IF(AND(M19="",O19="",R19=""),L19,L19+IF(M19="",0,M19)-IF(O19="",0,O19)-IF(R19="",0,R19))) -> 2577692 | V19: =AE18 -> 2443036 | AE19: =IF(V19="","",IF(AND(W19="",Y19="",AB19=""),V19,V19+IF(W19="",0,W19)-IF(Y19="",0,Y19)-IF(AB19="",0,AB19))) -> 2443036 | AF19: =AL18 -> 328064 | AL19: =IF(AF19="","",IF(AND(AG19="",AI19=""),AF19,AF19+IF(AG19="",0,AG19)-IF(AI19="",0,AI19))) -> 328064 | AM19: =AS18 -> 529521 | AS19: =IF(AM19="","",IF(AND(AN19="",AP19=""),AM19,AM19+IF(AN19="",0,AN19)-IF(AP19="",0,AP19))) -> 529521 | AT19: =AZ18 -> 44014 | AZ19: =IF(AT19="","",IF(AND(AU19="",AW19=""),AT19,AT19+IF(AU19="",0,AU19)-IF(AW19="",0,AW19))) -> 44014 | BA19: =BJ18 -> 536860 | BJ19: =IF(BA19="","",IF(AND(BB19="",BD19="",BG19=""),BA19,BA19+IF(BB19="",0,BB19)-IF(BD19="",0,BD19)-IF(BG19="",0,BG19))) -> 536860 | BK19: =BT18 -> 278400 | BT19: =IF(BK19="","",IF(AND(BL19="",BN19="",BQ19=""),BK19,BK19+IF(BL19="",0,BL19)-IF(BN19="",0,BN19)-IF(BQ19="",0,BQ19))) -> 278400 | BU19: =CD18 -> 508583 | CD19: =IF(BU19="","",IF(AND(BV19="",BX19="",CA19=""),BU19,BU19+IF(BV19="",0,BV19)-IF(BX19="",0,BX19)-IF(CA19="",0,CA19))) -> 508583 | CE19: =CN18 -> 510730 | CN19: =IF(CE19="","",IF(AND(CF19="",CH19="",CK19=""),CE19,CE19+IF(CF19="",0,CF19)-IF(CH19="",0,CH19)-IF(CK19="",0,CK19))) -> 510730 | CO19: =CX18 -> 26023 | CX19: =IF(CO19="","",IF(AND(CP19="",CR19="",CU19=""),CO19,CO19+IF(CP19="",0,CP19)-IF(CR19="",0,CR19)-IF(CU19="",0,CU19))) -> 26023 | CY19: =DE18 -> 1164563 | DE19: =IF(CY19="","",IF(AND(CZ19="",DB19=""),CY19,CY19+IF(CZ19="",0,CZ19)-IF(DB19="",0,DB19))) -> 1164563 | DF19: =DL18 -> 961820 | DL19: =IF(DF19="","",IF(AND(DG19="",DI19=""),DF19,DF19+IF(DG19="",0,DG19)-IF(DI19="",0,DI19))) -> 961820 | DM19: =DS18 -> 32951 | DS19: =IF(DM19="","",IF(AND(DN19="",DP19=""),DM19,DM19+IF(DN19="",0,DN19)-IF(DP19="",0,DP19))) -> 32951
A20: 16 Mar (Sen) | B20: =K19 -> 2506149 | K20: =IF(B20="","",IF(AND(C20="",E20="",H20=""),B20,B20+IF(C20="",0,C20)-IF(E20="",0,E20)-IF(H20="",0,H20))) -> 2506149 | L20: =U19 -> 2577692 | U20: =IF(L20="","",IF(AND(M20="",O20="",R20=""),L20,L20+IF(M20="",0,M20)-IF(O20="",0,O20)-IF(R20="",0,R20))) -> 2577692 | V20: =AE19 -> 2443036 | AE20: =IF(V20="","",IF(AND(W20="",Y20="",AB20=""),V20,V20+IF(W20="",0,W20)-IF(Y20="",0,Y20)-IF(AB20="",0,AB20))) -> 2443036 | AF20: =AL19 -> 328064 | AL20: =IF(AF20="","",IF(AND(AG20="",AI20=""),AF20,AF20+IF(AG20="",0,AG20)-IF(AI20="",0,AI20))) -> 328064 | AM20: =AS19 -> 529521 | AS20: =IF(AM20="","",IF(AND(AN20="",AP20=""),AM20,AM20+IF(AN20="",0,AN20)-IF(AP20="",0,AP20))) -> 529521 | AT20: =AZ19 -> 44014 | AZ20: =IF(AT20="","",IF(AND(AU20="",AW20=""),AT20,AT20+IF(AU20="",0,AU20)-IF(AW20="",0,AW20))) -> 44014 | BA20: =BJ19 -> 536860 | BJ20: =IF(BA20="","",IF(AND(BB20="",BD20="",BG20=""),BA20,BA20+IF(BB20="",0,BB20)-IF(BD20="",0,BD20)-IF(BG20="",0,BG20))) -> 536860 | BK20: =BT19 -> 278400 | BT20: =IF(BK20="","",IF(AND(BL20="",BN20="",BQ20=""),BK20,BK20+IF(BL20="",0,BL20)-IF(BN20="",0,BN20)-IF(BQ20="",0,BQ20))) -> 278400 | BU20: =CD19 -> 508583 | CD20: =IF(BU20="","",IF(AND(BV20="",BX20="",CA20=""),BU20,BU20+IF(BV20="",0,BV20)-IF(BX20="",0,BX20)-IF(CA20="",0,CA20))) -> 508583 | CE20: =CN19 -> 510730 | CN20: =IF(CE20="","",IF(AND(CF20="",CH20="",CK20=""),CE20,CE20+IF(CF20="",0,CF20)-IF(CH20="",0,CH20)-IF(CK20="",0,CK20))) -> 510730 | CO20: =CX19 -> 26023 | CX20: =IF(CO20="","",IF(AND(CP20="",CR20="",CU20=""),CO20,CO20+IF(CP20="",0,CP20)-IF(CR20="",0,CR20)-IF(CU20="",0,CU20))) -> 26023 | CY20: =DE19 -> 1164563 | DE20: =IF(CY20="","",IF(AND(CZ20="",DB20=""),CY20,CY20+IF(CZ20="",0,CZ20)-IF(DB20="",0,DB20))) -> 1164563 | DF20: =DL19 -> 961820 | DL20: =IF(DF20="","",IF(AND(DG20="",DI20=""),DF20,DF20+IF(DG20="",0,DG20)-IF(DI20="",0,DI20))) -> 961820 | DM20: =DS19 -> 32951 | DS20: =IF(DM20="","",IF(AND(DN20="",DP20=""),DM20,DM20+IF(DN20="",0,DN20)-IF(DP20="",0,DP20))) -> 32951
A21: 17 Mar (Sel) | B21: =K20 -> 2506149 | K21: =IF(B21="","",IF(AND(C21="",E21="",H21=""),B21,B21+IF(C21="",0,C21)-IF(E21="",0,E21)-IF(H21="",0,H21))) -> 2506149 | L21: =U20 -> 2577692 | U21: =IF(L21="","",IF(AND(M21="",O21="",R21=""),L21,L21+IF(M21="",0,M21)-IF(O21="",0,O21)-IF(R21="",0,R21))) -> 2577692 | V21: =AE20 -> 2443036 | AE21: =IF(V21="","",IF(AND(W21="",Y21="",AB21=""),V21,V21+IF(W21="",0,W21)-IF(Y21="",0,Y21)-IF(AB21="",0,AB21))) -> 2443036 | AF21: =AL20 -> 328064 | AL21: =IF(AF21="","",IF(AND(AG21="",AI21=""),AF21,AF21+IF(AG21="",0,AG21)-IF(AI21="",0,AI21))) -> 328064 | AM21: =AS20 -> 529521 | AS21: =IF(AM21="","",IF(AND(AN21="",AP21=""),AM21,AM21+IF(AN21="",0,AN21)-IF(AP21="",0,AP21))) -> 529521 | AT21: =AZ20 -> 44014 | AZ21: =IF(AT21="","",IF(AND(AU21="",AW21=""),AT21,AT21+IF(AU21="",0,AU21)-IF(AW21="",0,AW21))) -> 44014 | BA21: =BJ20 -> 536860 | BJ21: =IF(BA21="","",IF(AND(BB21="",BD21="",BG21=""),BA21,BA21+IF(BB21="",0,BB21)-IF(BD21="",0,BD21)-IF(BG21="",0,BG21))) -> 536860 | BK21: =BT20 -> 278400 | BT21: =IF(BK21="","",IF(AND(BL21="",BN21="",BQ21=""),BK21,BK21+IF(BL21="",0,BL21)-IF(BN21="",0,BN21)-IF(BQ21="",0,BQ21))) -> 278400 | BU21: =CD20 -> 508583 | CD21: =IF(BU21="","",IF(AND(BV21="",BX21="",CA21=""),BU21,BU21+IF(BV21="",0,BV21)-IF(BX21="",0,BX21)-IF(CA21="",0,CA21))) -> 508583 | CE21: =CN20 -> 510730 | CN21: =IF(CE21="","",IF(AND(CF21="",CH21="",CK21=""),CE21,CE21+IF(CF21="",0,CF21)-IF(CH21="",0,CH21)-IF(CK21="",0,CK21))) -> 510730 | CO21: =CX20 -> 26023 | CX21: =IF(CO21="","",IF(AND(CP21="",CR21="",CU21=""),CO21,CO21+IF(CP21="",0,CP21)-IF(CR21="",0,CR21)-IF(CU21="",0,CU21))) -> 26023 | CY21: =DE20 -> 1164563 | DE21: =IF(CY21="","",IF(AND(CZ21="",DB21=""),CY21,CY21+IF(CZ21="",0,CZ21)-IF(DB21="",0,DB21))) -> 1164563 | DF21: =DL20 -> 961820 | DL21: =IF(DF21="","",IF(AND(DG21="",DI21=""),DF21,DF21+IF(DG21="",0,DG21)-IF(DI21="",0,DI21))) -> 961820 | DM21: =DS20 -> 32951 | DS21: =IF(DM21="","",IF(AND(DN21="",DP21=""),DM21,DM21+IF(DN21="",0,DN21)-IF(DP21="",0,DP21))) -> 32951
A22: 18 Mar (Rab) | B22: =K21 -> 2506149 | K22: =IF(B22="","",IF(AND(C22="",E22="",H22=""),B22,B22+IF(C22="",0,C22)-IF(E22="",0,E22)-IF(H22="",0,H22))) -> 2506149 | L22: =U21 -> 2577692 | U22: =IF(L22="","",IF(AND(M22="",O22="",R22=""),L22,L22+IF(M22="",0,M22)-IF(O22="",0,O22)-IF(R22="",0,R22))) -> 2577692 | V22: =AE21 -> 2443036 | AE22: =IF(V22="","",IF(AND(W22="",Y22="",AB22=""),V22,V22+IF(W22="",0,W22)-IF(Y22="",0,Y22)-IF(AB22="",0,AB22))) -> 2443036 | AF22: =AL21 -> 328064 | AL22: =IF(AF22="","",IF(AND(AG22="",AI22=""),AF22,AF22+IF(AG22="",0,AG22)-IF(AI22="",0,AI22))) -> 328064 | AM22: =AS21 -> 529521 | AS22: =IF(AM22="","",IF(AND(AN22="",AP22=""),AM22,AM22+IF(AN22="",0,AN22)-IF(AP22="",0,AP22))) -> 529521 | AT22: =AZ21 -> 44014 | AZ22: =IF(AT22="","",IF(AND(AU22="",AW22=""),AT22,AT22+IF(AU22="",0,AU22)-IF(AW22="",0,AW22))) -> 44014 | BA22: =BJ21 -> 536860 | BJ22: =IF(BA22="","",IF(AND(BB22="",BD22="",BG22=""),BA22,BA22+IF(BB22="",0,BB22)-IF(BD22="",0,BD22)-IF(BG22="",0,BG22))) -> 536860 | BK22: =BT21 -> 278400 | BT22: =IF(BK22="","",IF(AND(BL22="",BN22="",BQ22=""),BK22,BK22+IF(BL22="",0,BL22)-IF(BN22="",0,BN22)-IF(BQ22="",0,BQ22))) -> 278400 | BU22: =CD21 -> 508583 | CD22: =IF(BU22="","",IF(AND(BV22="",BX22="",CA22=""),BU22,BU22+IF(BV22="",0,BV22)-IF(BX22="",0,BX22)-IF(CA22="",0,CA22))) -> 508583 | CE22: =CN21 -> 510730 | CN22: =IF(CE22="","",IF(AND(CF22="",CH22="",CK22=""),CE22,CE22+IF(CF22="",0,CF22)-IF(CH22="",0,CH22)-IF(CK22="",0,CK22))) -> 510730 | CO22: =CX21 -> 26023 | CX22: =IF(CO22="","",IF(AND(CP22="",CR22="",CU22=""),CO22,CO22+IF(CP22="",0,CP22)-IF(CR22="",0,CR22)-IF(CU22="",0,CU22))) -> 26023 | CY22: =DE21 -> 1164563 | DE22: =IF(CY22="","",IF(AND(CZ22="",DB22=""),CY22,CY22+IF(CZ22="",0,CZ22)-IF(DB22="",0,DB22))) -> 1164563 | DF22: =DL21 -> 961820 | DL22: =IF(DF22="","",IF(AND(DG22="",DI22=""),DF22,DF22+IF(DG22="",0,DG22)-IF(DI22="",0,DI22))) -> 961820 | DM22: =DS21 -> 32951 | DS22: =IF(DM22="","",IF(AND(DN22="",DP22=""),DM22,DM22+IF(DN22="",0,DN22)-IF(DP22="",0,DP22))) -> 32951
... A34: 30 Mar (Sen) | B34: =K33 -> 2506149 | K34: =IF(B34="","",IF(AND(C34="",E34="",H34=""),B34,B34+IF(C34="",0,C34)-IF(E34="",0,E34)-IF(H34="",0,H34))) -> 2506149 | L34: =U33 -> 2577692 | U34: =IF(L34="","",IF(AND(M34="",O34="",R34=""),L34,L34+IF(M34="",0,M34)-IF(O34="",0,O34)-IF(R34="",0,R34))) -> 2577692 | V34: =AE33 -> 2443036 | AE34: =IF(V34="","",IF(AND(W34="",Y34="",AB34=""),V34,V34+IF(W34="",0,W34)-IF(Y34="",0,Y34)-IF(AB34="",0,AB34))) -> 2443036 | AF34: =AL33 -> 328064 | AL34: =IF(AF34="","",IF(AND(AG34="",AI34=""),AF34,AF34+IF(AG34="",0,AG34)-IF(AI34="",0,AI34))) -> 328064 | AM34: =AS33 -> 529521 | AS34: =IF(AM34="","",IF(AND(AN34="",AP34=""),AM34,AM34+IF(AN34="",0,AN34)-IF(AP34="",0,AP34))) -> 529521 | AT34: =AZ33 -> 44014 | AZ34: =IF(AT34="","",IF(AND(AU34="",AW34=""),AT34,AT34+IF(AU34="",0,AU34)-IF(AW34="",0,AW34))) -> 44014 | BA34: =BJ33 -> 536860 | BJ34: =IF(BA34="","",IF(AND(BB34="",BD34="",BG34=""),BA34,BA34+IF(BB34="",0,BB34)-IF(BD34="",0,BD34)-IF(BG34="",0,BG34))) -> 536860 | BK34: =BT33 -> 278400 | BT34: =IF(BK34="","",IF(AND(BL34="",BN34="",BQ34=""),BK34,BK34+IF(BL34="",0,BL34)-IF(BN34="",0,BN34)-IF(BQ34="",0,BQ34))) -> 278400 | BU34: =CD33 -> 508583 | CD34: =IF(BU34="","",IF(AND(BV34="",BX34="",CA34=""),BU34,BU34+IF(BV34="",0,BV34)-IF(BX34="",0,BX34)-IF(CA34="",0,CA34))) -> 508583 | CE34: =CN33 -> 510730 | CN34: =IF(CE34="","",IF(AND(CF34="",CH34="",CK34=""),CE34,CE34+IF(CF34="",0,CF34)-IF(CH34="",0,CH34)-IF(CK34="",0,CK34))) -> 510730 | CO34: =CX33 -> 26023 | CX34: =IF(CO34="","",IF(AND(CP34="",CR34="",CU34=""),CO34,CO34+IF(CP34="",0,CP34)-IF(CR34="",0,CR34)-IF(CU34="",0,CU34))) -> 26023 | CY34: =DE33 -> 1164563 | DE34: =IF(CY34="","",IF(AND(CZ34="",DB34=""),CY34,CY34+IF(CZ34="",0,CZ34)-IF(DB34="",0,DB34))) -> 1164563 | DF34: =DL33 -> 961820 | DL34: =IF(DF34="","",IF(AND(DG34="",DI34=""),DF34,DF34+IF(DG34="",0,DG34)-IF(DI34="",0,DI34))) -> 961820 | DM34: =DS33 -> 32951 | DS34: =IF(DM34="","",IF(AND(DN34="",DP34=""),DM34,DM34+IF(DN34="",0,DN34)-IF(DP34="",0,DP34))) -> 32951

Sheet REKAP STOK BULANAN
A1: REKAP MUTASI STOK BULANAN - MARET 2026
A3: Rekap otomatis dari sheet MUTASI STOK — Total masuk, keluar, dan sisa akhir bulan per tangki
A4: NO | B4: TANGKI | C4: PRODUK | D4: STOK AWAL (kg) | E4: TOTAL MASUK (kg) | F4: TOTAL KELUAR (kg) | G4: SISA AKHIR (kg) | H4: KETERANGAN
A5: 1 | B5: CPO ST01 | C5: CPO | D5: ='MUTASI STOK'!B5 -> 2506149 | E5: =SUMIF('MUTASI STOK'!C5:C34,">0") -> 0 | F5: =SUMIF('MUTASI STOK'!E5:E34,">0")+SUMIF('MUTASI STOK'!H5:H34,">0") -> 0 | G5: ='MUTASI STOK'!K34 -> 2506149 | H5: =IF(AND(E5=0,F5=0),"Tidak ada mutasi",IF(E5>0,"Masuk: "&TEXT(E5,"#,##0")&" kg | Keluar: "&TEXT(F5,"#,##0")&" kg","Keluar: "&TEXT(F5,"#,##0")&" kg")) -> Tidak ada mutasi
A6: 2 | B6: CPO ST02 | C6: CPO | D6: ='MUTASI STOK'!L5 -> 2577692 | E6: =SUMIF('MUTASI STOK'!M5:M34,">0") -> 0 | F6: =SUMIF('MUTASI STOK'!O5:O34,">0")+SUMIF('MUTASI STOK'!R5:R34,">0") -> 0 | G6: ='MUTASI STOK'!U34 -> 2577692 | H6: =IF(AND(E6=0,F6=0),"Tidak ada mutasi",IF(E6>0,"Masuk: "&TEXT(E6,"#,##0")&" kg | Keluar: "&TEXT(F6,"#,##0")&" kg","Keluar: "&TEXT(F6,"#,##0")&" kg")) -> Tidak ada mutasi
A7: 3 | B7: CPO ST03 | C7: CPO | D7: ='MUTASI STOK'!V5 -> 2443036 | E7: =SUMIF('MUTASI STOK'!W5:W34,">0") -> 0 | F7: =SUMIF('MUTASI STOK'!Y5:Y34,">0")+SUMIF('MUTASI STOK'!AB5:AB34,">0") -> 0 | G7: ='MUTASI STOK'!AE34 -> 2443036 | H7: =IF(AND(E7=0,F7=0),"Tidak ada mutasi",IF(E7>0,"Masuk: "&TEXT(E7,"#,##0")&" kg | Keluar: "&TEXT(F7,"#,##0")&" kg","Keluar: "&TEXT(F7,"#,##0")&" kg")) -> Tidak ada mutasi
A8: 4 | B8: PFAD ST04 | C8: PFAD | D8: ='MUTASI STOK'!AF5 -> 328064 | E8: =SUMIF('MUTASI STOK'!AG5:AG34,">0") -> 0 | F8: =SUMIF('MUTASI STOK'!AI5:AI34,">0") -> 0 | G8: ='MUTASI STOK'!AL34 -> 328064 | H8: =IF(AND(E8=0,F8=0),"Tidak ada mutasi",IF(E8>0,"Masuk: "&TEXT(E8,"#,##0")&" kg | Keluar: "&TEXT(F8,"#,##0")&" kg","Keluar: "&TEXT(F8,"#,##0")&" kg")) -> Tidak ada mutasi
A9: 5 | B9: Stearin ST05 | C9: Stearin | D9: ='MUTASI STOK'!AM5 -> 529521 | E9: =SUMIF('MUTASI STOK'!AN5:AN34,">0") -> 0 | F9: =SUMIF('MUTASI STOK'!AP5:AP34,">0") -> 0 | G9: ='MUTASI STOK'!AS34 -> 529521 | H9: =IF(AND(E9=0,F9=0),"Tidak ada mutasi",IF(E9>0,"Masuk: "&TEXT(E9,"#,##0")&" kg | Keluar: "&TEXT(F9,"#,##0")&" kg","Keluar: "&TEXT(F9,"#,##0")&" kg")) -> Tidak ada mutasi
A10: 6 | B10: Stearin ST06 | C10: Stearin | D10: ='MUTASI STOK'!AT5 -> 44014 | E10: =SUMIF('MUTASI STOK'!AU5:AU34,">0") -> 0 | F10: =SUMIF('MUTASI STOK'!AW5:AW34,">0") -> 0 | G10: ='MUTASI STOK'!AZ34 -> 44014 | H10: =IF(AND(E10=0,F10=0),"Tidak ada mutasi",IF(E10>0,"Masuk: "&TEXT(E10,"#,##0")&" kg | Keluar: "&TEXT(F10,"#,##0")&" kg","Keluar: "&TEXT(F10,"#,##0")&" kg")) -> Tidak ada mutasi
A11: 7 | B11: Olein ST07 | C11: Olein | D11: ='MUTASI STOK'!BA5 -> 536860 | E11: =SUMIF('MUTASI STOK'!BB5:BB34,">0") -> 0 | F11: =SUMIF('MUTASI STOK'!BD5:BD34,">0")+SUMIF('MUTASI STOK'!BG5:BG34,">0") -> 0 | G11: ='MUTASI STOK'!BJ34 -> 536860 | H11: =IF(AND(E11=0,F11=0),"Tidak ada mutasi",IF(E11>0,"Masuk: "&TEXT(E11,"#,##0")&" kg | Keluar: "&TEXT(F11,"#,##0")&" kg","Keluar: "&TEXT(F11,"#,##0")&" kg")) -> Tidak ada mutasi
A12: 8 | B12: Olein ST08 | C12: Olein | D12: ='MUTASI STOK'!BK5 -> 390600 | E12: =SUMIF('MUTASI STOK'!BL5:BL34,">0") -> 0 | F12: =SUMIF('MUTASI STOK'!BN5:BN34,">0")+SUMIF('MUTASI STOK'!BQ5:BQ34,">0") -> 112200 | G12: ='MUTASI STOK'!BT34 -> 278400 | H12: =IF(AND(E12=0,F12=0),"Tidak ada mutasi",IF(E12>0,"Masuk: "&TEXT(E12,"#,##0")&" kg | Keluar: "&TEXT(F12,"#,##0")&" kg","Keluar: "&TEXT(F12,"#,##0")&" kg")) -> Keluar: 112200,0 kg
A13: 9 | B13: Olein ST09 | C13: Olein | D13: ='MUTASI STOK'!BU5 -> 508583 | E13: =SUMIF('MUTASI STOK'!BV5:BV34,">0") -> 0 | F13: =SUMIF('MUTASI STOK'!BX5:BX34,">0")+SUMIF('MUTASI STOK'!CA5:CA34,">0") -> 0 | G13: ='MUTASI STOK'!CD34 -> 508583 | H13: =IF(AND(E13=0,F13=0),"Tidak ada mutasi",IF(E13>0,"Masuk: "&TEXT(E13,"#,##0")&" kg | Keluar: "&TEXT(F13,"#,##0")&" kg","Keluar: "&TEXT(F13,"#,##0")&" kg")) -> Tidak ada mutasi
A14: 10 | B14: Olein ST10 | C14: Olein | D14: ='MUTASI STOK'!CE5 -> 510730 | E14: =SUMIF('MUTASI STOK'!CF5:CF34,">0") -> 0 | F14: =SUMIF('MUTASI STOK'!CH5:CH34,">0")+SUMIF('MUTASI STOK'!CK5:CK34,">0") -> 0 | G14: ='MUTASI STOK'!CN34 -> 510730 | H14: =IF(AND(E14=0,F14=0),"Tidak ada mutasi",IF(E14>0,"Masuk: "&TEXT(E14,"#,##0")&" kg | Keluar: "&TEXT(F14,"#,##0")&" kg","Keluar: "&TEXT(F14,"#,##0")&" kg")) -> Tidak ada mutasi
A15: 11 | B15: Olein ST11 | C15: Olein | D15: ='MUTASI STOK'!CO5 -> 26023 | E15: =SUMIF('MUTASI STOK'!CP5:CP34,">0") -> 0 | F15: =SUMIF('MUTASI STOK'!CR5:CR34,">0")+SUMIF('MUTASI STOK'!CU5:CU34,">0") -> 0 | G15: ='MUTASI STOK'!CX34 -> 26023 | H15: =IF(AND(E15=0,F15=0),"Tidak ada mutasi",IF(E15>0,"Masuk: "&TEXT(E15,"#,##0")&" kg | Keluar: "&TEXT(F15,"#,##0")&" kg","Keluar: "&TEXT(F15,"#,##0")&" kg")) -> Tidak ada mutasi
A16: 12 | B16: RBDPO ST13 | C16: RBDPO | D16: ='MUTASI STOK'!CY5 -> 1164563 | E16: =SUMIF('MUTASI STOK'!CZ5:CZ34,">0") -> 0 | F16: =SUMIF('MUTASI STOK'!DB5:DB34,">0") -> 0 | G16: ='MUTASI STOK'!DE34 -> 1164563 | H16: =IF(AND(E16=0,F16=0),"Tidak ada mutasi",IF(E16>0,"Masuk: "&TEXT(E16,"#,##0")&" kg | Keluar: "&TEXT(F16,"#,##0")&" kg","Keluar: "&TEXT(F16,"#,##0")&" kg")) -> Tidak ada mutasi
A17: 13 | B17: RBDPO ST14 | C17: RBDPO | D17: ='MUTASI STOK'!DF5 -> 961820 | E17: =SUMIF('MUTASI STOK'!DG5:DG34,">0") -> 0 | F17: =SUMIF('MUTASI STOK'!DI5:DI34,">0") -> 0 | G17: ='MUTASI STOK'!DL34 -> 961820 | H17: =IF(AND(E17=0,F17=0),"Tidak ada mutasi",IF(E17>0,"Masuk: "&TEXT(E17,"#,##0")&" kg | Keluar: "&TEXT(F17,"#,##0")&" kg","Keluar: "&TEXT(F17,"#,##0")&" kg")) -> Tidak ada mutasi
A18: 14 | B18: Buffer 2 | C18: Buffer/Olein | D18: ='MUTASI STOK'!DM5 -> 32951 | E18: =SUMIF('MUTASI STOK'!DN5:DN34,">0") -> 0 | F18: =SUMIF('MUTASI STOK'!DP5:DP34,">0") -> 0 | G18: ='MUTASI STOK'!DS34 -> 32951 | H18: =IF(AND(E18=0,F18=0),"Tidak ada mutasi",IF(E18>0,"Masuk: "&TEXT(E18,"#,##0")&" kg | Keluar: "&TEXT(F18,"#,##0")&" kg","Keluar: "&TEXT(F18,"#,##0")&" kg")) -> Tidak ada mutasi
A20: TOTAL SEMUA TANGKI | D20: =SUM(D5:D18) -> 12560606 | E20: =SUM(E5:E18) -> 0 | F20: =SUM(F5:F18) -> 112200 | G20: =SUM(G5:G18) -> 12448406

Sheet INPUT KUALITAS
A1: INPUT KUALITAS HARIAN - STORAGE TANK - MARET 2026
A2: Keterangan: | D2: OK | E2: AMBANG BATAS | F2: OVER SPEC
A3: STANDAR: CPO FFA<=5.0% | DOBI>=2.31 | IV>=50 | Olein FFA<=0.10% | IV>=56.0 | CP<=10C | RBDPO FFA<=0.10% | IV>=50 | PV<=2.0 | Stearin FFA<=0.15% | IV>=34 | MP>=48C
A4: TANGGAL | B4: CPO ST 01 | J4: CPO ST 02 | R4: CPO ST 03 | Z4: PFAD ST04 | AC4: Stearin ST05 | AI4: Stearin ST06 | AO4: Olein ST07 | AU4: Olein ST08 | BA4: Olein ST09 | BG4: Olein ST10 | BM4: Olein ST11 | BS4: RBDPO ST13 | BY4: RBDPO ST14 | CE4: Buffer 2 | CK4: CATATAN
A5: TANGGAL | B5: Tonase (kg) | C5: FFA (%) | D5: M+I (%) | E5: DOBI | F5: IV | G5: PV | H5: ANV | I5: TOX | J5: Tonase (kg) | K5: FFA (%) | L5: M+I (%) | M5: DOBI | N5: IV | O5: PV | P5: ANV | Q5: TOX | R5: Tonase (kg) | S5: FFA (%) | T5: M+I (%) | U5: DOBI | V5: IV | W5: PV | X5: ANV | Y5: TOX | Z5: Tonase | AA5: FFA (%) | AB5: Moist (%) | AC5: Tonase | AD5: FFA (%) | AE5: CLR | AF5: Moist (%) | AG5: IV | AH5: MP (C) | AI5: Tonase | AJ5: FFA (%) | AK5: CLR | AL5: Moist (%) | AM5: IV | AN5: MP (C) | AO5: Tonase | AP5: FFA (%) | AQ5: CLR | AR5: Moist (%) | AS5: IV | AT5: CP (C) | AU5: Tonase | AV5: FFA (%) | AW5: CLR | AX5: Moist (%) | AY5: IV | AZ5: CP (C) | BA5: Tonase | BB5: FFA (%) | BC5: CLR | BD5: Moist (%) | BE5: IV | BF5: CP (C) | BG5: Tonase | BH5: FFA (%) | BI5: CLR | BJ5: Moist (%) | BK5: IV | BL5: CP (C) | BM5: Tonase | BN5: FFA (%) | BO5: CLR | BP5: Moist (%) | BQ5: IV | BR5: CP (C) | BS5: Tonase | BT5: FFA (%) | BU5: CLR | BV5: Moist (%) | BW5: IV | BX5: PV | BY5: Tonase | BZ5: FFA (%) | CA5: CLR | CB5: Moist (%) | CC5: IV | CD5: PV | CE5: Tonase | CF5: FFA (%) | CG5: CLR | CH5: Moist (%) | CI5: IV | CJ5: CP (C) | CK5: Catatan
